Workbook
Name Cluster_List: Lookups!$B$4:$B$18
Name Evaluator_Role_List: Lookups!$C$4:$C$12
Name High_Risk_Activity_List: Lookups!$D$4:$D$19
Name KPI_List: Lookups!$H$4:$H$18
Name Package_List: Lookups!$A$4:$A$6
Name Root_Cause_List: Lookups!$F$4:$F$14
Name Score_List: Lookups!$I$2:$I$7
Name Status_List: Lookups!$G$4:$G$7
Name Yes_No_List: Lookups!$E$4:$E$5

Sheet Instructions
A1: Saadiyat Lagoons HSE Scoring Template - Google Form Ready
A2: This workbook is now structured as a live HSE weekly KPI, dashboard, gap analysis, and CAPA control file. Complete only blue-font input cells or unlocked input fields.
A3: 2. Complete the visible input columns only. Hidden columns calculate automatically.
A4: 3. Score each KPI from 0 to 5. 0 = collapse of control, 5 = excellent sustained control.
A5: 4. Package and Cluster are mandatory. Contractor and responsible team auto-populate.
A6: 5. Weekly_Dashboard is for top management review. Monthly_Dashboard tracks recognition trend.
A7: 6. Gap_Analysis and CAPA_Tracker are for close-out management.
A18: Weekly operating method
A19: 1. Enter one line per completed site walk in Weekly_Inspections.
A20: 2. Select Package, Cluster, role, high risk activity, and KPI-for-attention fields from dropdown lists only.
A21: 3. Score every KPI from 0 to 5. Red flag logic now reads the Critical Gate KPI list directly from KPI_Weights.
A22: 4. Use Weekly_Dashboard for current week review, Monthly_Dashboard for recognition/improvement review, Gap_Analysis for weak KPI focus, and CAPA_Tracker for closeout status.
... A29: • Core scoring formulas made more robust and critical gate logic made dynamic from KPI_Weights.

Sheet Cluster_Master
A1: Cluster Master Register
A2: Reference data used for package/cluster selection and automatic population of contractor and leadership accountability details.
A3: Package | B3: Cluster | C3: Contractor | D3: Project Director (PD) | E3: Project Manager (PM) | F3: Construction Manager (CM) | G3: HSE Manager (HSEM) | H3: Section Engineer (SE)
A4: 2 | B4: Cluster 7A | C4: TAJV | D4: Hicham Adel Narch | E4: Ghaidh Alfaour | F4: George Deeb | G4: Timur Terakopov | H4: Liqat
A5: 2 | B5: Cluster 7B | C5: TAJV | D5: Hicham Adel Narch | E5: Ghaidh Alfaour | F5: George Deeb | G5: Timur Terakopov | H5: Eyad
A6: 2 | B6: Cluster 8A | C6: TAJV | D6: Hicham Adel Narch | E6: Ghaidh Alfaour | F6: Mohamed Salama | G6: Timur Terakopov | H6: Ahmad Adel
A7: 2 | B7: Cluster 8B | C7: TAJV | D7: Hicham Adel Narch | E7: Ghaidh Alfaour | F7: Mohamed Salama | G7: Timur Terakopov | H7: Ahmad Adel
A8: 2 | B8: Cluster 8C | C8: TAJV | D8: Hicham Adel Narch | E8: Ghaidh Alfaour | F8: George Deeb | G8: Timur Terakopov | H8: Ahmad Adel
A9: 2 | B9: Cluster 8D | C9: TAJV | D9: Hicham Adel Narch | E9: Ghaidh Alfaour | F9: George Deeb | G9: Timur Terakopov | H9: Ahmad Adel
A10: 3 | B10: Cluster 3 | C10: INNOVO | D10: Kahtan Tikriti | E10: Aiman Abdullah | F10: Salama Al Samdy | G10: Mazen Al Atwani | H10: TBD - Update Section Engineer
A11: 3 | B11: Cluster 4 | C11: INNOVO | D11: Kahtan Tikriti | E11: Aiman Abdullah | F11: Baha Basheer | G11: Mazen Al Atwani | H11: TBD - Update Section Engineer
A12: 3 | B12: Cluster 5 | C12: INNOVO | D12: Kahtan Tikriti | E12: Michael Ghali | F12: Robair Louies | G12: Mazen Al Atwani | H12: TBD - Update Section Engineer
A13: 3 | B13: Cluster 6 | C13: INNOVO | D13: Kahtan Tikriti | E13: Michael Ghali | F13: Remon Karas | G13: Mazen Al Atwani | H13: TBD - Update Section Engineer
A14: 4 | B14: Cluster 1A | C14: TAJV | D14: Hicham Adel Narch | E14: Ghaidh Alfaour | F14: Alaa Hegab | G14: Timur Terakopov | H14: Amr Taha
A15: 4 | B15: Cluster 1B | C15: TAJV | D15: Hicham Adel Narch | E15: Ghaidh Alfaour | F15: Hossam Ali Maher | G15: Timur Terakopov | H15: Md Ramadan / Osama Said
... A18: 4 | B18: Cluster 2C | C18: TAJV | D18: Hicham Adel Narch | E18: Ghaidh Alfaour | F18: Ahmed Salah Hassan Dewidar | G18: Timur Terakopov | H18: Salah Nayef

Sheet Lookups
A1: Lookup Lists | I1: Score_List
A2: Lists used for dropdowns in the Weekly_Inspections and CAPA_Tracker sheets. | I2: 0
A3: Package_List | B3: Cluster_List | C3: Evaluator_Role_List | D3: High_Risk_Activity_List | E3: Yes_No_List | F3: Root_Cause_List | G3: Status_List | H3: KPI_List | I3: 1
A4: 2 | B4: Cluster 7A | C4: Project Director | D4: Work at Height | E4: YES | F4: Leadership failure | G4: Open | H4: Work at Height Control | I4: 2
A5: 3 | B5: Cluster 7B | C5: Project Manager | D5: Edge Protection | E5: NO | F5: Poor supervision | G5: In Progress | H5: Edge Protection | I5: 3
A6: 4 | B6: Cluster 8A | C6: Construction Manager | D6: Falling Objects | F6: Poor planning | G6: Closed | H6: Falling Object Prevention | I6: 4
B7: Cluster 8B | C7: HSE Manager | D7: Excavation | F7: PTW failure | G7: On Hold | H7: Excavation Safety | I7: 5
B8: Cluster 8C | C8: Section Engineer | D8: Scaffolding | F8: Weak MSRA | H8: Scaffolding Compliance
B9: Cluster 8D | C9: QA/QC | D9: Permit to Work | F9: Poor subcontractor control | H9: PTW Implementation
B10: Cluster 3 | C10: KEO | D10: MSRA / Risk Assessment | F10: Resource constraint | H10: PTW Field Verification
B11: Cluster 4 | C11: Client | D11: Lifting Operations | F11: Inadequate competence | H11: MSRA Quality
B12: Cluster 5 | C12: Other | D12: Traffic Management | F12: Poor housekeeping culture | H12: Lifting/Precast Installation
B13: Cluster 6 | D13: Housekeeping | F13: Interface / simultaneous activity conflict | H13: Traffic & Man-Machine Interface
B14: Cluster 1A | D14: Waste Management | F14: Other | H14: Housekeeping/Waste Management
B15: Cluster 1B | D15: Fire Readiness | H15: Welfare Arrangement
B16: Cluster 2A | D16: Electrical Safety | H16: Fire Readiness
B17: Cluster 2B | D17: Portable Power Tools | H17: Supervision & Subcontractor Control
B18: Cluster 2C | D18: Heat Stress | H18: Temporary Electrical & Tool Safety
D19: Other

Sheet KPI_Weights
A1: KPI Weights and Gate Rules
A2: Weights sum to 100%. Critical gate KPIs trigger a red flag if scored 0 or 1 in any inspection.
A3: KPI | B3: Weight | C3: Critical Gate KPI? | D3: Notes
A4: Work at Height Control | B4: 0.12 | C4: YES | D4: Primary fall prevention and work at height control
A5: Edge Protection | B5: 0.12 | C5: NO | D5: Continuity and quality of edge protection
A6: Falling Object Prevention | B6: 0.05 | C6: NO | D6: Exclusion zones, toe boards, debris/tool control
A7: Excavation Safety | B7: 0.08 | C7: YES | D7: Barricading, access, services, support, spoil setback
A8: Scaffolding Compliance | B8: 0.1 | C8: YES | D8: Tagging, inspection, full planking, access, stability
A9: PTW Implementation | B9: 0.08 | C9: YES | D9: Valid PTW, correct scope, signatories, controls
A10: PTW Field Verification | B10: 0.06 | C10: NO | D10: Physical field verification before permit approval
A11: MSRA Quality | B11: 0.03 | C11: NO | D11: Task-specific risk assessment and understanding
A12: Lifting/Precast Installation | B12: 0.1 | C12: YES | D12: Lift plan, appointed person, exclusion, rigging
A13: Traffic & Man-Machine Interface | B13: 0.06 | C13: NO | D13: Pedestrian segregation, routes, signage, reversing
A14: Housekeeping/Waste Management | B14: 0.03 | C14: NO | D14: Cleanliness, stacking, access routes, slip/trip control
A15: Welfare Arrangement | B15: 0.03 | C15: NO | D15: Segregation, storage, transfer/disposal control
... A18: Temporary Electrical & Tool Safety | B18: 0.06 | C18: NO | D18: Temporary power, RCD, condition of tools/cables
A20: Total | B20: =SUM(B4:B18)

Sheet Weekly_Inspections
A1: Weekly Inspection Entry Sheet - Google Form Ready
A2: Complete only visible fields. Use the 0-5 dropdown for each KPI. Package and Cluster auto-fill contractor leadership and the dashboard updates automatically.
A3: Inspection_ID | B3: Inspection_Date | C3: Week_No | D3: Month | E3: Package | F3: Cluster | G3: Package_Cluster_Check | H3: Contractor | I3: Project Director (PD) | J3: Project Manager (PM) | K3: Construction Manager (CM) | L3: HSE Manager (HSEM) | M3: Section Engineer (SE) | N3: Your_Name | O3: Your_Role | P3: Area_or_Villa | Q3: Workers_Observed | R3: Main_High_Risk_Activity | S3: Stop_Work | T3: Work_at_Height | U3: Edge_Protection | V3: Falling_Object_Prevention | W3: Excavation_Safety | X3: Scaffolding_Compliance | Y3: PTW_Implementation | Z3: PTW_Field_Verification | AA3: MSRA_Quality | AB3: Lifting/Precast Installation | AC3: Traffic_Interface | AD3: Housekeeping/Waste Management | AE3: Welfare Arrangement | AF3: Fire_Readiness | AG3: Supervision_Subcontractor | AH3: Electrical_Tool_Safety | AI3: Total_Score | AJ3: Raw_Score_% | AK3: Weighted_Score_% | AL3: Critical_Red_Flag | AM3: Award_Eligible | AN3: Rating_Band | AO3: Repeat_Issue_Seen | AP3: Likely_Root_Cause | AQ3: Top_3_Gaps_Observed | AR3: Immediate_Action_Taken | AS3: Preventive_Action_Required | AT3: Positive_Observations | AU3: Action_Owner | AV3: Target_Closeout_Date | AW3: Evidence_Link_or_Photo | AX3: KPI_for_PD_Attention | AY3: KPI_for_PM_Attention | AZ3: KPI_for_CM_Attention | BA3: KPI_for_HSEM_Followup | BB3: KPI_for_SE_Supervision | BC3: Leadership_Visible_Effective | BD3: Unsafe_Work_Corrected_Immediately | BE3: Best_Improved_Cluster_this_Week | BF3: Cluster_Needing_Immediate_Intervention
A4: =IF($B4="","",TEXT($B4,"yyyymmdd")&"-"&SUBSTITUTE($F4," ","")&"-"&TEXT(COUNTIF($F$4:F4,$F4),"00")) | B4: 46107 | C4: =IF($B4="","",WEEKNUM($B4,2)) | D4: =IF($B4="","",TEXT($B4,"yyyy-mm")) | E4: 4 | F4: Cluster 2A | G4: =IF(OR($E4="",$F4=""),"",IFERROR(IF($E4=INDEX(Cluster_Master!$A$4:$A$18,MATCH($F4,Cluster_Master!$B$4:$B$18,0)),"OK","CHECK"),"CHECK")) | H4: =IFERROR(INDEX(Cluster_Master!$C$4:$C$18,MATCH($F4,Cluster_Master!$B$4:$B$18,0)),"") | I4: =IFERROR(INDEX(Cluster_Master!$D$4:$D$18,MATCH($F4,Cluster_Master!$B$4:$B$18,0)),"") | J4: =IFERROR(INDEX(Cluster_Master!$E$4:$E$18,MATCH($F4,Cluster_Master!$B$4:$B$18,0)),"") | K4: =IFERROR(INDEX(Cluster_Master!$F$4:$F$18,MATCH($F4,Cluster_Master!$B$4:$B$18,0)),"") | L4: =IFERROR(INDEX(Cluster_Master!$G$4:$G$18,MATCH($F4,Cluster_Master!$B$4:$B$18,0)),"") | M4: =IFERROR(INDEX(Cluster_Master!$H$4:$H$18,MATCH($F4,Cluster_Master!$B$4:$B$18,0)),"") | N4: Godwin | O4: KEO | P4: Villa 8 to 16 | R4: Work at Height | S4: YES | T4: 2 | U4: 2 | V4: 3 | W4: 3 | X4: 2 | Y4: 3 | Z4: 1 | AA4: 3 | AC4: 3 | AD4: 1 | AE4: 1 | AF4: 2 | AG4: 1 | AH4: 2 | AI4: =IF(COUNTA(T4:AH4)=0,"",SUM(T4:AH4)) | AJ4: =IF(COUNTA(T4:AH4)=0,"",AI4/(COUNT(KPI_Weights!$A$4:$A$18)*5)) | AK4: =IF(COUNTA(T4:AH4)=0,"",SUMPRODUCT(T4:AH4,KPI_Weights!$B$4:$B$18)/5) | AL4: =IF(COUNTA(T4:AH4)=0,"",IF(SUMPRODUCT(--(T4:AH4<=1),--(KPI_Weights!$C$4:$C$18="YES"))>0,"YES","NO")) | AM4: =IF(AJ4="","",IF(AND(AL4="NO",AJ4>=0.75),"YES","NO")) | AN4: =IF(AJ4="","",IF(AJ4<0.4,"Critical",IF(AJ4<0.6,"Poor",IF(AJ4<0.75,"Needs Improvement",IF(AJ4<0.9,"Good","Excellent"))))) | AO4: YES | AP4: Leadership failure | AQ4: 1. Leadership failure 2. Poor supervision 3. Poor sub-contractor control 4. PTW failure | AR4: Unsafe work practices were suspended immediately. The CM of the cluster was called but he refused to visit the location. | AS4: 1. PTW must be controlled by the main contractor. 2. Close supervision of sub-contractors by main contractor shall be ensured. 3. Non-performing subcontractors shall not be paid and shall be removed from project. 4. Non-performing construction team shall be replaced without delays | AU4: 1-3rd recommendation by the cluster CM 4th recommendation by the PD. | AV4: 46114
A5: =IF($B5="","",TEXT($B5,"yyyymmdd")&"-"&SUBSTITUTE($F5," ","")&"-"&TEXT(COUNTIF($F$4:F5,$F5),"00")) | B5: 46107 | C5: =IF($B5="","",WEEKNUM($B5,2)) | D5: =IF($B5="","",TEXT($B5,"yyyy-mm")) | E5: 2 | F5: Cluster 8A | G5: =IF(OR($E5="",$F5=""),"",IFERROR(IF($E5=INDEX(Cluster_Master!$A$4:$A$18,MATCH($F5,Cluster_Master!$B$4:$B$18,0)),"OK","CHECK"),"CHECK")) | H5: =IFERROR(INDEX(Cluster_Master!$C$4:$C$18,MATCH($F5,Cluster_Master!$B$4:$B$18,0)),"") | I5: =IFERROR(INDEX(Cluster_Master!$D$4:$D$18,MATCH($F5,Cluster_Master!$B$4:$B$18,0)),"") | J5: =IFERROR(INDEX(Cluster_Master!$E$4:$E$18,MATCH($F5,Cluster_Master!$B$4:$B$18,0)),"") | K5: =IFERROR(INDEX(Cluster_Master!$F$4:$F$18,MATCH($F5,Cluster_Master!$B$4:$B$18,0)),"") | L5: =IFERROR(INDEX(Cluster_Master!$G$4:$G$18,MATCH($F5,Cluster_Master!$B$4:$B$18,0)),"") | M5: =IFERROR(INDEX(Cluster_Master!$H$4:$H$18,MATCH($F5,Cluster_Master!$B$4:$B$18,0)),"") | N5: Godwin | O5: KEO | P5: General | R5: Scaffolding | S5: NO | T5: 4 | U5: 4 | V5: 4 | W5: 4 | X5: 4 | Y5: 4 | Z5: 4 | AA5: 4 | AB5: 4 | AC5: 4 | AD5: 4 | AE5: 3 | AF5: 4 | AG5: 4 | AH5: 4 | AI5: =IF(COUNTA(T5:AH5)=0,"",SUM(T5:AH5)) | AJ5: =IF(COUNTA(T5:AH5)=0,"",AI5/(COUNT(KPI_Weights!$A$4:$A$18)*5)) | AK5: =IF(COUNTA(T5:AH5)=0,"",SUMPRODUCT(T5:AH5,KPI_Weights!$B$4:$B$18)/5) | AL5: =IF(COUNTA(T5:AH5)=0,"",IF(SUMPRODUCT(--(T5:AH5<=1),--(KPI_Weights!$C$4:$C$18="YES"))>0,"YES","NO")) | AM5: =IF(AJ5="","",IF(AND(AL5="NO",AJ5>=0.75),"YES","NO")) | AN5: =IF(AJ5="","",IF(AJ5<0.4,"Critical",IF(AJ5<0.6,"Poor",IF(AJ5<0.75,"Needs Improvement",IF(AJ5<0.9,"Good","Excellent"))))) | AO5: NO | AP5: Other | AQ5: No significant gap observed | AR5: The team was commended for their visible leadership in driving transformation at Cluster 8A. | AS5: The Construction Manager and his team were advised to ensure that sub-contractors do not mess up with their site. The following advise was given: 1. No payment for work if site condition is below the acceptable standard. 2. Close supervision of sub-contractors by the construction team of the main contractor. 3. Housekeeping shall be maintined for all shift. 4. Provide a temporary storage area for waste for each villa. 5. PTW shall remain under the control of the main contractor. | AU5: Construction Manager of Cluster 8A HSE Manager of TAJV | AV5: Always
A6: =IF($B6="","",TEXT($B6,"yyyymmdd")&"-"&SUBSTITUTE($F6," ","")&"-"&TEXT(COUNTIF($F$4:F6,$F6),"00")) | B6: 46111 | C6: =IF($B6="","",WEEKNUM($B6,2)) | D6: =IF($B6="","",TEXT($B6,"yyyy-mm")) | E6: 3 | F6: Cluster 4 | G6: =IF(OR($E6="",$F6=""),"",IFERROR(IF($E6=INDEX(Cluster_Master!$A$4:$A$18,MATCH($F6,Cluster_Master!$B$4:$B$18,0)),"OK","CHECK"),"CHECK")) | H6: =IFERROR(INDEX(Cluster_Master!$C$4:$C$18,MATCH($F6,Cluster_Master!$B$4:$B$18,0)),"") | I6: =IFERROR(INDEX(Cluster_Master!$D$4:$D$18,MATCH($F6,Cluster_Master!$B$4:$B$18,0)),"") | J6: =IFERROR(INDEX(Cluster_Master!$E$4:$E$18,MATCH($F6,Cluster_Master!$B$4:$B$18,0)),"") | K6: =IFERROR(INDEX(Cluster_Master!$F$4:$F$18,MATCH($F6,Cluster_Master!$B$4:$B$18,0)),"") | L6: =IFERROR(INDEX(Cluster_Master!$G$4:$G$18,MATCH($F6,Cluster_Master!$B$4:$B$18,0)),"") | M6: =IFERROR(INDEX(Cluster_Master!$H$4:$H$18,MATCH($F6,Cluster_Master!$B$4:$B$18,0)),"") | N6: Shinoj | O6: KEO | P6: Villa 8 to 16 | Q6: Block work | R6: Edge Protection | S6: NO | T6: 3 | U6: 2 | V6: 3 | W6: 3 | X6: 2 | Y6: 4 | Z6: 3 | AA6: 5 | AB6: 1 | AC6: 2 | AD6: 4 | AE6: 2 | AF6: 3 | AG6: 1 | AH6: 3 | AI6: =IF(COUNTA(T6:AH6)=0,"",SUM(T6:AH6)) | AJ6: =IF(COUNTA(T6:AH6)=0,"",AI6/(COUNT(KPI_Weights!$A$4:$A$18)*5)) | AK6: =IF(COUNTA(T6:AH6)=0,"",SUMPRODUCT(T6:AH6,KPI_Weights!$B$4:$B$18)/5) | AL6: =IF(COUNTA(T6:AH6)=0,"",IF(SUMPRODUCT(--(T6:AH6<=1),--(KPI_Weights!$C$4:$C$18="YES"))>0,"YES","NO")) | AM6: =IF(AJ6="","",IF(AND(AL6="NO",AJ6>=0.75),"YES","NO")) | AN6: =IF(AJ6="","",IF(AJ6<0.4,"Critical",IF(AJ6<0.6,"Poor",IF(AJ6<0.75,"Needs Improvement",IF(AJ6<0.9,"Good","Excellent"))))) | AO6: NO | AP6: Poor supervision | AR6: sretybhy | AS6: hfidjdgkjdfkdfgb | AV6: 46112
A7: =IF($B7="","",TEXT($B7,"yyyymmdd")&"-"&SUBSTITUTE($F7," ","")&"-"&TEXT(COUNTIF($F$4:F7,$F7),"00")) | C7: =IF($B7="","",WEEKNUM($B7,2)) | D7: =IF($B7="","",TEXT($B7,"yyyy-mm")) | G7: =IF(OR($E7="",$F7=""),"",IFERROR(IF($E7=INDEX(Cluster_Master!$A$4:$A$18,MATCH($F7,Cluster_Master!$B$4:$B$18,0)),"OK","CHECK"),"CHECK")) | H7: =IFERROR(INDEX(Cluster_Master!$C$4:$C$18,MATCH($F7,Cluster_Master!$B$4:$B$18,0)),"") | I7: =IFERROR(INDEX(Cluster_Master!$D$4:$D$18,MATCH($F7,Cluster_Master!$B$4:$B$18,0)),"") | J7: =IFERROR(INDEX(Cluster_Master!$E$4:$E$18,MATCH($F7,Cluster_Master!$B$4:$B$18,0)),"") | K7: =IFERROR(INDEX(Cluster_Master!$F$4:$F$18,MATCH($F7,Cluster_Master!$B$4:$B$18,0)),"") | L7: =IFERROR(INDEX(Cluster_Master!$G$4:$G$18,MATCH($F7,Cluster_Master!$B$4:$B$18,0)),"") | M7: =IFERROR(INDEX(Cluster_Master!$H$4:$H$18,MATCH($F7,Cluster_Master!$B$4:$B$18,0)),"") | AI7: =IF(COUNTA(T7:AH7)=0,"",SUM(T7:AH7)) | AJ7: =IF(COUNTA(T7:AH7)=0,"",AI7/(COUNT(KPI_Weights!$A$4:$A$18)*5)) | AK7: =IF(COUNTA(T7:AH7)=0,"",SUMPRODUCT(T7:AH7,KPI_Weights!$B$4:$B$18)/5) | AL7: =IF(COUNTA(T7:AH7)=0,"",IF(SUMPRODUCT(--(T7:AH7<=1),--(KPI_Weights!$C$4:$C$18="YES"))>0,"YES","NO")) | AM7: =IF(AJ7="","",IF(AND(AL7="NO",AJ7>=0.75),"YES","NO")) | AN7: =IF(AJ7="","",IF(AJ7<0.4,"Critical",IF(AJ7<0.6,"Poor",IF(AJ7<0.75,"Needs Improvement",IF(AJ7<0.9,"Good","Excellent")))))
A8: =IF($B8="","",TEXT($B8,"yyyymmdd")&"-"&SUBSTITUTE($F8," ","")&"-"&TEXT(COUNTIF($F$4:F8,$F8),"00")) | C8: =IF($B8="","",WEEKNUM($B8,2)) | D8: =IF($B8="","",TEXT($B8,"yyyy-mm")) | G8: =IF(OR($E8="",$F8=""),"",IFERROR(IF($E8=INDEX(Cluster_Master!$A$4:$A$18,MATCH($F8,Cluster_Master!$B$4:$B$18,0)),"OK","CHECK"),"CHECK")) | H8: =IFERROR(INDEX(Cluster_Master!$C$4:$C$18,MATCH($F8,Cluster_Master!$B$4:$B$18,0)),"") | I8: =IFERROR(INDEX(Cluster_Master!$D$4:$D$18,MATCH($F8,Cluster_Master!$B$4:$B$18,0)),"") | J8: =IFERROR(INDEX(Cluster_Master!$E$4:$E$18,MATCH($F8,Cluster_Master!$B$4:$B$18,0)),"") | K8: =IFERROR(INDEX(Cluster_Master!$F$4:$F$18,MATCH($F8,Cluster_Master!$B$4:$B$18,0)),"") | L8: =IFERROR(INDEX(Cluster_Master!$G$4:$G$18,MATCH($F8,Cluster_Master!$B$4:$B$18,0)),"") | M8: =IFERROR(INDEX(Cluster_Master!$H$4:$H$18,MATCH($F8,Cluster_Master!$B$4:$B$18,0)),"") | AI8: =IF(COUNTA(T8:AH8)=0,"",SUM(T8:AH8)) | AJ8: =IF(COUNTA(T8:AH8)=0,"",AI8/(COUNT(KPI_Weights!$A$4:$A$18)*5)) | AK8: =IF(COUNTA(T8:AH8)=0,"",SUMPRODUCT(T8:AH8,KPI_Weights!$B$4:$B$18)/5) | AL8: =IF(COUNTA(T8:AH8)=0,"",IF(SUMPRODUCT(--(T8:AH8<=1),--(KPI_Weights!$C$4:$C$18="YES"))>0,"YES","NO")) | AM8: =IF(AJ8="","",IF(AND(AL8="NO",AJ8>=0.75),"YES","NO")) | AN8: =IF(AJ8="","",IF(AJ8<0.4,"Critical",IF(AJ8<0.6,"Poor",IF(AJ8<0.75,"Needs Improvement",IF(AJ8<0.9,"Good","Excellent")))))
A9: =IF($B9="","",TEXT($B9,"yyyymmdd")&"-"&SUBSTITUTE($F9," ","")&"-"&TEXT(COUNTIF($F$4:F9,$F9),"00")) | C9: =IF($B9="","",WEEKNUM($B9,2)) | D9: =IF($B9="","",TEXT($B9,"yyyy-mm")) | G9: =IF(OR($E9="",$F9=""),"",IFERROR(IF($E9=INDEX(Cluster_Master!$A$4:$A$18,MATCH($F9,Cluster_Master!$B$4:$B$18,0)),"OK","CHECK"),"CHECK")) | H9: =IFERROR(INDEX(Cluster_Master!$C$4:$C$18,MATCH($F9,Cluster_Master!$B$4:$B$18,0)),"") | I9: =IFERROR(INDEX(Cluster_Master!$D$4:$D$18,MATCH($F9,Cluster_Master!$B$4:$B$18,0)),"") | J9: =IFERROR(INDEX(Cluster_Master!$E$4:$E$18,MATCH($F9,Cluster_Master!$B$4:$B$18,0)),"") | K9: =IFERROR(INDEX(Cluster_Master!$F$4:$F$18,MATCH($F9,Cluster_Master!$B$4:$B$18,0)),"") | L9: =IFERROR(INDEX(Cluster_Master!$G$4:$G$18,MATCH($F9,Cluster_Master!$B$4:$B$18,0)),"") | M9: =IFERROR(INDEX(Cluster_Master!$H$4:$H$18,MATCH($F9,Cluster_Master!$B$4:$B$18,0)),"") | AI9: =IF(COUNTA(T9:AH9)=0,"",SUM(T9:AH9)) | AJ9: =IF(COUNTA(T9:AH9)=0,"",AI9/(COUNT(KPI_Weights!$A$4:$A$18)*5)) | AK9: =IF(COUNTA(T9:AH9)=0,"",SUMPRODUCT(T9:AH9,KPI_Weights!$B$4:$B$18)/5) | AL9: =IF(COUNTA(T9:AH9)=0,"",IF(SUMPRODUCT(--(T9:AH9<=1),--(KPI_Weights!$C$4:$C$18="YES"))>0,"YES","NO")) | AM9: =IF(AJ9="","",IF(AND(AL9="NO",AJ9>=0.75),"YES","NO")) | AN9: =IF(AJ9="","",IF(AJ9<0.4,"Critical",IF(AJ9<0.6,"Poor",IF(AJ9<0.75,"Needs Improvement",IF(AJ9<0.9,"Good","Excellent")))))
A10: =IF($B10="","",TEXT($B10,"yyyymmdd")&"-"&SUBSTITUTE($F10," ","")&"-"&TEXT(COUNTIF($F$4:F10,$F10),"00")) | C10: =IF($B10="","",WEEKNUM($B10,2)) | D10: =IF($B10="","",TEXT($B10,"yyyy-mm")) | G10: =IF(OR($E10="",$F10=""),"",IFERROR(IF($E10=INDEX(Cluster_Master!$A$4:$A$18,MATCH($F10,Cluster_Master!$B$4:$B$18,0)),"OK","CHECK"),"CHECK")) | H10: =IFERROR(INDEX(Cluster_Master!$C$4:$C$18,MATCH($F10,Cluster_Master!$B$4:$B$18,0)),"") | I10: =IFERROR(INDEX(Cluster_Master!$D$4:$D$18,MATCH($F10,Cluster_Master!$B$4:$B$18,0)),"") | J10: =IFERROR(INDEX(Cluster_Master!$E$4:$E$18,MATCH($F10,Cluster_Master!$B$4:$B$18,0)),"") | K10: =IFERROR(INDEX(Cluster_Master!$F$4:$F$18,MATCH($F10,Cluster_Master!$B$4:$B$18,0)),"") | L10: =IFERROR(INDEX(Cluster_Master!$G$4:$G$18,MATCH($F10,Cluster_Master!$B$4:$B$18,0)),"") | M10: =IFERROR(INDEX(Cluster_Master!$H$4:$H$18,MATCH($F10,Cluster_Master!$B$4:$B$18,0)),"") | AI10: =IF(COUNTA(T10:AH10)=0,"",SUM(T10:AH10)) | AJ10: =IF(COUNTA(T10:AH10)=0,"",AI10/(COUNT(KPI_Weights!$A$4:$A$18)*5)) | AK10: =IF(COUNTA(T10:AH10)=0,"",SUMPRODUCT(T10:AH10,KPI_Weights!$B$4:$B$18)/5) | AL10: =IF(COUNTA(T10:AH10)=0,"",IF(SUMPRODUCT(--(T10:AH10<=1),--(KPI_Weights!$C$4:$C$18="YES"))>0,"YES","NO")) | AM10: =IF(AJ10="","",IF(AND(AL10="NO",AJ10>=0.75),"YES","NO")) | AN10: =IF(AJ10="","",IF(AJ10<0.4,"Critical",IF(AJ10<0.6,"Poor",IF(AJ10<0.75,"Needs Improvement",IF(AJ10<0.9,"Good","Excellent")))))
A11: =IF($B11="","",TEXT($B11,"yyyymmdd")&"-"&SUBSTITUTE($F11," ","")&"-"&TEXT(COUNTIF($F$4:F11,$F11),"00")) | C11: =IF($B11="","",WEEKNUM($B11,2)) | D11: =IF($B11="","",TEXT($B11,"yyyy-mm")) | G11: =IF(OR($E11="",$F11=""),"",IFERROR(IF($E11=INDEX(Cluster_Master!$A$4:$A$18,MATCH($F11,Cluster_Master!$B$4:$B$18,0)),"OK","CHECK"),"CHECK")) | H11: =IFERROR(INDEX(Cluster_Master!$C$4:$C$18,MATCH($F11,Cluster_Master!$B$4:$B$18,0)),"") | I11: =IFERROR(INDEX(Cluster_Master!$D$4:$D$18,MATCH($F11,Cluster_Master!$B$4:$B$18,0)),"") | J11: =IFERROR(INDEX(Cluster_Master!$E$4:$E$18,MATCH($F11,Cluster_Master!$B$4:$B$18,0)),"") | K11: =IFERROR(INDEX(Cluster_Master!$F$4:$F$18,MATCH($F11,Cluster_Master!$B$4:$B$18,0)),"") | L11: =IFERROR(INDEX(Cluster_Master!$G$4:$G$18,MATCH($F11,Cluster_Master!$B$4:$B$18,0)),"") | M11: =IFERROR(INDEX(Cluster_Master!$H$4:$H$18,MATCH($F11,Cluster_Master!$B$4:$B$18,0)),"") | AI11: =IF(COUNTA(T11:AH11)=0,"",SUM(T11:AH11)) | AJ11: =IF(COUNTA(T11:AH11)=0,"",AI11/(COUNT(KPI_Weights!$A$4:$A$18)*5)) | AK11: =IF(COUNTA(T11:AH11)=0,"",SUMPRODUCT(T11:AH11,KPI_Weights!$B$4:$B$18)/5) | AL11: =IF(COUNTA(T11:AH11)=0,"",IF(SUMPRODUCT(--(T11:AH11<=1),--(KPI_Weights!$C$4:$C$18="YES"))>0,"YES","NO")) | AM11: =IF(AJ11="","",IF(AND(AL11="NO",AJ11>=0.75),"YES","NO")) | AN11: =IF(AJ11="","",IF(AJ11<0.4,"Critical",IF(AJ11<0.6,"Poor",IF(AJ11<0.75,"Needs Improvement",IF(AJ11<0.9,"Good","Excellent")))))
A12: =IF($B12="","",TEXT($B12,"yyyymmdd")&"-"&SUBSTITUTE($F12," ","")&"-"&TEXT(COUNTIF($F$4:F12,$F12),"00")) | C12: =IF($B12="","",WEEKNUM($B12,2)) | D12: =IF($B12="","",TEXT($B12,"yyyy-mm")) | G12: =IF(OR($E12="",$F12=""),"",IFERROR(IF($E12=INDEX(Cluster_Master!$A$4:$A$18,MATCH($F12,Cluster_Master!$B$4:$B$18,0)),"OK","CHECK"),"CHECK")) | H12: =IFERROR(INDEX(Cluster_Master!$C$4:$C$18,MATCH($F12,Cluster_Master!$B$4:$B$18,0)),"") | I12: =IFERROR(INDEX(Cluster_Master!$D$4:$D$18,MATCH($F12,Cluster_Master!$B$4:$B$18,0)),"") | J12: =IFERROR(INDEX(Cluster_Master!$E$4:$E$18,MATCH($F12,Cluster_Master!$B$4:$B$18,0)),"") | K12: =IFERROR(INDEX(Cluster_Master!$F$4:$F$18,MATCH($F12,Cluster_Master!$B$4:$B$18,0)),"") | L12: =IFERROR(INDEX(Cluster_Master!$G$4:$G$18,MATCH($F12,Cluster_Master!$B$4:$B$18,0)),"") | M12: =IFERROR(INDEX(Cluster_Master!$H$4:$H$18,MATCH($F12,Cluster_Master!$B$4:$B$18,0)),"") | AI12: =IF(COUNTA(T12:AH12)=0,"",SUM(T12:AH12)) | AJ12: =IF(COUNTA(T12:AH12)=0,"",AI12/(COUNT(KPI_Weights!$A$4:$A$18)*5)) | AK12: =IF(COUNTA(T12:AH12)=0,"",SUMPRODUCT(T12:AH12,KPI_Weights!$B$4:$B$18)/5) | AL12: =IF(COUNTA(T12:AH12)=0,"",IF(SUMPRODUCT(--(T12:AH12<=1),--(KPI_Weights!$C$4:$C$18="YES"))>0,"YES","NO")) | AM12: =IF(AJ12="","",IF(AND(AL12="NO",AJ12>=0.75),"YES","NO")) | AN12: =IF(AJ12="","",IF(AJ12<0.4,"Critical",IF(AJ12<0.6,"Poor",IF(AJ12<0.75,"Needs Improvement",IF(AJ12<0.9,"Good","Excellent")))))
A13: =IF($B13="","",TEXT($B13,"yyyymmdd")&"-"&SUBSTITUTE($F13," ","")&"-"&TEXT(COUNTIF($F$4:F13,$F13),"00")) | C13: =IF($B13="","",WEEKNUM($B13,2)) | D13: =IF($B13="","",TEXT($B13,"yyyy-mm")) | G13: =IF(OR($E13="",$F13=""),"",IFERROR(IF($E13=INDEX(Cluster_Master!$A$4:$A$18,MATCH($F13,Cluster_Master!$B$4:$B$18,0)),"OK","CHECK"),"CHECK")) | H13: =IFERROR(INDEX(Cluster_Master!$C$4:$C$18,MATCH($F13,Cluster_Master!$B$4:$B$18,0)),"") | I13: =IFERROR(INDEX(Cluster_Master!$D$4:$D$18,MATCH($F13,Cluster_Master!$B$4:$B$18,0)),"") | J13: =IFERROR(INDEX(Cluster_Master!$E$4:$E$18,MATCH($F13,Cluster_Master!$B$4:$B$18,0)),"") | K13: =IFERROR(INDEX(Cluster_Master!$F$4:$F$18,MATCH($F13,Cluster_Master!$B$4:$B$18,0)),"") | L13: =IFERROR(INDEX(Cluster_Master!$G$4:$G$18,MATCH($F13,Cluster_Master!$B$4:$B$18,0)),"") | M13: =IFERROR(INDEX(Cluster_Master!$H$4:$H$18,MATCH($F13,Cluster_Master!$B$4:$B$18,0)),"") | AI13: =IF(COUNTA(T13:AH13)=0,"",SUM(T13:AH13)) | AJ13: =IF(COUNTA(T13:AH13)=0,"",AI13/(COUNT(KPI_Weights!$A$4:$A$18)*5)) | AK13: =IF(COUNTA(T13:AH13)=0,"",SUMPRODUCT(T13:AH13,KPI_Weights!$B$4:$B$18)/5) | AL13: =IF(COUNTA(T13:AH13)=0,"",IF(SUMPRODUCT(--(T13:AH13<=1),--(KPI_Weights!$C$4:$C$18="YES"))>0,"YES","NO")) | AM13: =IF(AJ13="","",IF(AND(AL13="NO",AJ13>=0.75),"YES","NO")) | AN13: =IF(AJ13="","",IF(AJ13<0.4,"Critical",IF(AJ13<0.6,"Poor",IF(AJ13<0.75,"Needs Improvement",IF(AJ13<0.9,"Good","Excellent")))))
A14: =IF($B14="","",TEXT($B14,"yyyymmdd")&"-"&SUBSTITUTE($F14," ","")&"-"&TEXT(COUNTIF($F$4:F14,$F14),"00")) | C14: =IF($B14="","",WEEKNUM($B14,2)) | D14: =IF($B14="","",TEXT($B14,"yyyy-mm")) | G14: =IF(OR($E14="",$F14=""),"",IFERROR(IF($E14=INDEX(Cluster_Master!$A$4:$A$18,MATCH($F14,Cluster_Master!$B$4:$B$18,0)),"OK","CHECK"),"CHECK")) | H14: =IFERROR(INDEX(Cluster_Master!$C$4:$C$18,MATCH($F14,Cluster_Master!$B$4:$B$18,0)),"") | I14: =IFERROR(INDEX(Cluster_Master!$D$4:$D$18,MATCH($F14,Cluster_Master!$B$4:$B$18,0)),"") | J14: =IFERROR(INDEX(Cluster_Master!$E$4:$E$18,MATCH($F14,Cluster_Master!$B$4:$B$18,0)),"") | K14: =IFERROR(INDEX(Cluster_Master!$F$4:$F$18,MATCH($F14,Cluster_Master!$B$4:$B$18,0)),"") | L14: =IFERROR(INDEX(Cluster_Master!$G$4:$G$18,MATCH($F14,Cluster_Master!$B$4:$B$18,0)),"") | M14: =IFERROR(INDEX(Cluster_Master!$H$4:$H$18,MATCH($F14,Cluster_Master!$B$4:$B$18,0)),"") | AI14: =IF(COUNTA(T14:AH14)=0,"",SUM(T14:AH14)) | AJ14: =IF(COUNTA(T14:AH14)=0,"",AI14/(COUNT(KPI_Weights!$A$4:$A$18)*5)) | AK14: =IF(COUNTA(T14:AH14)=0,"",SUMPRODUCT(T14:AH14,KPI_Weights!$B$4:$B$18)/5) | AL14: =IF(COUNTA(T14:AH14)=0,"",IF(SUMPRODUCT(--(T14:AH14<=1),--(KPI_Weights!$C$4:$C$18="YES"))>0,"YES","NO")) | AM14: =IF(AJ14="","",IF(AND(AL14="NO",AJ14>=0.75),"YES","NO")) | AN14: =IF(AJ14="","",IF(AJ14<0.4,"Critical",IF(AJ14<0.6,"Poor",IF(AJ14<0.75,"Needs Improvement",IF(AJ14<0.9,"Good","Excellent")))))
A15: =IF($B15="","",TEXT($B15,"yyyymmdd")&"-"&SUBSTITUTE($F15," ","")&"-"&TEXT(COUNTIF($F$4:F15,$F15),"00")) | C15: =IF($B15="","",WEEKNUM($B15,2)) | D15: =IF($B15="","",TEXT($B15,"yyyy-mm")) | G15: =IF(OR($E15="",$F15=""),"",IFERROR(IF($E15=INDEX(Cluster_Master!$A$4:$A$18,MATCH($F15,Cluster_Master!$B$4:$B$18,0)),"OK","CHECK"),"CHECK")) | H15: =IFERROR(INDEX(Cluster_Master!$C$4:$C$18,MATCH($F15,Cluster_Master!$B$4:$B$18,0)),"") | I15: =IFERROR(INDEX(Cluster_Master!$D$4:$D$18,MATCH($F15,Cluster_Master!$B$4:$B$18,0)),"") | J15: =IFERROR(INDEX(Cluster_Master!$E$4:$E$18,MATCH($F15,Cluster_Master!$B$4:$B$18,0)),"") | K15: =IFERROR(INDEX(Cluster_Master!$F$4:$F$18,MATCH($F15,Cluster_Master!$B$4:$B$18,0)),"") | L15: =IFERROR(INDEX(Cluster_Master!$G$4:$G$18,MATCH($F15,Cluster_Master!$B$4:$B$18,0)),"") | M15: =IFERROR(INDEX(Cluster_Master!$H$4:$H$18,MATCH($F15,Cluster_Master!$B$4:$B$18,0)),"") | AI15: =IF(COUNTA(T15:AH15)=0,"",SUM(T15:AH15)) | AJ15: =IF(COUNTA(T15:AH15)=0,"",AI15/(COUNT(KPI_Weights!$A$4:$A$18)*5)) | AK15: =IF(COUNTA(T15:AH15)=0,"",SUMPRODUCT(T15:AH15,KPI_Weights!$B$4:$B$18)/5) | AL15: =IF(COUNTA(T15:AH15)=0,"",IF(SUMPRODUCT(--(T15:AH15<=1),--(KPI_Weights!$C$4:$C$18="YES"))>0,"YES","NO")) | AM15: =IF(AJ15="","",IF(AND(AL15="NO",AJ15>=0.75),"YES","NO")) | AN15: =IF(AJ15="","",IF(AJ15<0.4,"Critical",IF(AJ15<0.6,"Poor",IF(AJ15<0.75,"Needs Improvement",IF(AJ15<0.9,"Good","Excellent")))))
A16: =IF($B16="","",TEXT($B16,"yyyymmdd")&"-"&SUBSTITUTE($F16," ","")&"-"&TEXT(COUNTIF($F$4:F16,$F16),"00")) | C16: =IF($B16="","",WEEKNUM($B16,2)) | D16: =IF($B16="","",TEXT($B16,"yyyy-mm")) | G16: =IF(OR($E16="",$F16=""),"",IFERROR(IF($E16=INDEX(Cluster_Master!$A$4:$A$18,MATCH($F16,Cluster_Master!$B$4:$B$18,0)),"OK","CHECK"),"CHECK")) | H16: =IFERROR(INDEX(Cluster_Master!$C$4:$C$18,MATCH($F16,Cluster_Master!$B$4:$B$18,0)),"") | I16: =IFERROR(INDEX(Cluster_Master!$D$4:$D$18,MATCH($F16,Cluster_Master!$B$4:$B$18,0)),"") | J16: =IFERROR(INDEX(Cluster_Master!$E$4:$E$18,MATCH($F16,Cluster_Master!$B$4:$B$18,0)),"") | K16: =IFERROR(INDEX(Cluster_Master!$F$4:$F$18,MATCH($F16,Cluster_Master!$B$4:$B$18,0)),"") | L16: =IFERROR(INDEX(Cluster_Master!$G$4:$G$18,MATCH($F16,Cluster_Master!$B$4:$B$18,0)),"") | M16: =IFERROR(INDEX(Cluster_Master!$H$4:$H$18,MATCH($F16,Cluster_Master!$B$4:$B$18,0)),"") | AI16: =IF(COUNTA(T16:AH16)=0,"",SUM(T16:AH16)) | AJ16: =IF(COUNTA(T16:AH16)=0,"",AI16/(COUNT(KPI_Weights!$A$4:$A$18)*5)) | AK16: =IF(COUNTA(T16:AH16)=0,"",SUMPRODUCT(T16:AH16,KPI_Weights!$B$4:$B$18)/5) | AL16: =IF(COUNTA(T16:AH16)=0,"",IF(SUMPRODUCT(--(T16:AH16<=1),--(KPI_Weights!$C$4:$C$18="YES"))>0,"YES","NO")) | AM16: =IF(AJ16="","",IF(AND(AL16="NO",AJ16>=0.75),"YES","NO")) | AN16: =IF(AJ16="","",IF(AJ16<0.4,"Critical",IF(AJ16<0.6,"Poor",IF(AJ16<0.75,"Needs Improvement",IF(AJ16<0.9,"Good","Excellent")))))
A17: =IF($B17="","",TEXT($B17,"yyyymmdd")&"-"&SUBSTITUTE($F17," ","")&"-"&TEXT(COUNTIF($F$4:F17,$F17),"00")) | C17: =IF($B17="","",WEEKNUM($B17,2)) | D17: =IF($B17="","",TEXT($B17,"yyyy-mm")) | G17: =IF(OR($E17="",$F17=""),"",IFERROR(IF($E17=INDEX(Cluster_Master!$A$4:$A$18,MATCH($F17,Cluster_Master!$B$4:$B$18,0)),"OK","CHECK"),"CHECK")) | H17: =IFERROR(INDEX(Cluster_Master!$C$4:$C$18,MATCH($F17,Cluster_Master!$B$4:$B$18,0)),"") | I17: =IFERROR(INDEX(Cluster_Master!$D$4:$D$18,MATCH($F17,Cluster_Master!$B$4:$B$18,0)),"") | J17: =IFERROR(INDEX(Cluster_Master!$E$4:$E$18,MATCH($F17,Cluster_Master!$B$4:$B$18,0)),"") | K17: =IFERROR(INDEX(Cluster_Master!$F$4:$F$18,MATCH($F17,Cluster_Master!$B$4:$B$18,0)),"") | L17: =IFERROR(INDEX(Cluster_Master!$G$4:$G$18,MATCH($F17,Cluster_Master!$B$4:$B$18,0)),"") | M17: =IFERROR(INDEX(Cluster_Master!$H$4:$H$18,MATCH($F17,Cluster_Master!$B$4:$B$18,0)),"") | AI17: =IF(COUNTA(T17:AH17)=0,"",SUM(T17:AH17)) | AJ17: =IF(COUNTA(T17:AH17)=0,"",AI17/(COUNT(KPI_Weights!$A$4:$A$18)*5)) | AK17: =IF(COUNTA(T17:AH17)=0,"",SUMPRODUCT(T17:AH17,KPI_Weights!$B$4:$B$18)/5) | AL17: =IF(COUNTA(T17:AH17)=0,"",IF(SUMPRODUCT(--(T17:AH17<=1),--(KPI_Weights!$C$4:$C$18="YES"))>0,"YES","NO")) | AM17: =IF(AJ17="","",IF(AND(AL17="NO",AJ17>=0.75),"YES","NO")) | AN17: =IF(AJ17="","",IF(AJ17<0.4,"Critical",IF(AJ17<0.6,"Poor",IF(AJ17<0.75,"Needs Improvement",IF(AJ17<0.9,"Good","Excellent")))))
A18: =IF($B18="","",TEXT($B18,"yyyymmdd")&"-"&SUBSTITUTE($F18," ","")&"-"&TEXT(COUNTIF($F$4:F18,$F18),"00")) | C18: =IF($B18="","",WEEKNUM($B18,2)) | D18: =IF($B18="","",TEXT($B18,"yyyy-mm")) | G18: =IF(OR($E18="",$F18=""),"",IFERROR(IF($E18=INDEX(Cluster_Master!$A$4:$A$18,MATCH($F18,Cluster_Master!$B$4:$B$18,0)),"OK","CHECK"),"CHECK")) | H18: =IFERROR(INDEX(Cluster_Master!$C$4:$C$18,MATCH($F18,Cluster_Master!$B$4:$B$18,0)),"") | I18: =IFERROR(INDEX(Cluster_Master!$D$4:$D$18,MATCH($F18,Cluster_Master!$B$4:$B$18,0)),"") | J18: =IFERROR(INDEX(Cluster_Master!$E$4:$E$18,MATCH($F18,Cluster_Master!$B$4:$B$18,0)),"") | K18: =IFERROR(INDEX(Cluster_Master!$F$4:$F$18,MATCH($F18,Cluster_Master!$B$4:$B$18,0)),"") | L18: =IFERROR(INDEX(Cluster_Master!$G$4:$G$18,MATCH($F18,Cluster_Master!$B$4:$B$18,0)),"") | M18: =IFERROR(INDEX(Cluster_Master!$H$4:$H$18,MATCH($F18,Cluster_Master!$B$4:$B$18,0)),"") | AI18: =IF(COUNTA(T18:AH18)=0,"",SUM(T18:AH18)) | AJ18: =IF(COUNTA(T18:AH18)=0,"",AI18/(COUNT(KPI_Weights!$A$4:$A$18)*5)) | AK18: =IF(COUNTA(T18:AH18)=0,"",SUMPRODUCT(T18:AH18,KPI_Weights!$B$4:$B$18)/5) | AL18: =IF(COUNTA(T18:AH18)=0,"",IF(SUMPRODUCT(--(T18:AH18<=1),--(KPI_Weights!$C$4:$C$18="YES"))>0,"YES","NO")) | AM18: =IF(AJ18="","",IF(AND(AL18="NO",AJ18>=0.75),"YES","NO")) | AN18: =IF(AJ18="","",IF(AJ18<0.4,"Critical",IF(AJ18<0.6,"Poor",IF(AJ18<0.75,"Needs Improvement",IF(AJ18<0.9,"Good","Excellent")))))
... A996: =IF($B996="","",TEXT($B996,"yyyymmdd")&"-"&SUBSTITUTE($F996," ","")&"-"&TEXT(COUNTIF($F$4:F996,$F996),"00")) | C996: =IF($B996="","",WEEKNUM($B996,2)) | D996: =IF($B996="","",TEXT($B996,"yyyy-mm")) | G996: =IF(OR($E996="",$F996=""),"",IFERROR(IF($E996=INDEX(Cluster_Master!$A$4:$A$18,MATCH($F996,Cluster_Master!$B$4:$B$18,0)),"OK","CHECK"),"CHECK")) | H996: =IFERROR(INDEX(Cluster_Master!$C$4:$C$18,MATCH($F996,Cluster_Master!$B$4:$B$18,0)),"") | I996: =IFERROR(INDEX(Cluster_Master!$D$4:$D$18,MATCH($F996,Cluster_Master!$B$4:$B$18,0)),"") | J996: =IFERROR(INDEX(Cluster_Master!$E$4:$E$18,MATCH($F996,Cluster_Master!$B$4:$B$18,0)),"") | K996: =IFERROR(INDEX(Cluster_Master!$F$4:$F$18,MATCH($F996,Cluster_Master!$B$4:$B$18,0)),"") | L996: =IFERROR(INDEX(Cluster_Master!$G$4:$G$18,MATCH($F996,Cluster_Master!$B$4:$B$18,0)),"") | M996: =IFERROR(INDEX(Cluster_Master!$H$4:$H$18,MATCH($F996,Cluster_Master!$B$4:$B$18,0)),"") | AI996: =IF(COUNTA(T996:AH996)=0,"",SUM(T996:AH996)) | AJ996: =IF(COUNTA(T996:AH996)=0,"",AI996/(COUNT(KPI_Weights!$A$4:$A$18)*5)) | AK996: =IF(COUNTA(T996:AH996)=0,"",SUMPRODUCT(T996:AH996,KPI_Weights!$B$4:$B$18)/5) | AL996: =IF(COUNTA(T996:AH996)=0,"",IF(SUMPRODUCT(--(T996:AH996<=1),--(KPI_Weights!$C$4:$C$18="YES"))>0,"YES","NO")) | AM996: =IF(AJ996="","",IF(AND(AL996="NO",AJ996>=0.75),"YES","NO")) | AN996: =IF(AJ996="","",IF(AJ996<0.4,"Critical",IF(AJ996<0.6,"Poor",IF(AJ996<0.75,"Needs Improvement",IF(AJ996<0.9,"Good","Excellent")))))

Sheet Weekly_Dashboard
A1: Weekly Dashboard
A2: Set the control week and month in blue-font cells. This sheet summarizes weekly and current month performance by cluster and highlights weak KPIs / root causes.
A4: Control inputs
A5: Selected Week No | B5: =IFERROR(MAX(Weekly_Inspections!$C$4:$C$996),"")
A6: Selected Month (yyyy-mm) | B6: =IFERROR(LOOKUP(2,1/(Weekly_Inspections!$D$4:$D$996<>""),Weekly_Inspections!$D$4:$D$996),"")
A7: Previous Month (yyyy-mm) | B7: =IF($B$6="","",TEXT(EDATE(DATE(VALUE(LEFT($B$6,4)),VALUE(RIGHT($B$6,2)),1),-1),"yyyy-mm"))
A9: Cluster | B9: Package | C9: Contractor | D9: Week Avg Raw % | E9: Week Avg Weighted % | F9: Week Red Flags | G9: Month Avg Raw % | H9: Month Avg Weighted % | I9: Month Red Flags | J9: Month Improvement | K9: Award Eligible | L9: Rank
A10: Cluster 7A | B10: =IFERROR(INDEX(Cluster_Master!$A$4:$A$18,MATCH($A10,Cluster_Master!$B$4:$B$18,0)),"") | C10: =IFERROR(INDEX(Cluster_Master!$C$4:$C$18,MATCH($A10,Cluster_Master!$B$4:$B$18,0)),"") | D10: =IF($B$5="","",IFERROR(AVERAGEIFS(Weekly_Inspections!$AJ$4:$AJ$996,Weekly_Inspections!$F$4:$F$996,$A10,Weekly_Inspections!$C$4:$C$996,$B$5),"")) | E10: =IF($B$5="","",IFERROR(AVERAGEIFS(Weekly_Inspections!$AK$4:$AK$996,Weekly_Inspections!$F$4:$F$996,$A10,Weekly_Inspections!$C$4:$C$996,$B$5),"")) | F10: =IF($B$5="","",COUNTIFS(Weekly_Inspections!$F$4:$F$996,$A10,Weekly_Inspections!$C$4:$C$996,$B$5,Weekly_Inspections!$AL$4:$AL$996,"YES")) | G10: =IF($B$6="","",IFERROR(AVERAGEIFS(Weekly_Inspections!$AJ$4:$AJ$996,Weekly_Inspections!$F$4:$F$996,$A10,Weekly_Inspections!$D$4:$D$996,$B$6),"")) | H10: =IF($B$6="","",IFERROR(AVERAGEIFS(Weekly_Inspections!$AK$4:$AK$996,Weekly_Inspections!$F$4:$F$996,$A10,Weekly_Inspections!$D$4:$D$996,$B$6),"")) | I10: =IF($B$6="","",COUNTIFS(Weekly_Inspections!$F$4:$F$996,$A10,Weekly_Inspections!$D$4:$D$996,$B$6,Weekly_Inspections!$AL$4:$AL$996,"YES")) | J10: =IF(OR($B$6="",$B$7=""),"",IFERROR((G10-AVERAGEIFS(Weekly_Inspections!$AJ$4:$AJ$996,Weekly_Inspections!$F$4:$F$996,$A10,Weekly_Inspections!$D$4:$D$996,$B$7))/AVERAGEIFS(Weekly_Inspections!$AJ$4:$AJ$996,Weekly_Inspections!$F$4:$F$996,$A10,Weekly_Inspections!$D$4:$D$996,$B$7),"")) | K10: =IF(G10="","",IF(AND(I10=0,G10>=0.75),"YES","NO")) | L10: =IF(G10="","",RANK(G10,$G$10:$G$24,0))
A11: Cluster 7B | B11: =IFERROR(INDEX(Cluster_Master!$A$4:$A$18,MATCH($A11,Cluster_Master!$B$4:$B$18,0)),"") | C11: =IFERROR(INDEX(Cluster_Master!$C$4:$C$18,MATCH($A11,Cluster_Master!$B$4:$B$18,0)),"") | D11: =IF($B$5="","",IFERROR(AVERAGEIFS(Weekly_Inspections!$AJ$4:$AJ$996,Weekly_Inspections!$F$4:$F$996,$A11,Weekly_Inspections!$C$4:$C$996,$B$5),"")) | E11: =IF($B$5="","",IFERROR(AVERAGEIFS(Weekly_Inspections!$AK$4:$AK$996,Weekly_Inspections!$F$4:$F$996,$A11,Weekly_Inspections!$C$4:$C$996,$B$5),"")) | F11: =IF($B$5="","",COUNTIFS(Weekly_Inspections!$F$4:$F$996,$A11,Weekly_Inspections!$C$4:$C$996,$B$5,Weekly_Inspections!$AL$4:$AL$996,"YES")) | G11: =IF($B$6="","",IFERROR(AVERAGEIFS(Weekly_Inspections!$AJ$4:$AJ$996,Weekly_Inspections!$F$4:$F$996,$A11,Weekly_Inspections!$D$4:$D$996,$B$6),"")) | H11: =IF($B$6="","",IFERROR(AVERAGEIFS(Weekly_Inspections!$AK$4:$AK$996,Weekly_Inspections!$F$4:$F$996,$A11,Weekly_Inspections!$D$4:$D$996,$B$6),"")) | I11: =IF($B$6="","",COUNTIFS(Weekly_Inspections!$F$4:$F$996,$A11,Weekly_Inspections!$D$4:$D$996,$B$6,Weekly_Inspections!$AL$4:$AL$996,"YES")) | J11: =IF(OR($B$6="",$B$7=""),"",IFERROR((G11-AVERAGEIFS(Weekly_Inspections!$AJ$4:$AJ$996,Weekly_Inspections!$F$4:$F$996,$A11,Weekly_Inspections!$D$4:$D$996,$B$7))/AVERAGEIFS(Weekly_Inspections!$AJ$4:$AJ$996,Weekly_Inspections!$F$4:$F$996,$A11,Weekly_Inspections!$D$4:$D$996,$B$7),"")) | K11: =IF(G11="","",IF(AND(I11=0,G11>=0.75),"YES","NO")) | L11: =IF(G11="","",RANK(G11,$G$10:$G$24,0))
A12: Cluster 8A | B12: =IFERROR(INDEX(Cluster_Master!$A$4:$A$18,MATCH($A12,Cluster_Master!$B$4:$B$18,0)),"") | C12: =IFERROR(INDEX(Cluster_Master!$C$4:$C$18,MATCH($A12,Cluster_Master!$B$4:$B$18,0)),"") | D12: =IF($B$5="","",IFERROR(AVERAGEIFS(Weekly_Inspections!$AJ$4:$AJ$996,Weekly_Inspections!$F$4:$F$996,$A12,Weekly_Inspections!$C$4:$C$996,$B$5),"")) | E12: =IF($B$5="","",IFERROR(AVERAGEIFS(Weekly_Inspections!$AK$4:$AK$996,Weekly_Inspections!$F$4:$F$996,$A12,Weekly_Inspections!$C$4:$C$996,$B$5),"")) | F12: =IF($B$5="","",COUNTIFS(Weekly_Inspections!$F$4:$F$996,$A12,Weekly_Inspections!$C$4:$C$996,$B$5,Weekly_Inspections!$AL$4:$AL$996,"YES")) | G12: =IF($B$6="","",IFERROR(AVERAGEIFS(Weekly_Inspections!$AJ$4:$AJ$996,Weekly_Inspections!$F$4:$F$996,$A12,Weekly_Inspections!$D$4:$D$996,$B$6),"")) | H12: =IF($B$6="","",IFERROR(AVERAGEIFS(Weekly_Inspections!$AK$4:$AK$996,Weekly_Inspections!$F$4:$F$996,$A12,Weekly_Inspections!$D$4:$D$996,$B$6),"")) | I12: =IF($B$6="","",COUNTIFS(Weekly_Inspections!$F$4:$F$996,$A12,Weekly_Inspections!$D$4:$D$996,$B$6,Weekly_Inspections!$AL$4:$AL$996,"YES")) | J12: =IF(OR($B$6="",$B$7=""),"",IFERROR((G12-AVERAGEIFS(Weekly_Inspections!$AJ$4:$AJ$996,Weekly_Inspections!$F$4:$F$996,$A12,Weekly_Inspections!$D$4:$D$996,$B$7))/AVERAGEIFS(Weekly_Inspections!$AJ$4:$AJ$996,Weekly_Inspections!$F$4:$F$996,$A12,Weekly_Inspections!$D$4:$D$996,$B$7),"")) | K12: =IF(G12="","",IF(AND(I12=0,G12>=0.75),"YES","NO")) | L12: =IF(G12="","",RANK(G12,$G$10:$G$24,0))
A13: Cluster 8B | B13: =IFERROR(INDEX(Cluster_Master!$A$4:$A$18,MATCH($A13,Cluster_Master!$B$4:$B$18,0)),"") | C13: =IFERROR(INDEX(Cluster_Master!$C$4:$C$18,MATCH($A13,Cluster_Master!$B$4:$B$18,0)),"") | D13: =IF($B$5="","",IFERROR(AVERAGEIFS(Weekly_Inspections!$AJ$4:$AJ$996,Weekly_Inspections!$F$4:$F$996,$A13,Weekly_Inspections!$C$4:$C$996,$B$5),"")) | E13: =IF($B$5="","",IFERROR(AVERAGEIFS(Weekly_Inspections!$AK$4:$AK$996,Weekly_Inspections!$F$4:$F$996,$A13,Weekly_Inspections!$C$4:$C$996,$B$5),"")) | F13: =IF($B$5="","",COUNTIFS(Weekly_Inspections!$F$4:$F$996,$A13,Weekly_Inspections!$C$4:$C$996,$B$5,Weekly_Inspections!$AL$4:$AL$996,"YES")) | G13: =IF($B$6="","",IFERROR(AVERAGEIFS(Weekly_Inspections!$AJ$4:$AJ$996,Weekly_Inspections!$F$4:$F$996,$A13,Weekly_Inspections!$D$4:$D$996,$B$6),"")) | H13: =IF($B$6="","",IFERROR(AVERAGEIFS(Weekly_Inspections!$AK$4:$AK$996,Weekly_Inspections!$F$4:$F$996,$A13,Weekly_Inspections!$D$4:$D$996,$B$6),"")) | I13: =IF($B$6="","",COUNTIFS(Weekly_Inspections!$F$4:$F$996,$A13,Weekly_Inspections!$D$4:$D$996,$B$6,Weekly_Inspections!$AL$4:$AL$996,"YES")) | J13: =IF(OR($B$6="",$B$7=""),"",IFERROR((G13-AVERAGEIFS(Weekly_Inspections!$AJ$4:$AJ$996,Weekly_Inspections!$F$4:$F$996,$A13,Weekly_Inspections!$D$4:$D$996,$B$7))/AVERAGEIFS(Weekly_Inspections!$AJ$4:$AJ$996,Weekly_Inspections!$F$4:$F$996,$A13,Weekly_Inspections!$D$4:$D$996,$B$7),"")) | K13: =IF(G13="","",IF(AND(I13=0,G13>=0.75),"YES","NO")) | L13: =IF(G13="","",RANK(G13,$G$10:$G$24,0))
A14: Cluster 8C | B14: =IFERROR(INDEX(Cluster_Master!$A$4:$A$18,MATCH($A14,Cluster_Master!$B$4:$B$18,0)),"") | C14: =IFERROR(INDEX(Cluster_Master!$C$4:$C$18,MATCH($A14,Cluster_Master!$B$4:$B$18,0)),"") | D14: =IF($B$5="","",IFERROR(AVERAGEIFS(Weekly_Inspections!$AJ$4:$AJ$996,Weekly_Inspections!$F$4:$F$996,$A14,Weekly_Inspections!$C$4:$C$996,$B$5),"")) | E14: =IF($B$5="","",IFERROR(AVERAGEIFS(Weekly_Inspections!$AK$4:$AK$996,Weekly_Inspections!$F$4:$F$996,$A14,Weekly_Inspections!$C$4:$C$996,$B$5),"")) | F14: =IF($B$5="","",COUNTIFS(Weekly_Inspections!$F$4:$F$996,$A14,Weekly_Inspections!$C$4:$C$996,$B$5,Weekly_Inspections!$AL$4:$AL$996,"YES")) | G14: =IF($B$6="","",IFERROR(AVERAGEIFS(Weekly_Inspections!$AJ$4:$AJ$996,Weekly_Inspections!$F$4:$F$996,$A14,Weekly_Inspections!$D$4:$D$996,$B$6),"")) | H14: =IF($B$6="","",IFERROR(AVERAGEIFS(Weekly_Inspections!$AK$4:$AK$996,Weekly_Inspections!$F$4:$F$996,$A14,Weekly_Inspections!$D$4:$D$996,$B$6),"")) | I14: =IF($B$6="","",COUNTIFS(Weekly_Inspections!$F$4:$F$996,$A14,Weekly_Inspections!$D$4:$D$996,$B$6,Weekly_Inspections!$AL$4:$AL$996,"YES")) | J14: =IF(OR($B$6="",$B$7=""),"",IFERROR((G14-AVERAGEIFS(Weekly_Inspections!$AJ$4:$AJ$996,Weekly_Inspections!$F$4:$F$996,$A14,Weekly_Inspections!$D$4:$D$996,$B$7))/AVERAGEIFS(Weekly_Inspections!$AJ$4:$AJ$996,Weekly_Inspections!$F$4:$F$996,$A14,Weekly_Inspections!$D$4:$D$996,$B$7),"")) | K14: =IF(G14="","",IF(AND(I14=0,G14>=0.75),"YES","NO")) | L14: =IF(G14="","",RANK(G14,$G$10:$G$24,0))
A15: Cluster 8D | B15: =IFERROR(INDEX(Cluster_Master!$A$4:$A$18,MATCH($A15,Cluster_Master!$B$4:$B$18,0)),"") | C15: =IFERROR(INDEX(Cluster_Master!$C$4:$C$18,MATCH($A15,Cluster_Master!$B$4:$B$18,0)),"") | D15: =IF($B$5="","",IFERROR(AVERAGEIFS(Weekly_Inspections!$AJ$4:$AJ$996,Weekly_Inspections!$F$4:$F$996,$A15,Weekly_Inspections!$C$4:$C$996,$B$5),"")) | E15: =IF($B$5="","",IFERROR(AVERAGEIFS(Weekly_Inspections!$AK$4:$AK$996,Weekly_Inspections!$F$4:$F$996,$A15,Weekly_Inspections!$C$4:$C$996,$B$5),"")) | F15: =IF($B$5="","",COUNTIFS(Weekly_Inspections!$F$4:$F$996,$A15,Weekly_Inspections!$C$4:$C$996,$B$5,Weekly_Inspections!$AL$4:$AL$996,"YES")) | G15: =IF($B$6="","",IFERROR(AVERAGEIFS(Weekly_Inspections!$AJ$4:$AJ$996,Weekly_Inspections!$F$4:$F$996,$A15,Weekly_Inspections!$D$4:$D$996,$B$6),"")) | H15: =IF($B$6="","",IFERROR(AVERAGEIFS(Weekly_Inspections!$AK$4:$AK$996,Weekly_Inspections!$F$4:$F$996,$A15,Weekly_Inspections!$D$4:$D$996,$B$6),"")) | I15: =IF($B$6="","",COUNTIFS(Weekly_Inspections!$F$4:$F$996,$A15,Weekly_Inspections!$D$4:$D$996,$B$6,Weekly_Inspections!$AL$4:$AL$996,"YES")) | J15: =IF(OR($B$6="",$B$7=""),"",IFERROR((G15-AVERAGEIFS(Weekly_Inspections!$AJ$4:$AJ$996,Weekly_Inspections!$F$4:$F$996,$A15,Weekly_Inspections!$D$4:$D$996,$B$7))/AVERAGEIFS(Weekly_Inspections!$AJ$4:$AJ$996,Weekly_Inspections!$F$4:$F$996,$A15,Weekly_Inspections!$D$4:$D$996,$B$7),"")) | K15: =IF(G15="","",IF(AND(I15=0,G15>=0.75),"YES","NO")) | L15: =IF(G15="","",RANK(G15,$G$10:$G$24,0))
A16: Cluster 3 | B16: =IFERROR(INDEX(Cluster_Master!$A$4:$A$18,MATCH($A16,Cluster_Master!$B$4:$B$18,0)),"") | C16: =IFERROR(INDEX(Cluster_Master!$C$4:$C$18,MATCH($A16,Cluster_Master!$B$4:$B$18,0)),"") | D16: =IF($B$5="","",IFERROR(AVERAGEIFS(Weekly_Inspections!$AJ$4:$AJ$996,Weekly_Inspections!$F$4:$F$996,$A16,Weekly_Inspections!$C$4:$C$996,$B$5),"")) | E16: =IF($B$5="","",IFERROR(AVERAGEIFS(Weekly_Inspections!$AK$4:$AK$996,Weekly_Inspections!$F$4:$F$996,$A16,Weekly_Inspections!$C$4:$C$996,$B$5),"")) | F16: =IF($B$5="","",COUNTIFS(Weekly_Inspections!$F$4:$F$996,$A16,Weekly_Inspections!$C$4:$C$996,$B$5,Weekly_Inspections!$AL$4:$AL$996,"YES")) | G16: =IF($B$6="","",IFERROR(AVERAGEIFS(Weekly_Inspections!$AJ$4:$AJ$996,Weekly_Inspections!$F$4:$F$996,$A16,Weekly_Inspections!$D$4:$D$996,$B$6),"")) | H16: =IF($B$6="","",IFERROR(AVERAGEIFS(Weekly_Inspections!$AK$4:$AK$996,Weekly_Inspections!$F$4:$F$996,$A16,Weekly_Inspections!$D$4:$D$996,$B$6),"")) | I16: =IF($B$6="","",COUNTIFS(Weekly_Inspections!$F$4:$F$996,$A16,Weekly_Inspections!$D$4:$D$996,$B$6,Weekly_Inspections!$AL$4:$AL$996,"YES")) | J16: =IF(OR($B$6="",$B$7=""),"",IFERROR((G16-AVERAGEIFS(Weekly_Inspections!$AJ$4:$AJ$996,Weekly_Inspections!$F$4:$F$996,$A16,Weekly_Inspections!$D$4:$D$996,$B$7))/AVERAGEIFS(Weekly_Inspections!$AJ$4:$AJ$996,Weekly_Inspections!$F$4:$F$996,$A16,Weekly_Inspections!$D$4:$D$996,$B$7),"")) | K16: =IF(G16="","",IF(AND(I16=0,G16>=0.75),"YES","NO")) | L16: =IF(G16="","",RANK(G16,$G$10:$G$24,0))
A17: Cluster 4 | B17: =IFERROR(INDEX(Cluster_Master!$A$4:$A$18,MATCH($A17,Cluster_Master!$B$4:$B$18,0)),"") | C17: =IFERROR(INDEX(Cluster_Master!$C$4:$C$18,MATCH($A17,Cluster_Master!$B$4:$B$18,0)),"") | D17: =IF($B$5="","",IFERROR(AVERAGEIFS(Weekly_Inspections!$AJ$4:$AJ$996,Weekly_Inspections!$F$4:$F$996,$A17,Weekly_Inspections!$C$4:$C$996,$B$5),"")) | E17: =IF($B$5="","",IFERROR(AVERAGEIFS(Weekly_Inspections!$AK$4:$AK$996,Weekly_Inspections!$F$4:$F$996,$A17,Weekly_Inspections!$C$4:$C$996,$B$5),"")) | F17: =IF($B$5="","",COUNTIFS(Weekly_Inspections!$F$4:$F$996,$A17,Weekly_Inspections!$C$4:$C$996,$B$5,Weekly_Inspections!$AL$4:$AL$996,"YES")) | G17: =IF($B$6="","",IFERROR(AVERAGEIFS(Weekly_Inspections!$AJ$4:$AJ$996,Weekly_Inspections!$F$4:$F$996,$A17,Weekly_Inspections!$D$4:$D$996,$B$6),"")) | H17: =IF($B$6="","",IFERROR(AVERAGEIFS(Weekly_Inspections!$AK$4:$AK$996,Weekly_Inspections!$F$4:$F$996,$A17,Weekly_Inspections!$D$4:$D$996,$B$6),"")) | I17: =IF($B$6="","",COUNTIFS(Weekly_Inspections!$F$4:$F$996,$A17,Weekly_Inspections!$D$4:$D$996,$B$6,Weekly_Inspections!$AL$4:$AL$996,"YES")) | J17: =IF(OR($B$6="",$B$7=""),"",IFERROR((G17-AVERAGEIFS(Weekly_Inspections!$AJ$4:$AJ$996,Weekly_Inspections!$F$4:$F$996,$A17,Weekly_Inspections!$D$4:$D$996,$B$7))/AVERAGEIFS(Weekly_Inspections!$AJ$4:$AJ$996,Weekly_Inspections!$F$4:$F$996,$A17,Weekly_Inspections!$D$4:$D$996,$B$7),"")) | K17: =IF(G17="","",IF(AND(I17=0,G17>=0.75),"YES","NO")) | L17: =IF(G17="","",RANK(G17,$G$10:$G$24,0))
A18: Cluster 5 | B18: =IFERROR(INDEX(Cluster_Master!$A$4:$A$18,MATCH($A18,Cluster_Master!$B$4:$B$18,0)),"") | C18: =IFERROR(INDEX(Cluster_Master!$C$4:$C$18,MATCH($A18,Cluster_Master!$B$4:$B$18,0)),"") | D18: =IF($B$5="","",IFERROR(AVERAGEIFS(Weekly_Inspections!$AJ$4:$AJ$996,Weekly_Inspections!$F$4:$F$996,$A18,Weekly_Inspections!$C$4:$C$996,$B$5),"")) | E18: =IF($B$5="","",IFERROR(AVERAGEIFS(Weekly_Inspections!$AK$4:$AK$996,Weekly_Inspections!$F$4:$F$996,$A18,Weekly_Inspections!$C$4:$C$996,$B$5),"")) | F18: =IF($B$5="","",COUNTIFS(Weekly_Inspections!$F$4:$F$996,$A18,Weekly_Inspections!$C$4:$C$996,$B$5,Weekly_Inspections!$AL$4:$AL$996,"YES")) | G18: =IF($B$6="","",IFERROR(AVERAGEIFS(Weekly_Inspections!$AJ$4:$AJ$996,Weekly_Inspections!$F$4:$F$996,$A18,Weekly_Inspections!$D$4:$D$996,$B$6),"")) | H18: =IF($B$6="","",IFERROR(AVERAGEIFS(Weekly_Inspections!$AK$4:$AK$996,Weekly_Inspections!$F$4:$F$996,$A18,Weekly_Inspections!$D$4:$D$996,$B$6),"")) | I18: =IF($B$6="","",COUNTIFS(Weekly_Inspections!$F$4:$F$996,$A18,Weekly_Inspections!$D$4:$D$996,$B$6,Weekly_Inspections!$AL$4:$AL$996,"YES")) | J18: =IF(OR($B$6="",$B$7=""),"",IFERROR((G18-AVERAGEIFS(Weekly_Inspections!$AJ$4:$AJ$996,Weekly_Inspections!$F$4:$F$996,$A18,Weekly_Inspections!$D$4:$D$996,$B$7))/AVERAGEIFS(Weekly_Inspections!$AJ$4:$AJ$996,Weekly_Inspections!$F$4:$F$996,$A18,Weekly_Inspections!$D$4:$D$996,$B$7),"")) | K18: =IF(G18="","",IF(AND(I18=0,G18>=0.75),"YES","NO")) | L18: =IF(G18="","",RANK(G18,$G$10:$G$24,0))
A19: Cluster 6 | B19: =IFERROR(INDEX(Cluster_Master!$A$4:$A$18,MATCH($A19,Cluster_Master!$B$4:$B$18,0)),"") | C19: =IFERROR(INDEX(Cluster_Master!$C$4:$C$18,MATCH($A19,Cluster_Master!$B$4:$B$18,0)),"") | D19: =IF($B$5="","",IFERROR(AVERAGEIFS(Weekly_Inspections!$AJ$4:$AJ$996,Weekly_Inspections!$F$4:$F$996,$A19,Weekly_Inspections!$C$4:$C$996,$B$5),"")) | E19: =IF($B$5="","",IFERROR(AVERAGEIFS(Weekly_Inspections!$AK$4:$AK$996,Weekly_Inspections!$F$4:$F$996,$A19,Weekly_Inspections!$C$4:$C$996,$B$5),"")) | F19: =IF($B$5="","",COUNTIFS(Weekly_Inspections!$F$4:$F$996,$A19,Weekly_Inspections!$C$4:$C$996,$B$5,Weekly_Inspections!$AL$4:$AL$996,"YES")) | G19: =IF($B$6="","",IFERROR(AVERAGEIFS(Weekly_Inspections!$AJ$4:$AJ$996,Weekly_Inspections!$F$4:$F$996,$A19,Weekly_Inspections!$D$4:$D$996,$B$6),"")) | H19: =IF($B$6="","",IFERROR(AVERAGEIFS(Weekly_Inspections!$AK$4:$AK$996,Weekly_Inspections!$F$4:$F$996,$A19,Weekly_Inspections!$D$4:$D$996,$B$6),"")) | I19: =IF($B$6="","",COUNTIFS(Weekly_Inspections!$F$4:$F$996,$A19,Weekly_Inspections!$D$4:$D$996,$B$6,Weekly_Inspections!$AL$4:$AL$996,"YES")) | J19: =IF(OR($B$6="",$B$7=""),"",IFERROR((G19-AVERAGEIFS(Weekly_Inspections!$AJ$4:$AJ$996,Weekly_Inspections!$F$4:$F$996,$A19,Weekly_Inspections!$D$4:$D$996,$B$7))/AVERAGEIFS(Weekly_Inspections!$AJ$4:$AJ$996,Weekly_Inspections!$F$4:$F$996,$A19,Weekly_Inspections!$D$4:$D$996,$B$7),"")) | K19: =IF(G19="","",IF(AND(I19=0,G19>=0.75),"YES","NO")) | L19: =IF(G19="","",RANK(G19,$G$10:$G$24,0))
A20: Cluster 1A | B20: =IFERROR(INDEX(Cluster_Master!$A$4:$A$18,MATCH($A20,Cluster_Master!$B$4:$B$18,0)),"") | C20: =IFERROR(INDEX(Cluster_Master!$C$4:$C$18,MATCH($A20,Cluster_Master!$B$4:$B$18,0)),"") | D20: =IF($B$5="","",IFERROR(AVERAGEIFS(Weekly_Inspections!$AJ$4:$AJ$996,Weekly_Inspections!$F$4:$F$996,$A20,Weekly_Inspections!$C$4:$C$996,$B$5),"")) | E20: =IF($B$5="","",IFERROR(AVERAGEIFS(Weekly_Inspections!$AK$4:$AK$996,Weekly_Inspections!$F$4:$F$996,$A20,Weekly_Inspections!$C$4:$C$996,$B$5),"")) | F20: =IF($B$5="","",COUNTIFS(Weekly_Inspections!$F$4:$F$996,$A20,Weekly_Inspections!$C$4:$C$996,$B$5,Weekly_Inspections!$AL$4:$AL$996,"YES")) | G20: =IF($B$6="","",IFERROR(AVERAGEIFS(Weekly_Inspections!$AJ$4:$AJ$996,Weekly_Inspections!$F$4:$F$996,$A20,Weekly_Inspections!$D$4:$D$996,$B$6),"")) | H20: =IF($B$6="","",IFERROR(AVERAGEIFS(Weekly_Inspections!$AK$4:$AK$996,Weekly_Inspections!$F$4:$F$996,$A20,Weekly_Inspections!$D$4:$D$996,$B$6),"")) | I20: =IF($B$6="","",COUNTIFS(Weekly_Inspections!$F$4:$F$996,$A20,Weekly_Inspections!$D$4:$D$996,$B$6,Weekly_Inspections!$AL$4:$AL$996,"YES")) | J20: =IF(OR($B$6="",$B$7=""),"",IFERROR((G20-AVERAGEIFS(Weekly_Inspections!$AJ$4:$AJ$996,Weekly_Inspections!$F$4:$F$996,$A20,Weekly_Inspections!$D$4:$D$996,$B$7))/AVERAGEIFS(Weekly_Inspections!$AJ$4:$AJ$996,Weekly_Inspections!$F$4:$F$996,$A20,Weekly_Inspections!$D$4:$D$996,$B$7),"")) | K20: =IF(G20="","",IF(AND(I20=0,G20>=0.75),"YES","NO")) | L20: =IF(G20="","",RANK(G20,$G$10:$G$24,0))
A21: Cluster 1B | B21: =IFERROR(INDEX(Cluster_Master!$A$4:$A$18,MATCH($A21,Cluster_Master!$B$4:$B$18,0)),"") | C21: =IFERROR(INDEX(Cluster_Master!$C$4:$C$18,MATCH($A21,Cluster_Master!$B$4:$B$18,0)),"") | D21: =IF($B$5="","",IFERROR(AVERAGEIFS(Weekly_Inspections!$AJ$4:$AJ$996,Weekly_Inspections!$F$4:$F$996,$A21,Weekly_Inspections!$C$4:$C$996,$B$5),"")) | E21: =IF($B$5="","",IFERROR(AVERAGEIFS(Weekly_Inspections!$AK$4:$AK$996,Weekly_Inspections!$F$4:$F$996,$A21,Weekly_Inspections!$C$4:$C$996,$B$5),"")) | F21: =IF($B$5="","",COUNTIFS(Weekly_Inspections!$F$4:$F$996,$A21,Weekly_Inspections!$C$4:$C$996,$B$5,Weekly_Inspections!$AL$4:$AL$996,"YES")) | G21: =IF($B$6="","",IFERROR(AVERAGEIFS(Weekly_Inspections!$AJ$4:$AJ$996,Weekly_Inspections!$F$4:$F$996,$A21,Weekly_Inspections!$D$4:$D$996,$B$6),"")) | H21: =IF($B$6="","",IFERROR(AVERAGEIFS(Weekly_Inspections!$AK$4:$AK$996,Weekly_Inspections!$F$4:$F$996,$A21,Weekly_Inspections!$D$4:$D$996,$B$6),"")) | I21: =IF($B$6="","",COUNTIFS(Weekly_Inspections!$F$4:$F$996,$A21,Weekly_Inspections!$D$4:$D$996,$B$6,Weekly_Inspections!$AL$4:$AL$996,"YES")) | J21: =IF(OR($B$6="",$B$7=""),"",IFERROR((G21-AVERAGEIFS(Weekly_Inspections!$AJ$4:$AJ$996,Weekly_Inspections!$F$4:$F$996,$A21,Weekly_Inspections!$D$4:$D$996,$B$7))/AVERAGEIFS(Weekly_Inspections!$AJ$4:$AJ$996,Weekly_Inspections!$F$4:$F$996,$A21,Weekly_Inspections!$D$4:$D$996,$B$7),"")) | K21: =IF(G21="","",IF(AND(I21=0,G21>=0.75),"YES","NO")) | L21: =IF(G21="","",RANK(G21,$G$10:$G$24,0))
... A24: Cluster 2C | B24: =IFERROR(INDEX(Cluster_Master!$A$4:$A$18,MATCH($A24,Cluster_Master!$B$4:$B$18,0)),"") | C24: =IFERROR(INDEX(Cluster_Master!$C$4:$C$18,MATCH($A24,Cluster_Master!$B$4:$B$18,0)),"") | D24: =IF($B$5="","",IFERROR(AVERAGEIFS(Weekly_Inspections!$AJ$4:$AJ$996,Weekly_Inspections!$F$4:$F$996,$A24,Weekly_Inspections!$C$4:$C$996,$B$5),"")) | E24: =IF($B$5="","",IFERROR(AVERAGEIFS(Weekly_Inspections!$AK$4:$AK$996,Weekly_Inspections!$F$4:$F$996,$A24,Weekly_Inspections!$C$4:$C$996,$B$5),"")) | F24: =IF($B$5="","",COUNTIFS(Weekly_Inspections!$F$4:$F$996,$A24,Weekly_Inspections!$C$4:$C$996,$B$5,Weekly_Inspections!$AL$4:$AL$996,"YES")) | G24: =IF($B$6="","",IFERROR(AVERAGEIFS(Weekly_Inspections!$AJ$4:$AJ$996,Weekly_Inspections!$F$4:$F$996,$A24,Weekly_Inspections!$D$4:$D$996,$B$6),"")) | H24: =IF($B$6="","",IFERROR(AVERAGEIFS(Weekly_Inspections!$AK$4:$AK$996,Weekly_Inspections!$F$4:$F$996,$A24,Weekly_Inspections!$D$4:$D$996,$B$6),"")) | I24: =IF($B$6="","",COUNTIFS(Weekly_Inspections!$F$4:$F$996,$A24,Weekly_Inspections!$D$4:$D$996,$B$6,Weekly_Inspections!$AL$4:$AL$996,"YES")) | J24: =IF(OR($B$6="",$B$7=""),"",IFERROR((G24-AVERAGEIFS(Weekly_Inspections!$AJ$4:$AJ$996,Weekly_Inspections!$F$4:$F$996,$A24,Weekly_Inspections!$D$4:$D$996,$B$7))/AVERAGEIFS(Weekly_Inspections!$AJ$4:$AJ$996,Weekly_Inspections!$F$4:$F$996,$A24,Weekly_Inspections!$D$4:$D$996,$B$7),"")) | K24: =IF(G24="","",IF(AND(I24=0,G24>=0.75),"YES","NO")) | L24: =IF(G24="","",RANK(G24,$G$10:$G$24,0))
A27: KPI performance snapshot
A28: KPI | B28: Selected Week Avg Score | C28: Selected Month Avg Score | D28: Gap to 5 (Week) | E28: Gap to 5 (Month) | G28: Root Cause | H28: Selected Week Count | I28: Selected Month Count
A29: Work at Height Control | B29: =IF($B$5="","",IFERROR(AVERAGEIFS(Weekly_Inspections!$T$4:$T$499,Weekly_Inspections!$C$4:$C$499,$B$5),"")) | C29: =IF($B$6="","",IFERROR(AVERAGEIFS(Weekly_Inspections!$T$4:$T$499,Weekly_Inspections!$D$4:$D$499,$B$6),"")) | D29: =IF(B29="","",5-B29) | E29: =IF(C29="","",5-C29) | G29: Leadership failure | H29: =IF($B$5="","",COUNTIFS(Weekly_Inspections!$AP$4:$AP$499,$G29,Weekly_Inspections!$C$4:$C$499,$B$5)) | I29: =IF($B$6="","",COUNTIFS(Weekly_Inspections!$AP$4:$AP$499,$G29,Weekly_Inspections!$D$4:$D$499,$B$6))
A30: Edge Protection | B30: =IF($B$5="","",IFERROR(AVERAGEIFS(Weekly_Inspections!$U$4:$U$499,Weekly_Inspections!$C$4:$C$499,$B$5),"")) | C30: =IF($B$6="","",IFERROR(AVERAGEIFS(Weekly_Inspections!$U$4:$U$499,Weekly_Inspections!$D$4:$D$499,$B$6),"")) | D30: =IF(B30="","",5-B30) | E30: =IF(C30="","",5-C30) | G30: Poor supervision | H30: =IF($B$5="","",COUNTIFS(Weekly_Inspections!$AP$4:$AP$499,$G30,Weekly_Inspections!$C$4:$C$499,$B$5)) | I30: =IF($B$6="","",COUNTIFS(Weekly_Inspections!$AP$4:$AP$499,$G30,Weekly_Inspections!$D$4:$D$499,$B$6))
A31: Falling Object Prevention | B31: =IF($B$5="","",IFERROR(AVERAGEIFS(Weekly_Inspections!$V$4:$V$499,Weekly_Inspections!$C$4:$C$499,$B$5),"")) | C31: =IF($B$6="","",IFERROR(AVERAGEIFS(Weekly_Inspections!$V$4:$V$499,Weekly_Inspections!$D$4:$D$499,$B$6),"")) | D31: =IF(B31="","",5-B31) | E31: =IF(C31="","",5-C31) | G31: Poor planning | H31: =IF($B$5="","",COUNTIFS(Weekly_Inspections!$AP$4:$AP$499,$G31,Weekly_Inspections!$C$4:$C$499,$B$5)) | I31: =IF($B$6="","",COUNTIFS(Weekly_Inspections!$AP$4:$AP$499,$G31,Weekly_Inspections!$D$4:$D$499,$B$6))
A32: Excavation Safety | B32: =IF($B$5="","",IFERROR(AVERAGEIFS(Weekly_Inspections!$W$4:$W$499,Weekly_Inspections!$C$4:$C$499,$B$5),"")) | C32: =IF($B$6="","",IFERROR(AVERAGEIFS(Weekly_Inspections!$W$4:$W$499,Weekly_Inspections!$D$4:$D$499,$B$6),"")) | D32: =IF(B32="","",5-B32) | E32: =IF(C32="","",5-C32) | G32: PTW failure | H32: =IF($B$5="","",COUNTIFS(Weekly_Inspections!$AP$4:$AP$499,$G32,Weekly_Inspections!$C$4:$C$499,$B$5)) | I32: =IF($B$6="","",COUNTIFS(Weekly_Inspections!$AP$4:$AP$499,$G32,Weekly_Inspections!$D$4:$D$499,$B$6))
A33: Scaffolding Compliance | B33: =IF($B$5="","",IFERROR(AVERAGEIFS(Weekly_Inspections!$X$4:$X$499,Weekly_Inspections!$C$4:$C$499,$B$5),"")) | C33: =IF($B$6="","",IFERROR(AVERAGEIFS(Weekly_Inspections!$X$4:$X$499,Weekly_Inspections!$D$4:$D$499,$B$6),"")) | D33: =IF(B33="","",5-B33) | E33: =IF(C33="","",5-C33) | G33: Weak MSRA | H33: =IF($B$5="","",COUNTIFS(Weekly_Inspections!$AP$4:$AP$499,$G33,Weekly_Inspections!$C$4:$C$499,$B$5)) | I33: =IF($B$6="","",COUNTIFS(Weekly_Inspections!$AP$4:$AP$499,$G33,Weekly_Inspections!$D$4:$D$499,$B$6))
A34: PTW Implementation | B34: =IF($B$5="","",IFERROR(AVERAGEIFS(Weekly_Inspections!$Y$4:$Y$499,Weekly_Inspections!$C$4:$C$499,$B$5),"")) | C34: =IF($B$6="","",IFERROR(AVERAGEIFS(Weekly_Inspections!$Y$4:$Y$499,Weekly_Inspections!$D$4:$D$499,$B$6),"")) | D34: =IF(B34="","",5-B34) | E34: =IF(C34="","",5-C34) | G34: Poor subcontractor control | H34: =IF($B$5="","",COUNTIFS(Weekly_Inspections!$AP$4:$AP$499,$G34,Weekly_Inspections!$C$4:$C$499,$B$5)) | I34: =IF($B$6="","",COUNTIFS(Weekly_Inspections!$AP$4:$AP$499,$G34,Weekly_Inspections!$D$4:$D$499,$B$6))
A35: PTW Field Verification | B35: =IF($B$5="","",IFERROR(AVERAGEIFS(Weekly_Inspections!$Z$4:$Z$499,Weekly_Inspections!$C$4:$C$499,$B$5),"")) | C35: =IF($B$6="","",IFERROR(AVERAGEIFS(Weekly_Inspections!$Z$4:$Z$499,Weekly_Inspections!$D$4:$D$499,$B$6),"")) | D35: =IF(B35="","",5-B35) | E35: =IF(C35="","",5-C35) | G35: Resource constraint | H35: =IF($B$5="","",COUNTIFS(Weekly_Inspections!$AP$4:$AP$499,$G35,Weekly_Inspections!$C$4:$C$499,$B$5)) | I35: =IF($B$6="","",COUNTIFS(Weekly_Inspections!$AP$4:$AP$499,$G35,Weekly_Inspections!$D$4:$D$499,$B$6))
A36: MSRA Quality | B36: =IF($B$5="","",IFERROR(AVERAGEIFS(Weekly_Inspections!$AA$4:$AA$499,Weekly_Inspections!$C$4:$C$499,$B$5),"")) | C36: =IF($B$6="","",IFERROR(AVERAGEIFS(Weekly_Inspections!$AA$4:$AA$499,Weekly_Inspections!$D$4:$D$499,$B$6),"")) | D36: =IF(B36="","",5-B36) | E36: =IF(C36="","",5-C36) | G36: Inadequate competence | H36: =IF($B$5="","",COUNTIFS(Weekly_Inspections!$AP$4:$AP$499,$G36,Weekly_Inspections!$C$4:$C$499,$B$5)) | I36: =IF($B$6="","",COUNTIFS(Weekly_Inspections!$AP$4:$AP$499,$G36,Weekly_Inspections!$D$4:$D$499,$B$6))
A37: Lifting/Precast Installation | B37: =IF($B$5="","",IFERROR(AVERAGEIFS(Weekly_Inspections!$AB$4:$AB$499,Weekly_Inspections!$C$4:$C$499,$B$5),"")) | C37: =IF($B$6="","",IFERROR(AVERAGEIFS(Weekly_Inspections!$AB$4:$AB$499,Weekly_Inspections!$D$4:$D$499,$B$6),"")) | D37: =IF(B37="","",5-B37) | E37: =IF(C37="","",5-C37) | G37: Poor housekeeping culture | H37: =IF($B$5="","",COUNTIFS(Weekly_Inspections!$AP$4:$AP$499,$G37,Weekly_Inspections!$C$4:$C$499,$B$5)) | I37: =IF($B$6="","",COUNTIFS(Weekly_Inspections!$AP$4:$AP$499,$G37,Weekly_Inspections!$D$4:$D$499,$B$6))
A38: Traffic & Man-Machine Interface | B38: =IF($B$5="","",IFERROR(AVERAGEIFS(Weekly_Inspections!$AC$4:$AC$499,Weekly_Inspections!$C$4:$C$499,$B$5),"")) | C38: =IF($B$6="","",IFERROR(AVERAGEIFS(Weekly_Inspections!$AC$4:$AC$499,Weekly_Inspections!$D$4:$D$499,$B$6),"")) | D38: =IF(B38="","",5-B38) | E38: =IF(C38="","",5-C38) | G38: Interface / simultaneous activity conflict | H38: =IF($B$5="","",COUNTIFS(Weekly_Inspections!$AP$4:$AP$499,$G38,Weekly_Inspections!$C$4:$C$499,$B$5)) | I38: =IF($B$6="","",COUNTIFS(Weekly_Inspections!$AP$4:$AP$499,$G38,Weekly_Inspections!$D$4:$D$499,$B$6))
