Workbook
Name Cluster_List: [1]Lookups!$B$4:$B$18
Name Cluster_List: [1]Lookups!$B$4:$B$18
Name Cluster_List: [1]Lookups!$B$4:$B$18
Name Cluster_List: [1]Lookups!$B$4:$B$18
Name Cluster_List: Lookups!$B$4:$B$18
Name Evaluator_Role_List: [1]Lookups!$C$4:$C$12
Name Evaluator_Role_List: [1]Lookups!$C$4:$C$12
Name Evaluator_Role_List: [1]Lookups!$C$4:$C$12
Name Evaluator_Role_List: [1]Lookups!$C$4:$C$12
Name Evaluator_Role_List: Lookups!$C$4:$C$12
Name High_Risk_Activity_List: [1]Lookups!$D$4:$D$19
Name High_Risk_Activity_List: [1]Lookups!$D$4:$D$19
Name High_Risk_Activity_List: [1]Lookups!$D$4:$D$19
Name High_Risk_Activity_List: [1]Lookups!$D$4:$D$19
Name High_Risk_Activity_List: Lookups!$D$4:$D$19
Name KPI_List: [1]Lookups!$H$4:$H$18
Name KPI_List: [1]Lookups!$H$4:$H$18
Name KPI_List: [1]Lookups!$H$4:$H$18
Name KPI_List: [1]Lookups!$H$4:$H$18
Name KPI_List: Lookups!$H$4:$H$18
Name Package_List: [1]Lookups!$A$4:$A$6
Name Package_List: [1]Lookups!$A$4:$A$6
Name Package_List: [1]Lookups!$A$4:$A$6
Name Package_List: [1]Lookups!$A$4:$A$6
Name Package_List: Lookups!$A$4:$A$6
Name Root_Cause_List: [1]Lookups!$F$4:$F$14
Name Root_Cause_List: [1]Lookups!$F$4:$F$14
Name Root_Cause_List: [1]Lookups!$F$4:$F$14
Name Root_Cause_List: [1]Lookups!$F$4:$F$14
Name Root_Cause_List: Lookups!$F$4:$F$14
Name Score_List: Lookups!$I$2:$I$7
Name Status_List: Lookups!$G$4:$G$7
Name Yes_No_List: [1]Lookups!$E$4:$E$5
Name Yes_No_List: [1]Lookups!$E$4:$E$5
Name Yes_No_List: [1]Lookups!$E$4:$E$5
Name Yes_No_List: [1]Lookups!$E$4:$E$5
Name Yes_No_List: Lookups!$E$4:$E$5

Sheet Cluster_Master
A1: Cluster Master Register
A2: Reference data used for package/cluster selection and automatic population of contractor and leadership accountability details.
A3: Package | B3: Cluster | C3: Contractor | D3: Project Director (PD) | E3: Project Manager (PM) | F3: Construction Manager (CM) | G3: HSE Manager (HSEM) | H3: Section Engineer (SE)
A4: 2 | B4: Cluster 7A | C4: TAJV | D4: Hicham Adel Narch | E4: Ghaidh Alfaour | F4: George Deeb | G4: Timur | H4: Liqat
A5: 2 | B5: Cluster 7B | C5: TAJV | D5: Hicham Adel Narch | E5: Ghaidh Alfaour | F5: George Deeb | G5: Timur | H5: Eyad
A6: 2 | B6: Cluster 8A | C6: TAJV | D6: Hicham Adel Narch | E6: Ghaidh Alfaour | F6: Mohamed Salama | G6: Timur | H6: Ahmad Adel
A7: 2 | B7: Cluster 8B | C7: TAJV | D7: Hicham Adel Narch | E7: Ghaidh Alfaour | F7: Mohamed Salama | G7: Timur | H7: Ahmad Adel
A8: 2 | B8: Cluster 8C | C8: TAJV | D8: Hicham Adel Narch | E8: Ghaidh Alfaour | F8: George Deeb | G8: Timur | H8: Ahmad Adel
A9: 2 | B9: Cluster 8D | C9: TAJV | D9: Hicham Adel Narch | E9: Ghaidh Alfaour | F9: George Deeb | G9: Timur | H9: Ahmad Adel
A10: 3 | B10: Cluster 3 | C10: INNOVO | D10: Kahtan Tikriti | E10: Aiman Abdullah | F10: Salama Al Samdy | G10: Mazen Al Atwani
A11: 3 | B11: Cluster 4 | C11: INNOVO | D11: Kahtan Tikriti | E11: Aiman Abdullah | F11: Baha Basheer | G11: Mazen Al Atwani
A12: 3 | B12: Cluster 5 | C12: INNOVO | D12: Kahtan Tikriti | E12: Michael Ghali | F12: Robair Louies | G12: Mazen Al Atwani
A13: 3 | B13: Cluster 6 | C13: INNOVO | D13: Kahtan Tikriti | E13: Michael Ghali | F13: Remon Karas | G13: Mazen Al Atwani
A14: 4 | B14: Cluster 1A | C14: TAJV | D14: Hicham Adel Narch | E14: Ghaidh Alfaour | F14: Alaa Hegab | G14: Timur Terakopov | H14: Amr Taha
A15: 4 | B15: Cluster 1B | C15: TAJV | D15: Hicham Adel Narch | E15: Ghaidh Alfaour | F15: Hossam Ali Maher | G15: Timur Terakopov | H15: Md Ramadan / Osama Said
A16: 4 | B16: Cluster 2A | C16: TAJV | D16: Hicham Adel Narch | E16: Ghaidh Alfaour | F16: Ahmed Salah Hassan Dewidar | G16: Timur Terakopov | H16: Rami Issa
A17: 4 | B17: Cluster 2B | C17: TAJV | D17: Hicham Adel Narch | E17: Ghaidh Alfaour | F17: Ahmed Salah Hassan Dewidar | G17: Timur Terakopov | H17: Rami Issa
A18: 4 | B18: Cluster 2C | C18: TAJV | D18: Hicham Adel Narch | E18: Ghaidh Alfaour | F18: Ahmed Salah Hassan Dewidar | G18: Timur Terakopov | H18: Salah Nayef

Sheet Lookups
A1: Lookup Lists | I1: Score_List
A2: Lists used for dropdowns in the Weekly_Inspections and CAPA_Tracker sheets. | I2: 0
A3: Package_List | B3: Cluster_List | C3: Evaluator_Role_List | D3: High_Risk_Activity_List | E3: Yes_No_List | F3: Root_Cause_List | G3: Status_List | H3: KPI_List | I3: 1
A4: 2 | B4: Cluster 7A | C4: Project Director | D4: Work at Height | E4: YES | F4: Leadership failure | G4: Open | H4: Work at Height Control | I4: 2
A5: 3 | B5: Cluster 7B | C5: Project Manager | D5: Edge Protection | E5: NO | F5: Poor supervision | G5: In Progress | H5: Edge Protection | I5: 3
A6: 4 | B6: Cluster 8A | C6: Construction Manager | D6: Falling Objects | F6: Poor planning | G6: Closed | H6: Falling Object Prevention | I6: 4
B7: Cluster 8B | C7: HSE Manager | D7: Excavation | F7: PTW failure | G7: On Hold | H7: Excavation Safety | I7: 5
B8: Cluster 8C | C8: Section Engineer | D8: Scaffolding | F8: Weak MSRA | H8: Scaffolding Compliance
B9: Cluster 8D | C9: QA/QC | D9: Permit to Work | F9: Poor subcontractor control | H9: PTW Implementation
B10: Cluster 3 | C10: KEO | D10: MSRA / Risk Assessment | F10: Resource constraint | H10: PTW Field Verification
B11: Cluster 4 | C11: Client | D11: Lifting Operations | F11: Inadequate competence | H11: MSRA Quality
B12: Cluster 5 | C12: Other | D12: Traffic Management | F12: Poor housekeeping culture | H12: Lifting Operations
B13: Cluster 6 | D13: Housekeeping | F13: Interface / simultaneous activity conflict | H13: Traffic & Man-Machine Interface
B14: Cluster 1A | D14: Waste Management | F14: Other | H14: Housekeeping Standard
B15: Cluster 1B | D15: Fire Readiness | H15: Waste Management
B16: Cluster 2A | D16: Electrical Safety | H16: Fire Readiness
B17: Cluster 2B | D17: Portable Power Tools | H17: Supervision & Subcontractor Control
B18: Cluster 2C | D18: Heat Stress | H18: Temporary Electrical & Tool Safety
D19: Other

Sheet KPI_Weights
A1: KPI Weights and Gate Rules
A2: Weights sum to 100%. Critical gate KPIs trigger a red flag if scored 0 or 1 in any inspection.
A3: KPI | B3: Weight | C3: Critical Gate KPI? | D3: Notes
A4: Work at Height Control | B4: 0.12 | C4: YES | D4: Primary fall prevention and work at height control
A5: Edge Protection | B5: 0.12 | C5: NO | D5: Continuity and quality of edge protection
A6: Falling Object Prevention | B6: 0.05 | C6: NO | D6: Exclusion zones, toe boards, debris/tool control
A7: Excavation Safety | B7: 0.08 | C7: YES | D7: Barricading, access, services, support, spoil setback
A8: Scaffolding Compliance | B8: 0.1 | C8: YES | D8: Tagging, inspection, full planking, access, stability
A9: PTW Implementation | B9: 0.08 | C9: YES | D9: Valid PTW, correct scope, signatories, controls
A10: PTW Field Verification | B10: 0.06 | C10: NO | D10: Physical field verification before permit approval
A11: MSRA Quality | B11: 0.03 | C11: NO | D11: Task-specific risk assessment and understanding
A12: Lifting/Precast Installation | B12: 0.1 | C12: YES | D12: Lift plan, appointed person, exclusion, rigging
A13: Traffic & Man-Machine Interface | B13: 0.06 | C13: NO | D13: Pedestrian segregation, routes, signage, reversing
A14: Housekeeping/Waste Management | B14: 0.03 | C14: NO | D14: Cleanliness, stacking, access routes, slip/trip control
A15: Welfare Arrangement | B15: 0.03 | C15: NO | D15: Segregation, storage, transfer/disposal control
... A18: Temporary Electrical & Tool Safety | B18: 0.06 | C18: NO | D18: Temporary power, RCD, condition of tools/cables
A20: Total | B20: =SUM(B4:B18) -> 1

Sheet Weekly_Inspections
A1: Weekly Inspection Entry Sheet - Google Form Ready
A2: Complete only visible fields. Use the 0-5 dropdown for each KPI. Package and Cluster auto-fill contractor leadership and the dashboard updates automatically.
A3: Inspection_ID | B3: Inspection_Date | C3: Week_No | D3: Month | E3: Package | F3: Cluster | G3: Package_Cluster_Check | H3: Contractor | I3: Project Director (PD) | J3: Project Manager (PM) | K3: Construction Manager (CM) | L3: HSE Manager (HSEM) | M3: Section Engineer (SE) | N3: Your_Name | O3: Your_Role | P3: Area_or_Villa | Q3: Workers_Observed | R3: Main_High_Risk_Activity | S3: Stop_Work | T3: Work_at_Height | U3: Edge_Protection | V3: Falling_Object_Prevention | W3: Excavation_Safety | X3: Scaffolding_Compliance | Y3: PTW_Implementation | Z3: PTW_Field_Verification | AA3: MSRA_Quality | AB3: Lifting/Precast Installation | AC3: Traffic_Interface | AD3: Housekeeping/Waste Management | AE3: Welfare Arrangement | AF3: Fire_Readiness | AG3: Supervision_Subcontractor | AH3: Electrical_Tool_Safety | AI3: Total_Score | AJ3: Raw_Score_% | AK3: Weighted_Score_% | AL3: Critical_Red_Flag | AM3: Award_Eligible | AN3: Rating_Band | AO3: Repeat_Issue_Seen | AP3: Likely_Root_Cause | AQ3: Top_3_Gaps_Observed | AR3: Immediate_Action_Taken | AS3: Preventive_Action_Required | AT3: Positive_Observations | AU3: Action_Owner | AV3: Target_Closeout_Date | AW3: Evidence_Link_or_Photo | AX3: KPI_for_PD_Attention | AY3: KPI_for_PM_Attention | AZ3: KPI_for_CM_Attention | BA3: KPI_for_HSEM_Followup | BB3: KPI_for_SE_Supervision | BC3: Leadership_Visible_Effective | BD3: Unsafe_Work_Corrected_Immediately | BE3: Best_Improved_Cluster_this_Week | BF3: Cluster_Needing_Immediate_Intervention
A4: =IF($B4="","",TEXT($B4,"yyyymmdd")&"-"&SUBSTITUTE($F4," ","")&"-"&TEXT(COUNTIF($F$4:F4,$F4),"00")) -> 20260326-Cluster2A-01 | B4: 46107 | C4: =IF($B4="","",WEEKNUM($B4,2)) -> 13 | D4: =IF($B4="","",TEXT($B4,"yyyy-mm")) -> 2026-03 | E4: 4 | F4: Cluster 2A | G4: =IF(OR($E4="",$F4=""),"",IFERROR(IF($E4=INDEX(Cluster_Master!$A$4:$A$18,MATCH($F4,Cluster_Master!$B$4:$B$18,0)),"OK","CHECK"),"CHECK")) -> OK | H4: =IFERROR(INDEX(Cluster_Master!$C$4:$C$18,MATCH($F4,Cluster_Master!$B$4:$B$18,0)),"") -> TAJV | I4: =IFERROR(INDEX(Cluster_Master!$D$4:$D$18,MATCH($F4,Cluster_Master!$B$4:$B$18,0)),"") -> Hicham Adel Narch | J4: =IFERROR(INDEX(Cluster_Master!$E$4:$E$18,MATCH($F4,Cluster_Master!$B$4:$B$18,0)),"") -> Ghaidh Alfaour | K4: =IFERROR(INDEX(Cluster_Master!$F$4:$F$18,MATCH($F4,Cluster_Master!$B$4:$B$18,0)),"") -> Ahmed Salah Hassan Dewidar | L4: =IFERROR(INDEX(Cluster_Master!$G$4:$G$18,MATCH($F4,Cluster_Master!$B$4:$B$18,0)),"") -> Timur Terakopov | M4: =IFERROR(INDEX(Cluster_Master!$H$4:$H$18,MATCH($F4,Cluster_Master!$B$4:$B$18,0)),"") -> Rami Issa | N4: Godwin | O4: KEO | P4: Villa 8 to 16 | R4: Work at Height | S4: YES | T4: 2 | U4: 2 | V4: 3 | W4: 3 | X4: 2 | Y4: 3 | Z4: 1 | AA4: 3 | AC4: 3 | AD4: 1 | AE4: 1 | AF4: 2 | AG4: 1 | AH4: 2 | AI4: =IF(COUNTA(T4:AH4)=0,"",SUM(T4:AH4)) -> 29 | AJ4: =IF(COUNTA(T4:AH4)=0,"",AI4/75) -> 0.38666667 | AK4: =IF(COUNTA(T4:AH4)=0,"",(SUM(T4*KPI_Weights!$B$4,U4*KPI_Weights!$B$5,V4*KPI_Weights!$B$6,W4*KPI_Weights!$B$7,X4*KPI_Weights!$B$8,Y4*KPI_Weights!$B$9,Z4*KPI_Weights!$B$10,AA4*KPI_Weights!$B$11,AB4*KPI_Weights!$B$12,AC4*KPI_Weights!$B$13,AD4*KPI_Weights!$B$14,AE4*KPI_Weights!$B$15,AF4*KPI_Weights!$B$16,AG4*KPI_Weights!$B$17,AH4*KPI_Weights!$B$18))/5) -> 0.39 | AL4: =IF(COUNTA(T4:AH4)=0,"",IF(OR(T4<=1,W4<=1,X4<=1,Y4<=1,AB4<=1),"YES","NO")) -> YES | AM4: =IF(AJ4="","",IF(AND(AL4="NO",AJ4>=0.75),"YES","NO")) -> NO | AN4: =IF(AJ4="","",IF(AJ4<0.4,"Critical",IF(AJ4<0.6,"Poor",IF(AJ4<0.75,"Needs Improvement",IF(AJ4<0.9,"Good","Excellent"))))) -> Critical | AO4: YES | AP4: Leadership failure | AQ4: 1. Leadership failure 2. Poor supervision 3. Poor sub-contractor control 4. PTW failure | AR4: Unsafe work practices were suspended immediately. The CM of the cluster was called but he refused to visit the location. | AS4: 1. PTW must be controlled by the main contractor. 2. Close supervision of sub-contractors by main contractor shall be ensured. 3. Non-performing subcontractors shall not be paid and shall be removed from project. 4. Non-performing construction team shall be replaced without delays | AU4: 1-3rd recommendation by the cluster CM 4th recommendation by the PD. | AV4: 46114
A5: =IF($B5="","",TEXT($B5,"yyyymmdd")&"-"&SUBSTITUTE($F5," ","")&"-"&TEXT(COUNTIF($F$4:F5,$F5),"00")) -> 20260326-Cluster8A-01 | B5: 46107 | C5: =IF($B5="","",WEEKNUM($B5,2)) -> 13 | D5: =IF($B5="","",TEXT($B5,"yyyy-mm")) -> 2026-03 | E5: 2 | F5: Cluster 8A | G5: =IF(OR($E5="",$F5=""),"",IFERROR(IF($E5=INDEX(Cluster_Master!$A$4:$A$18,MATCH($F5,Cluster_Master!$B$4:$B$18,0)),"OK","CHECK"),"CHECK")) -> OK | H5: =IFERROR(INDEX(Cluster_Master!$C$4:$C$18,MATCH($F5,Cluster_Master!$B$4:$B$18,0)),"") -> TAJV | I5: =IFERROR(INDEX(Cluster_Master!$D$4:$D$18,MATCH($F5,Cluster_Master!$B$4:$B$18,0)),"") -> Hicham Adel Narch | J5: =IFERROR(INDEX(Cluster_Master!$E$4:$E$18,MATCH($F5,Cluster_Master!$B$4:$B$18,0)),"") -> Ghaidh Alfaour | K5: =IFERROR(INDEX(Cluster_Master!$F$4:$F$18,MATCH($F5,Cluster_Master!$B$4:$B$18,0)),"") -> Mohamed Salama | L5: =IFERROR(INDEX(Cluster_Master!$G$4:$G$18,MATCH($F5,Cluster_Master!$B$4:$B$18,0)),"") -> Timur | M5: =IFERROR(INDEX(Cluster_Master!$H$4:$H$18,MATCH($F5,Cluster_Master!$B$4:$B$18,0)),"") -> Ahmad Adel | N5: Godwin | O5: KEO | P5: General | R5: Scaffolding | S5: NO | T5: 4 | U5: 4 | V5: 4 | W5: 4 | X5: 4 | Y5: 4 | Z5: 4 | AA5: 4 | AB5: 4 | AC5: 4 | AD5: 4 | AE5: 3 | AF5: 4 | AG5: 4 | AH5: 4 | AI5: =IF(COUNTA(T5:AH5)=0,"",SUM(T5:AH5)) -> 59 | AJ5: =IF(COUNTA(T5:AH5)=0,"",AI5/75) -> 0.78666667 | AK5: =IF(COUNTA(T5:AH5)=0,"",(SUM(T5*KPI_Weights!$B$4,U5*KPI_Weights!$B$5,V5*KPI_Weights!$B$6,W5*KPI_Weights!$B$7,X5*KPI_Weights!$B$8,Y5*KPI_Weights!$B$9,Z5*KPI_Weights!$B$10,AA5*KPI_Weights!$B$11,AB5*KPI_Weights!$B$12,AC5*KPI_Weights!$B$13,AD5*KPI_Weights!$B$14,AE5*KPI_Weights!$B$15,AF5*KPI_Weights!$B$16,AG5*KPI_Weights!$B$17,AH5*KPI_Weights!$B$18))/5) -> 0.794 | AL5: =IF(COUNTA(T5:AH5)=0,"",IF(OR(T5<=1,W5<=1,X5<=1,Y5<=1,AB5<=1),"YES","NO")) -> NO | AM5: =IF(AJ5="","",IF(AND(AL5="NO",AJ5>=0.75),"YES","NO")) -> YES | AN5: =IF(AJ5="","",IF(AJ5<0.4,"Critical",IF(AJ5<0.6,"Poor",IF(AJ5<0.75,"Needs Improvement",IF(AJ5<0.9,"Good","Excellent"))))) -> Good | AO5: NO | AP5: Other | AQ5: No significant gap observed | AR5: The team was commended for their visible leadership in driving transformation at Cluster 8A. | AS5: The Construction Manager and his team were advised to ensure that sub-contractors do not mess up with their site. The following advise was given: 1. No payment for work if site condition is below the acceptable standard. 2. Close supervision of sub-contractors by the construction team of the main contractor. 3. Housekeeping shall be maintined for all shift. 4. Provide a temporary storage area for waste for each villa. 5. PTW shall remain under the control of the main contractor. | AU5: Construction Manager of Cluster 8A HSE Manager of TAJV | AV5: Always
A6: =IF($B6="","",TEXT($B6,"yyyymmdd")&"-"&SUBSTITUTE($F6," ","")&"-"&TEXT(COUNTIF($F$4:F6,$F6),"00")) -> 20260330-Cluster4-01 | B6: 46111 | C6: =IF($B6="","",WEEKNUM($B6,2)) -> 14 | D6: =IF($B6="","",TEXT($B6,"yyyy-mm")) -> 2026-03 | E6: 3 | F6: Cluster 4 | G6: =IF(OR($E6="",$F6=""),"",IFERROR(IF($E6=INDEX(Cluster_Master!$A$4:$A$18,MATCH($F6,Cluster_Master!$B$4:$B$18,0)),"OK","CHECK"),"CHECK")) -> OK | H6: =IFERROR(INDEX(Cluster_Master!$C$4:$C$18,MATCH($F6,Cluster_Master!$B$4:$B$18,0)),"") -> INNOVO | I6: =IFERROR(INDEX(Cluster_Master!$D$4:$D$18,MATCH($F6,Cluster_Master!$B$4:$B$18,0)),"") -> Kahtan Tikriti | J6: =IFERROR(INDEX(Cluster_Master!$E$4:$E$18,MATCH($F6,Cluster_Master!$B$4:$B$18,0)),"") -> Aiman Abdullah | K6: =IFERROR(INDEX(Cluster_Master!$F$4:$F$18,MATCH($F6,Cluster_Master!$B$4:$B$18,0)),"") -> Baha Basheer | L6: =IFERROR(INDEX(Cluster_Master!$G$4:$G$18,MATCH($F6,Cluster_Master!$B$4:$B$18,0)),"") -> Mazen Al Atwani | M6: =IFERROR(INDEX(Cluster_Master!$H$4:$H$18,MATCH($F6,Cluster_Master!$B$4:$B$18,0)),"") -> 0 | N6: Shinoj | O6: KEO | P6: Villa 8 to 16 | Q6: Block work | R6: Edge Protection | S6: NO | T6: 3 | U6: 2 | V6: 3 | W6: 3 | X6: 2 | Y6: 4 | Z6: 3 | AA6: 5 | AB6: 1 | AC6: 2 | AD6: 4 | AE6: 2 | AF6: 3 | AG6: 1 | AH6: 3 | AI6: =IF(COUNTA(T6:AH6)=0,"",SUM(T6:AH6)) -> 41 | AJ6: =IF(COUNTA(T6:AH6)=0,"",AI6/75) -> 0.54666667 | AK6: =IF(COUNTA(T6:AH6)=0,"",(SUM(T6*KPI_Weights!$B$4,U6*KPI_Weights!$B$5,V6*KPI_Weights!$B$6,W6*KPI_Weights!$B$7,X6*KPI_Weights!$B$8,Y6*KPI_Weights!$B$9,Z6*KPI_Weights!$B$10,AA6*KPI_Weights!$B$11,AB6*KPI_Weights!$B$12,AC6*KPI_Weights!$B$13,AD6*KPI_Weights!$B$14,AE6*KPI_Weights!$B$15,AF6*KPI_Weights!$B$16,AG6*KPI_Weights!$B$17,AH6*KPI_Weights!$B$18))/5) -> 0.52 | AL6: =IF(COUNTA(T6:AH6)=0,"",IF(OR(T6<=1,W6<=1,X6<=1,Y6<=1,AB6<=1),"YES","NO")) -> YES | AM6: =IF(AJ6="","",IF(AND(AL6="NO",AJ6>=0.75),"YES","NO")) -> NO | AN6: =IF(AJ6="","",IF(AJ6<0.4,"Critical",IF(AJ6<0.6,"Poor",IF(AJ6<0.75,"Needs Improvement",IF(AJ6<0.9,"Good","Excellent"))))) -> Poor | AO6: NO | AP6: Poor supervision | AR6: sretybhy | AS6: hfidjdgkjdfkdfgb | AV6: 46112
A7: =IF($B7="","",TEXT($B7,"yyyymmdd")&"-"&SUBSTITUTE($F7," ","")&"-"&TEXT(COUNTIF($F$4:F7,$F7),"00")) -> 20260331-Cluster1A-01 | B7: 46112 | C7: =IF($B7="","",WEEKNUM($B7,2)) -> 14 | D7: =IF($B7="","",TEXT($B7,"yyyy-mm")) -> 2026-03 | E7: 3 | F7: Cluster 1A | G7: =IF(OR($E7="",$F7=""),"",IFERROR(IF($E7=INDEX(Cluster_Master!$A$4:$A$18,MATCH($F7,Cluster_Master!$B$4:$B$18,0)),"OK","CHECK"),"CHECK")) -> CHECK | H7: =IFERROR(INDEX(Cluster_Master!$C$4:$C$18,MATCH($F7,Cluster_Master!$B$4:$B$18,0)),"") -> TAJV | I7: =IFERROR(INDEX(Cluster_Master!$D$4:$D$18,MATCH($F7,Cluster_Master!$B$4:$B$18,0)),"") -> Hicham Adel Narch | J7: =IFERROR(INDEX(Cluster_Master!$E$4:$E$18,MATCH($F7,Cluster_Master!$B$4:$B$18,0)),"") -> Ghaidh Alfaour | K7: =IFERROR(INDEX(Cluster_Master!$F$4:$F$18,MATCH($F7,Cluster_Master!$B$4:$B$18,0)),"") -> Alaa Hegab | L7: =IFERROR(INDEX(Cluster_Master!$G$4:$G$18,MATCH($F7,Cluster_Master!$B$4:$B$18,0)),"") -> Timur Terakopov | M7: =IFERROR(INDEX(Cluster_Master!$H$4:$H$18,MATCH($F7,Cluster_Master!$B$4:$B$18,0)),"") -> Amr Taha | N7: Javed | O7: KEO | P7: Villa 8 to 16 | Q7: Block work | R7: Edge Protection | S7: NO | T7: 3 | U7: 2 | V7: 3 | W7: 3 | X7: 2 | Y7: 4 | Z7: 3 | AA7: 5 | AB7: 1 | AC7: 2 | AD7: 4 | AE7: 2 | AF7: 3 | AG7: 1 | AH7: 3 | AI7: =IF(COUNTA(T7:AH7)=0,"",SUM(T7:AH7)) -> 41 | AJ7: =IF(COUNTA(T7:AH7)=0,"",AI7/75) -> 0.54666667 | AK7: =IF(COUNTA(T7:AH7)=0,"",(SUM(T7*KPI_Weights!$B$4,U7*KPI_Weights!$B$5,V7*KPI_Weights!$B$6,W7*KPI_Weights!$B$7,X7*KPI_Weights!$B$8,Y7*KPI_Weights!$B$9,Z7*KPI_Weights!$B$10,AA7*KPI_Weights!$B$11,AB7*KPI_Weights!$B$12,AC7*KPI_Weights!$B$13,AD7*KPI_Weights!$B$14,AE7*KPI_Weights!$B$15,AF7*KPI_Weights!$B$16,AG7*KPI_Weights!$B$17,AH7*KPI_Weights!$B$18))/5) -> 0.52 | AL7: =IF(COUNTA(T7:AH7)=0,"",IF(OR(T7<=1,W7<=1,X7<=1,Y7<=1,AB7<=1),"YES","NO")) -> YES | AM7: =IF(AJ7="","",IF(AND(AL7="NO",AJ7>=0.75),"YES","NO")) -> NO | AN7: =IF(AJ7="","",IF(AJ7<0.4,"Critical",IF(AJ7<0.6,"Poor",IF(AJ7<0.75,"Needs Improvement",IF(AJ7<0.9,"Good","Excellent"))))) -> Poor | AO7: NO | AP7: Poor supervision | AR7: sretybhy | AS7: hfidjdgkjdfkdfgb | AV7: 46112
A8: =IF($B8="","",TEXT($B8,"yyyymmdd")&"-"&SUBSTITUTE($F8," ","")&"-"&TEXT(COUNTIF($F$4:F8,$F8),"00")) -> 20260331-Cluster1B-01 | B8: 46112 | C8: =IF($B8="","",WEEKNUM($B8,2)) -> 14 | D8: =IF($B8="","",TEXT($B8,"yyyy-mm")) -> 2026-03 | E8: 3 | F8: Cluster 1B | G8: =IF(OR($E8="",$F8=""),"",IFERROR(IF($E8=INDEX(Cluster_Master!$A$4:$A$18,MATCH($F8,Cluster_Master!$B$4:$B$18,0)),"OK","CHECK"),"CHECK")) -> CHECK | H8: =IFERROR(INDEX(Cluster_Master!$C$4:$C$18,MATCH($F8,Cluster_Master!$B$4:$B$18,0)),"") -> TAJV | I8: =IFERROR(INDEX(Cluster_Master!$D$4:$D$18,MATCH($F8,Cluster_Master!$B$4:$B$18,0)),"") -> Hicham Adel Narch | J8: =IFERROR(INDEX(Cluster_Master!$E$4:$E$18,MATCH($F8,Cluster_Master!$B$4:$B$18,0)),"") -> Ghaidh Alfaour | K8: =IFERROR(INDEX(Cluster_Master!$F$4:$F$18,MATCH($F8,Cluster_Master!$B$4:$B$18,0)),"") -> Hossam Ali Maher | L8: =IFERROR(INDEX(Cluster_Master!$G$4:$G$18,MATCH($F8,Cluster_Master!$B$4:$B$18,0)),"") -> Timur Terakopov | M8: =IFERROR(INDEX(Cluster_Master!$H$4:$H$18,MATCH($F8,Cluster_Master!$B$4:$B$18,0)),"") -> Md Ramadan / Osama Said | N8: Javed | O8: KEO | P8: Villa 8 to 16 | Q8: Block work | R8: Edge Protection | S8: NO | T8: 3 | U8: 2 | V8: 3 | W8: 3 | X8: 2 | Y8: 4 | Z8: 3 | AA8: 5 | AB8: 1 | AC8: 2 | AD8: 4 | AE8: 2 | AF8: 3 | AG8: 1 | AH8: 3 | AI8: =IF(COUNTA(T8:AH8)=0,"",SUM(T8:AH8)) -> 41 | AJ8: =IF(COUNTA(T8:AH8)=0,"",AI8/75) -> 0.54666667 | AK8: =IF(COUNTA(T8:AH8)=0,"",(SUM(T8*KPI_Weights!$B$4,U8*KPI_Weights!$B$5,V8*KPI_Weights!$B$6,W8*KPI_Weights!$B$7,X8*KPI_Weights!$B$8,Y8*KPI_Weights!$B$9,Z8*KPI_Weights!$B$10,AA8*KPI_Weights!$B$11,AB8*KPI_Weights!$B$12,AC8*KPI_Weights!$B$13,AD8*KPI_Weights!$B$14,AE8*KPI_Weights!$B$15,AF8*KPI_Weights!$B$16,AG8*KPI_Weights!$B$17,AH8*KPI_Weights!$B$18))/5) -> 0.52 | AL8: =IF(COUNTA(T8:AH8)=0,"",IF(OR(T8<=1,W8<=1,X8<=1,Y8<=1,AB8<=1),"YES","NO")) -> YES | AM8: =IF(AJ8="","",IF(AND(AL8="NO",AJ8>=0.75),"YES","NO")) -> NO | AN8: =IF(AJ8="","",IF(AJ8<0.4,"Critical",IF(AJ8<0.6,"Poor",IF(AJ8<0.75,"Needs Improvement",IF(AJ8<0.9,"Good","Excellent"))))) -> Poor | AO8: NO | AP8: Poor supervision | AR8: sretybhy | AS8: hfidjdgkjdfkdfgb | AV8: 46112
A9: =IF($B9="","",TEXT($B9,"yyyymmdd")&"-"&SUBSTITUTE($F9," ","")&"-"&TEXT(COUNTIF($F$4:F9,$F9),"00")) -> 20260331-Cluster6-01 | B9: 46112 | C9: =IF($B9="","",WEEKNUM($B9,2)) -> 14 | D9: =IF($B9="","",TEXT($B9,"yyyy-mm")) -> 2026-03 | E9: 3 | F9: Cluster 6 | G9: =IF(OR($E9="",$F9=""),"",IFERROR(IF($E9=INDEX(Cluster_Master!$A$4:$A$18,MATCH($F9,Cluster_Master!$B$4:$B$18,0)),"OK","CHECK"),"CHECK")) -> OK | H9: =IFERROR(INDEX(Cluster_Master!$C$4:$C$18,MATCH($F9,Cluster_Master!$B$4:$B$18,0)),"") -> INNOVO | I9: =IFERROR(INDEX(Cluster_Master!$D$4:$D$18,MATCH($F9,Cluster_Master!$B$4:$B$18,0)),"") -> Kahtan Tikriti | J9: =IFERROR(INDEX(Cluster_Master!$E$4:$E$18,MATCH($F9,Cluster_Master!$B$4:$B$18,0)),"") -> Michael Ghali | K9: =IFERROR(INDEX(Cluster_Master!$F$4:$F$18,MATCH($F9,Cluster_Master!$B$4:$B$18,0)),"") -> Remon Karas | L9: =IFERROR(INDEX(Cluster_Master!$G$4:$G$18,MATCH($F9,Cluster_Master!$B$4:$B$18,0)),"") -> Mazen Al Atwani | M9: =IFERROR(INDEX(Cluster_Master!$H$4:$H$18,MATCH($F9,Cluster_Master!$B$4:$B$18,0)),"") -> 0 | N9: Javed | O9: KEO | P9: Villa 8 to 16 | Q9: Block work | R9: Edge Protection | S9: NO | T9: 3 | U9: 2 | V9: 3 | W9: 3 | X9: 2 | Y9: 4 | Z9: 3 | AA9: 5 | AB9: 1 | AC9: 2 | AD9: 4 | AE9: 2 | AF9: 3 | AG9: 1 | AH9: 3 | AI9: =IF(COUNTA(T9:AH9)=0,"",SUM(T9:AH9)) -> 41 | AJ9: =IF(COUNTA(T9:AH9)=0,"",AI9/75) -> 0.54666667 | AK9: =IF(COUNTA(T9:AH9)=0,"",(SUM(T9*KPI_Weights!$B$4,U9*KPI_Weights!$B$5,V9*KPI_Weights!$B$6,W9*KPI_Weights!$B$7,X9*KPI_Weights!$B$8,Y9*KPI_Weights!$B$9,Z9*KPI_Weights!$B$10,AA9*KPI_Weights!$B$11,AB9*KPI_Weights!$B$12,AC9*KPI_Weights!$B$13,AD9*KPI_Weights!$B$14,AE9*KPI_Weights!$B$15,AF9*KPI_Weights!$B$16,AG9*KPI_Weights!$B$17,AH9*KPI_Weights!$B$18))/5) -> 0.52 | AL9: =IF(COUNTA(T9:AH9)=0,"",IF(OR(T9<=1,W9<=1,X9<=1,Y9<=1,AB9<=1),"YES","NO")) -> YES | AM9: =IF(AJ9="","",IF(AND(AL9="NO",AJ9>=0.75),"YES","NO")) -> NO | AN9: =IF(AJ9="","",IF(AJ9<0.4,"Critical",IF(AJ9<0.6,"Poor",IF(AJ9<0.75,"Needs Improvement",IF(AJ9<0.9,"Good","Excellent"))))) -> Poor | AO9: NO | AP9: Poor supervision | AR9: sretybhy | AS9: hfidjdgkjdfkdfgb | AV9: 46112
A10: =IF($B10="","",TEXT($B10,"yyyymmdd")&"-"&SUBSTITUTE($F10," ","")&"-"&TEXT(COUNTIF($F$4:F10,$F10),"00")) | C10: =IF($B10="","",WEEKNUM($B10,2)) | D10: =IF($B10="","",TEXT($B10,"yyyy-mm")) | G10: =IF(OR($E10="",$F10=""),"",IFERROR(IF($E10=INDEX(Cluster_Master!$A$4:$A$18,MATCH($F10,Cluster_Master!$B$4:$B$18,0)),"OK","CHECK"),"CHECK")) | H10: =IFERROR(INDEX(Cluster_Master!$C$4:$C$18,MATCH($F10,Cluster_Master!$B$4:$B$18,0)),"") | I10: =IFERROR(INDEX(Cluster_Master!$D$4:$D$18,MATCH($F10,Cluster_Master!$B$4:$B$18,0)),"") | J10: =IFERROR(INDEX(Cluster_Master!$E$4:$E$18,MATCH($F10,Cluster_Master!$B$4:$B$18,0)),"") | K10: =IFERROR(INDEX(Cluster_Master!$F$4:$F$18,MATCH($F10,Cluster_Master!$B$4:$B$18,0)),"") | L10: =IFERROR(INDEX(Cluster_Master!$G$4:$G$18,MATCH($F10,Cluster_Master!$B$4:$B$18,0)),"") | M10: =IFERROR(INDEX(Cluster_Master!$H$4:$H$18,MATCH($F10,Cluster_Master!$B$4:$B$18,0)),"") | AI10: =IF(COUNTA(T10:AH10)=0,"",SUM(T10:AH10)) | AJ10: =IF(COUNTA(T10:AH10)=0,"",AI10/75) | AK10: =IF(COUNTA(T10:AH10)=0,"",(SUM(T10*KPI_Weights!$B$4,U10*KPI_Weights!$B$5,V10*KPI_Weights!$B$6,W10*KPI_Weights!$B$7,X10*KPI_Weights!$B$8,Y10*KPI_Weights!$B$9,Z10*KPI_Weights!$B$10,AA10*KPI_Weights!$B$11,AB10*KPI_Weights!$B$12,AC10*KPI_Weights!$B$13,AD10*KPI_Weights!$B$14,AE10*KPI_Weights!$B$15,AF10*KPI_Weights!$B$16,AG10*KPI_Weights!$B$17,AH10*KPI_Weights!$B$18))/5) | AL10: =IF(COUNTA(T10:AH10)=0,"",IF(OR(T10<=1,W10<=1,X10<=1,Y10<=1,AB10<=1),"YES","NO")) | AM10: =IF(AJ10="","",IF(AND(AL10="NO",AJ10>=0.75),"YES","NO")) | AN10: =IF(AJ10="","",IF(AJ10<0.4,"Critical",IF(AJ10<0.6,"Poor",IF(AJ10<0.75,"Needs Improvement",IF(AJ10<0.9,"Good","Excellent")))))
A11: =IF($B11="","",TEXT($B11,"yyyymmdd")&"-"&SUBSTITUTE($F11," ","")&"-"&TEXT(COUNTIF($F$4:F11,$F11),"00")) | C11: =IF($B11="","",WEEKNUM($B11,2)) | D11: =IF($B11="","",TEXT($B11,"yyyy-mm")) | G11: =IF(OR($E11="",$F11=""),"",IFERROR(IF($E11=INDEX(Cluster_Master!$A$4:$A$18,MATCH($F11,Cluster_Master!$B$4:$B$18,0)),"OK","CHECK"),"CHECK")) | H11: =IFERROR(INDEX(Cluster_Master!$C$4:$C$18,MATCH($F11,Cluster_Master!$B$4:$B$18,0)),"") | I11: =IFERROR(INDEX(Cluster_Master!$D$4:$D$18,MATCH($F11,Cluster_Master!$B$4:$B$18,0)),"") | J11: =IFERROR(INDEX(Cluster_Master!$E$4:$E$18,MATCH($F11,Cluster_Master!$B$4:$B$18,0)),"") | K11: =IFERROR(INDEX(Cluster_Master!$F$4:$F$18,MATCH($F11,Cluster_Master!$B$4:$B$18,0)),"") | L11: =IFERROR(INDEX(Cluster_Master!$G$4:$G$18,MATCH($F11,Cluster_Master!$B$4:$B$18,0)),"") | M11: =IFERROR(INDEX(Cluster_Master!$H$4:$H$18,MATCH($F11,Cluster_Master!$B$4:$B$18,0)),"") | AI11: =IF(COUNTA(T11:AH11)=0,"",SUM(T11:AH11)) | AJ11: =IF(COUNTA(T11:AH11)=0,"",AI11/75) | AK11: =IF(COUNTA(T11:AH11)=0,"",(SUM(T11*KPI_Weights!$B$4,U11*KPI_Weights!$B$5,V11*KPI_Weights!$B$6,W11*KPI_Weights!$B$7,X11*KPI_Weights!$B$8,Y11*KPI_Weights!$B$9,Z11*KPI_Weights!$B$10,AA11*KPI_Weights!$B$11,AB11*KPI_Weights!$B$12,AC11*KPI_Weights!$B$13,AD11*KPI_Weights!$B$14,AE11*KPI_Weights!$B$15,AF11*KPI_Weights!$B$16,AG11*KPI_Weights!$B$17,AH11*KPI_Weights!$B$18))/5) | AL11: =IF(COUNTA(T11:AH11)=0,"",IF(OR(T11<=1,W11<=1,X11<=1,Y11<=1,AB11<=1),"YES","NO")) | AM11: =IF(AJ11="","",IF(AND(AL11="NO",AJ11>=0.75),"YES","NO")) | AN11: =IF(AJ11="","",IF(AJ11<0.4,"Critical",IF(AJ11<0.6,"Poor",IF(AJ11<0.75,"Needs Improvement",IF(AJ11<0.9,"Good","Excellent")))))
A12: =IF($B12="","",TEXT($B12,"yyyymmdd")&"-"&SUBSTITUTE($F12," ","")&"-"&TEXT(COUNTIF($F$4:F12,$F12),"00")) | C12: =IF($B12="","",WEEKNUM($B12,2)) | D12: =IF($B12="","",TEXT($B12,"yyyy-mm")) | G12: =IF(OR($E12="",$F12=""),"",IFERROR(IF($E12=INDEX(Cluster_Master!$A$4:$A$18,MATCH($F12,Cluster_Master!$B$4:$B$18,0)),"OK","CHECK"),"CHECK")) | H12: =IFERROR(INDEX(Cluster_Master!$C$4:$C$18,MATCH($F12,Cluster_Master!$B$4:$B$18,0)),"") | I12: =IFERROR(INDEX(Cluster_Master!$D$4:$D$18,MATCH($F12,Cluster_Master!$B$4:$B$18,0)),"") | J12: =IFERROR(INDEX(Cluster_Master!$E$4:$E$18,MATCH($F12,Cluster_Master!$B$4:$B$18,0)),"") | K12: =IFERROR(INDEX(Cluster_Master!$F$4:$F$18,MATCH($F12,Cluster_Master!$B$4:$B$18,0)),"") | L12: =IFERROR(INDEX(Cluster_Master!$G$4:$G$18,MATCH($F12,Cluster_Master!$B$4:$B$18,0)),"") | M12: =IFERROR(INDEX(Cluster_Master!$H$4:$H$18,MATCH($F12,Cluster_Master!$B$4:$B$18,0)),"") | AI12: =IF(COUNTA(T12:AH12)=0,"",SUM(T12:AH12)) | AJ12: =IF(COUNTA(T12:AH12)=0,"",AI12/75) | AK12: =IF(COUNTA(T12:AH12)=0,"",(SUM(T12*KPI_Weights!$B$4,U12*KPI_Weights!$B$5,V12*KPI_Weights!$B$6,W12*KPI_Weights!$B$7,X12*KPI_Weights!$B$8,Y12*KPI_Weights!$B$9,Z12*KPI_Weights!$B$10,AA12*KPI_Weights!$B$11,AB12*KPI_Weights!$B$12,AC12*KPI_Weights!$B$13,AD12*KPI_Weights!$B$14,AE12*KPI_Weights!$B$15,AF12*KPI_Weights!$B$16,AG12*KPI_Weights!$B$17,AH12*KPI_Weights!$B$18))/5) | AL12: =IF(COUNTA(T12:AH12)=0,"",IF(OR(T12<=1,W12<=1,X12<=1,Y12<=1,AB12<=1),"YES","NO")) | AM12: =IF(AJ12="","",IF(AND(AL12="NO",AJ12>=0.75),"YES","NO")) | AN12: =IF(AJ12="","",IF(AJ12<0.4,"Critical",IF(AJ12<0.6,"Poor",IF(AJ12<0.75,"Needs Improvement",IF(AJ12<0.9,"Good","Excellent")))))
A13: =IF($B13="","",TEXT($B13,"yyyymmdd")&"-"&SUBSTITUTE($F13," ","")&"-"&TEXT(COUNTIF($F$4:F13,$F13),"00")) | C13: =IF($B13="","",WEEKNUM($B13,2)) | D13: =IF($B13="","",TEXT($B13,"yyyy-mm")) | G13: =IF(OR($E13="",$F13=""),"",IFERROR(IF($E13=INDEX(Cluster_Master!$A$4:$A$18,MATCH($F13,Cluster_Master!$B$4:$B$18,0)),"OK","CHECK"),"CHECK")) | H13: =IFERROR(INDEX(Cluster_Master!$C$4:$C$18,MATCH($F13,Cluster_Master!$B$4:$B$18,0)),"") | I13: =IFERROR(INDEX(Cluster_Master!$D$4:$D$18,MATCH($F13,Cluster_Master!$B$4:$B$18,0)),"") | J13: =IFERROR(INDEX(Cluster_Master!$E$4:$E$18,MATCH($F13,Cluster_Master!$B$4:$B$18,0)),"") | K13: =IFERROR(INDEX(Cluster_Master!$F$4:$F$18,MATCH($F13,Cluster_Master!$B$4:$B$18,0)),"") | L13: =IFERROR(INDEX(Cluster_Master!$G$4:$G$18,MATCH($F13,Cluster_Master!$B$4:$B$18,0)),"") | M13: =IFERROR(INDEX(Cluster_Master!$H$4:$H$18,MATCH($F13,Cluster_Master!$B$4:$B$18,0)),"") | AI13: =IF(COUNTA(T13:AH13)=0,"",SUM(T13:AH13)) | AJ13: =IF(COUNTA(T13:AH13)=0,"",AI13/75) | AK13: =IF(COUNTA(T13:AH13)=0,"",(SUM(T13*KPI_Weights!$B$4,U13*KPI_Weights!$B$5,V13*KPI_Weights!$B$6,W13*KPI_Weights!$B$7,X13*KPI_Weights!$B$8,Y13*KPI_Weights!$B$9,Z13*KPI_Weights!$B$10,AA13*KPI_Weights!$B$11,AB13*KPI_Weights!$B$12,AC13*KPI_Weights!$B$13,AD13*KPI_Weights!$B$14,AE13*KPI_Weights!$B$15,AF13*KPI_Weights!$B$16,AG13*KPI_Weights!$B$17,AH13*KPI_Weights!$B$18))/5) | AL13: =IF(COUNTA(T13:AH13)=0,"",IF(OR(T13<=1,W13<=1,X13<=1,Y13<=1,AB13<=1),"YES","NO")) | AM13: =IF(AJ13="","",IF(AND(AL13="NO",AJ13>=0.75),"YES","NO")) | AN13: =IF(AJ13="","",IF(AJ13<0.4,"Critical",IF(AJ13<0.6,"Poor",IF(AJ13<0.75,"Needs Improvement",IF(AJ13<0.9,"Good","Excellent")))))
A14: =IF($B14="","",TEXT($B14,"yyyymmdd")&"-"&SUBSTITUTE($F14," ","")&"-"&TEXT(COUNTIF($F$4:F14,$F14),"00")) | C14: =IF($B14="","",WEEKNUM($B14,2)) | D14: =IF($B14="","",TEXT($B14,"yyyy-mm")) | G14: =IF(OR($E14="",$F14=""),"",IFERROR(IF($E14=INDEX(Cluster_Master!$A$4:$A$18,MATCH($F14,Cluster_Master!$B$4:$B$18,0)),"OK","CHECK"),"CHECK")) | H14: =IFERROR(INDEX(Cluster_Master!$C$4:$C$18,MATCH($F14,Cluster_Master!$B$4:$B$18,0)),"") | I14: =IFERROR(INDEX(Cluster_Master!$D$4:$D$18,MATCH($F14,Cluster_Master!$B$4:$B$18,0)),"") | J14: =IFERROR(INDEX(Cluster_Master!$E$4:$E$18,MATCH($F14,Cluster_Master!$B$4:$B$18,0)),"") | K14: =IFERROR(INDEX(Cluster_Master!$F$4:$F$18,MATCH($F14,Cluster_Master!$B$4:$B$18,0)),"") | L14: =IFERROR(INDEX(Cluster_Master!$G$4:$G$18,MATCH($F14,Cluster_Master!$B$4:$B$18,0)),"") | M14: =IFERROR(INDEX(Cluster_Master!$H$4:$H$18,MATCH($F14,Cluster_Master!$B$4:$B$18,0)),"") | AI14: =IF(COUNTA(T14:AH14)=0,"",SUM(T14:AH14)) | AJ14: =IF(COUNTA(T14:AH14)=0,"",AI14/75) | AK14: =IF(COUNTA(T14:AH14)=0,"",(SUM(T14*KPI_Weights!$B$4,U14*KPI_Weights!$B$5,V14*KPI_Weights!$B$6,W14*KPI_Weights!$B$7,X14*KPI_Weights!$B$8,Y14*KPI_Weights!$B$9,Z14*KPI_Weights!$B$10,AA14*KPI_Weights!$B$11,AB14*KPI_Weights!$B$12,AC14*KPI_Weights!$B$13,AD14*KPI_Weights!$B$14,AE14*KPI_Weights!$B$15,AF14*KPI_Weights!$B$16,AG14*KPI_Weights!$B$17,AH14*KPI_Weights!$B$18))/5) | AL14: =IF(COUNTA(T14:AH14)=0,"",IF(OR(T14<=1,W14<=1,X14<=1,Y14<=1,AB14<=1),"YES","NO")) | AM14: =IF(AJ14="","",IF(AND(AL14="NO",AJ14>=0.75),"YES","NO")) | AN14: =IF(AJ14="","",IF(AJ14<0.4,"Critical",IF(AJ14<0.6,"Poor",IF(AJ14<0.75,"Needs Improvement",IF(AJ14<0.9,"Good","Excellent")))))
A15: =IF($B15="","",TEXT($B15,"yyyymmdd")&"-"&SUBSTITUTE($F15," ","")&"-"&TEXT(COUNTIF($F$4:F15,$F15),"00")) | C15: =IF($B15="","",WEEKNUM($B15,2)) | D15: =IF($B15="","",TEXT($B15,"yyyy-mm")) | G15: =IF(OR($E15="",$F15=""),"",IFERROR(IF($E15=INDEX(Cluster_Master!$A$4:$A$18,MATCH($F15,Cluster_Master!$B$4:$B$18,0)),"OK","CHECK"),"CHECK")) | H15: =IFERROR(INDEX(Cluster_Master!$C$4:$C$18,MATCH($F15,Cluster_Master!$B$4:$B$18,0)),"") | I15: =IFERROR(INDEX(Cluster_Master!$D$4:$D$18,MATCH($F15,Cluster_Master!$B$4:$B$18,0)),"") | J15: =IFERROR(INDEX(Cluster_Master!$E$4:$E$18,MATCH($F15,Cluster_Master!$B$4:$B$18,0)),"") | K15: =IFERROR(INDEX(Cluster_Master!$F$4:$F$18,MATCH($F15,Cluster_Master!$B$4:$B$18,0)),"") | L15: =IFERROR(INDEX(Cluster_Master!$G$4:$G$18,MATCH($F15,Cluster_Master!$B$4:$B$18,0)),"") | M15: =IFERROR(INDEX(Cluster_Master!$H$4:$H$18,MATCH($F15,Cluster_Master!$B$4:$B$18,0)),"") | AI15: =IF(COUNTA(T15:AH15)=0,"",SUM(T15:AH15)) | AJ15: =IF(COUNTA(T15:AH15)=0,"",AI15/75) | AK15: =IF(COUNTA(T15:AH15)=0,"",(SUM(T15*KPI_Weights!$B$4,U15*KPI_Weights!$B$5,V15*KPI_Weights!$B$6,W15*KPI_Weights!$B$7,X15*KPI_Weights!$B$8,Y15*KPI_Weights!$B$9,Z15*KPI_Weights!$B$10,AA15*KPI_Weights!$B$11,AB15*KPI_Weights!$B$12,AC15*KPI_Weights!$B$13,AD15*KPI_Weights!$B$14,AE15*KPI_Weights!$B$15,AF15*KPI_Weights!$B$16,AG15*KPI_Weights!$B$17,AH15*KPI_Weights!$B$18))/5) | AL15: =IF(COUNTA(T15:AH15)=0,"",IF(OR(T15<=1,W15<=1,X15<=1,Y15<=1,AB15<=1),"YES","NO")) | AM15: =IF(AJ15="","",IF(AND(AL15="NO",AJ15>=0.75),"YES","NO")) | AN15: =IF(AJ15="","",IF(AJ15<0.4,"Critical",IF(AJ15<0.6,"Poor",IF(AJ15<0.75,"Needs Improvement",IF(AJ15<0.9,"Good","Excellent")))))
A16: =IF($B16="","",TEXT($B16,"yyyymmdd")&"-"&SUBSTITUTE($F16," ","")&"-"&TEXT(COUNTIF($F$4:F16,$F16),"00")) | C16: =IF($B16="","",WEEKNUM($B16,2)) | D16: =IF($B16="","",TEXT($B16,"yyyy-mm")) | G16: =IF(OR($E16="",$F16=""),"",IFERROR(IF($E16=INDEX(Cluster_Master!$A$4:$A$18,MATCH($F16,Cluster_Master!$B$4:$B$18,0)),"OK","CHECK"),"CHECK")) | H16: =IFERROR(INDEX(Cluster_Master!$C$4:$C$18,MATCH($F16,Cluster_Master!$B$4:$B$18,0)),"") | I16: =IFERROR(INDEX(Cluster_Master!$D$4:$D$18,MATCH($F16,Cluster_Master!$B$4:$B$18,0)),"") | J16: =IFERROR(INDEX(Cluster_Master!$E$4:$E$18,MATCH($F16,Cluster_Master!$B$4:$B$18,0)),"") | K16: =IFERROR(INDEX(Cluster_Master!$F$4:$F$18,MATCH($F16,Cluster_Master!$B$4:$B$18,0)),"") | L16: =IFERROR(INDEX(Cluster_Master!$G$4:$G$18,MATCH($F16,Cluster_Master!$B$4:$B$18,0)),"") | M16: =IFERROR(INDEX(Cluster_Master!$H$4:$H$18,MATCH($F16,Cluster_Master!$B$4:$B$18,0)),"") | AI16: =IF(COUNTA(T16:AH16)=0,"",SUM(T16:AH16)) | AJ16: =IF(COUNTA(T16:AH16)=0,"",AI16/75) | AK16: =IF(COUNTA(T16:AH16)=0,"",(SUM(T16*KPI_Weights!$B$4,U16*KPI_Weights!$B$5,V16*KPI_Weights!$B$6,W16*KPI_Weights!$B$7,X16*KPI_Weights!$B$8,Y16*KPI_Weights!$B$9,Z16*KPI_Weights!$B$10,AA16*KPI_Weights!$B$11,AB16*KPI_Weights!$B$12,AC16*KPI_Weights!$B$13,AD16*KPI_Weights!$B$14,AE16*KPI_Weights!$B$15,AF16*KPI_Weights!$B$16,AG16*KPI_Weights!$B$17,AH16*KPI_Weights!$B$18))/5) | AL16: =IF(COUNTA(T16:AH16)=0,"",IF(OR(T16<=1,W16<=1,X16<=1,Y16<=1,AB16<=1),"YES","NO")) | AM16: =IF(AJ16="","",IF(AND(AL16="NO",AJ16>=0.75),"YES","NO")) | AN16: =IF(AJ16="","",IF(AJ16<0.4,"Critical",IF(AJ16<0.6,"Poor",IF(AJ16<0.75,"Needs Improvement",IF(AJ16<0.9,"Good","Excellent")))))
A17: =IF($B17="","",TEXT($B17,"yyyymmdd")&"-"&SUBSTITUTE($F17," ","")&"-"&TEXT(COUNTIF($F$4:F17,$F17),"00")) | C17: =IF($B17="","",WEEKNUM($B17,2)) | D17: =IF($B17="","",TEXT($B17,"yyyy-mm")) | G17: =IF(OR($E17="",$F17=""),"",IFERROR(IF($E17=INDEX(Cluster_Master!$A$4:$A$18,MATCH($F17,Cluster_Master!$B$4:$B$18,0)),"OK","CHECK"),"CHECK")) | H17: =IFERROR(INDEX(Cluster_Master!$C$4:$C$18,MATCH($F17,Cluster_Master!$B$4:$B$18,0)),"") | I17: =IFERROR(INDEX(Cluster_Master!$D$4:$D$18,MATCH($F17,Cluster_Master!$B$4:$B$18,0)),"") | J17: =IFERROR(INDEX(Cluster_Master!$E$4:$E$18,MATCH($F17,Cluster_Master!$B$4:$B$18,0)),"") | K17: =IFERROR(INDEX(Cluster_Master!$F$4:$F$18,MATCH($F17,Cluster_Master!$B$4:$B$18,0)),"") | L17: =IFERROR(INDEX(Cluster_Master!$G$4:$G$18,MATCH($F17,Cluster_Master!$B$4:$B$18,0)),"") | M17: =IFERROR(INDEX(Cluster_Master!$H$4:$H$18,MATCH($F17,Cluster_Master!$B$4:$B$18,0)),"") | AI17: =IF(COUNTA(T17:AH17)=0,"",SUM(T17:AH17)) | AJ17: =IF(COUNTA(T17:AH17)=0,"",AI17/75) | AK17: =IF(COUNTA(T17:AH17)=0,"",(SUM(T17*KPI_Weights!$B$4,U17*KPI_Weights!$B$5,V17*KPI_Weights!$B$6,W17*KPI_Weights!$B$7,X17*KPI_Weights!$B$8,Y17*KPI_Weights!$B$9,Z17*KPI_Weights!$B$10,AA17*KPI_Weights!$B$11,AB17*KPI_Weights!$B$12,AC17*KPI_Weights!$B$13,AD17*KPI_Weights!$B$14,AE17*KPI_Weights!$B$15,AF17*KPI_Weights!$B$16,AG17*KPI_Weights!$B$17,AH17*KPI_Weights!$B$18))/5) | AL17: =IF(COUNTA(T17:AH17)=0,"",IF(OR(T17<=1,W17<=1,X17<=1,Y17<=1,AB17<=1),"YES","NO")) | AM17: =IF(AJ17="","",IF(AND(AL17="NO",AJ17>=0.75),"YES","NO")) | AN17: =IF(AJ17="","",IF(AJ17<0.4,"Critical",IF(AJ17<0.6,"Poor",IF(AJ17<0.75,"Needs Improvement",IF(AJ17<0.9,"Good","Excellent")))))
A18: =IF($B18="","",TEXT($B18,"yyyymmdd")&"-"&SUBSTITUTE($F18," ","")&"-"&TEXT(COUNTIF($F$4:F18,$F18),"00")) | C18: =IF($B18="","",WEEKNUM($B18,2)) | D18: =IF($B18="","",TEXT($B18,"yyyy-mm")) | G18: =IF(OR($E18="",$F18=""),"",IFERROR(IF($E18=INDEX(Cluster_Master!$A$4:$A$18,MATCH($F18,Cluster_Master!$B$4:$B$18,0)),"OK","CHECK"),"CHECK")) | H18: =IFERROR(INDEX(Cluster_Master!$C$4:$C$18,MATCH($F18,Cluster_Master!$B$4:$B$18,0)),"") | I18: =IFERROR(INDEX(Cluster_Master!$D$4:$D$18,MATCH($F18,Cluster_Master!$B$4:$B$18,0)),"") | J18: =IFERROR(INDEX(Cluster_Master!$E$4:$E$18,MATCH($F18,Cluster_Master!$B$4:$B$18,0)),"") | K18: =IFERROR(INDEX(Cluster_Master!$F$4:$F$18,MATCH($F18,Cluster_Master!$B$4:$B$18,0)),"") | L18: =IFERROR(INDEX(Cluster_Master!$G$4:$G$18,MATCH($F18,Cluster_Master!$B$4:$B$18,0)),"") | M18: =IFERROR(INDEX(Cluster_Master!$H$4:$H$18,MATCH($F18,Cluster_Master!$B$4:$B$18,0)),"") | AI18: =IF(COUNTA(T18:AH18)=0,"",SUM(T18:AH18)) | AJ18: =IF(COUNTA(T18:AH18)=0,"",AI18/75) | AK18: =IF(COUNTA(T18:AH18)=0,"",(SUM(T18*KPI_Weights!$B$4,U18*KPI_Weights!$B$5,V18*KPI_Weights!$B$6,W18*KPI_Weights!$B$7,X18*KPI_Weights!$B$8,Y18*KPI_Weights!$B$9,Z18*KPI_Weights!$B$10,AA18*KPI_Weights!$B$11,AB18*KPI_Weights!$B$12,AC18*KPI_Weights!$B$13,AD18*KPI_Weights!$B$14,AE18*KPI_Weights!$B$15,AF18*KPI_Weights!$B$16,AG18*KPI_Weights!$B$17,AH18*KPI_Weights!$B$18))/5) | AL18: =IF(COUNTA(T18:AH18)=0,"",IF(OR(T18<=1,W18<=1,X18<=1,Y18<=1,AB18<=1),"YES","NO")) | AM18: =IF(AJ18="","",IF(AND(AL18="NO",AJ18>=0.75),"YES","NO")) | AN18: =IF(AJ18="","",IF(AJ18<0.4,"Critical",IF(AJ18<0.6,"Poor",IF(AJ18<0.75,"Needs Improvement",IF(AJ18<0.9,"Good","Excellent")))))
A19: =IF($B19="","",TEXT($B19,"yyyymmdd")&"-"&SUBSTITUTE($F19," ","")&"-"&TEXT(COUNTIF($F$4:F19,$F19),"00")) | C19: =IF($B19="","",WEEKNUM($B19,2)) | D19: =IF($B19="","",TEXT($B19,"yyyy-mm")) | G19: =IF(OR($E19="",$F19=""),"",IFERROR(IF($E19=INDEX(Cluster_Master!$A$4:$A$18,MATCH($F19,Cluster_Master!$B$4:$B$18,0)),"OK","CHECK"),"CHECK")) | H19: =IFERROR(INDEX(Cluster_Master!$C$4:$C$18,MATCH($F19,Cluster_Master!$B$4:$B$18,0)),"") | I19: =IFERROR(INDEX(Cluster_Master!$D$4:$D$18,MATCH($F19,Cluster_Master!$B$4:$B$18,0)),"") | J19: =IFERROR(INDEX(Cluster_Master!$E$4:$E$18,MATCH($F19,Cluster_Master!$B$4:$B$18,0)),"") | K19: =IFERROR(INDEX(Cluster_Master!$F$4:$F$18,MATCH($F19,Cluster_Master!$B$4:$B$18,0)),"") | L19: =IFERROR(INDEX(Cluster_Master!$G$4:$G$18,MATCH($F19,Cluster_Master!$B$4:$B$18,0)),"") | M19: =IFERROR(INDEX(Cluster_Master!$H$4:$H$18,MATCH($F19,Cluster_Master!$B$4:$B$18,0)),"") | AI19: =IF(COUNTA(T19:AH19)=0,"",SUM(T19:AH19)) | AJ19: =IF(COUNTA(T19:AH19)=0,"",AI19/75) | AK19: =IF(COUNTA(T19:AH19)=0,"",(SUM(T19*KPI_Weights!$B$4,U19*KPI_Weights!$B$5,V19*KPI_Weights!$B$6,W19*KPI_Weights!$B$7,X19*KPI_Weights!$B$8,Y19*KPI_Weights!$B$9,Z19*KPI_Weights!$B$10,AA19*KPI_Weights!$B$11,AB19*KPI_Weights!$B$12,AC19*KPI_Weights!$B$13,AD19*KPI_Weights!$B$14,AE19*KPI_Weights!$B$15,AF19*KPI_Weights!$B$16,AG19*KPI_Weights!$B$17,AH19*KPI_Weights!$B$18))/5) | AL19: =IF(COUNTA(T19:AH19)=0,"",IF(OR(T19<=1,W19<=1,X19<=1,Y19<=1,AB19<=1),"YES","NO")) | AM19: =IF(AJ19="","",IF(AND(AL19="NO",AJ19>=0.75),"YES","NO")) | AN19: =IF(AJ19="","",IF(AJ19<0.4,"Critical",IF(AJ19<0.6,"Poor",IF(AJ19<0.75,"Needs Improvement",IF(AJ19<0.9,"Good","Excellent")))))
A20: =IF($B20="","",TEXT($B20,"yyyymmdd")&"-"&SUBSTITUTE($F20," ","")&"-"&TEXT(COUNTIF($F$4:F20,$F20),"00")) | C20: =IF($B20="","",WEEKNUM($B20,2)) | D20: =IF($B20="","",TEXT($B20,"yyyy-mm")) | G20: =IF(OR($E20="",$F20=""),"",IFERROR(IF($E20=INDEX(Cluster_Master!$A$4:$A$18,MATCH($F20,Cluster_Master!$B$4:$B$18,0)),"OK","CHECK"),"CHECK")) | H20: =IFERROR(INDEX(Cluster_Master!$C$4:$C$18,MATCH($F20,Cluster_Master!$B$4:$B$18,0)),"") | I20: =IFERROR(INDEX(Cluster_Master!$D$4:$D$18,MATCH($F20,Cluster_Master!$B$4:$B$18,0)),"") | J20: =IFERROR(INDEX(Cluster_Master!$E$4:$E$18,MATCH($F20,Cluster_Master!$B$4:$B$18,0)),"") | K20: =IFERROR(INDEX(Cluster_Master!$F$4:$F$18,MATCH($F20,Cluster_Master!$B$4:$B$18,0)),"") | L20: =IFERROR(INDEX(Cluster_Master!$G$4:$G$18,MATCH($F20,Cluster_Master!$B$4:$B$18,0)),"") | M20: =IFERROR(INDEX(Cluster_Master!$H$4:$H$18,MATCH($F20,Cluster_Master!$B$4:$B$18,0)),"") | AI20: =IF(COUNTA(T20:AH20)=0,"",SUM(T20:AH20)) | AJ20: =IF(COUNTA(T20:AH20)=0,"",AI20/75) | AK20: =IF(COUNTA(T20:AH20)=0,"",(SUM(T20*KPI_Weights!$B$4,U20*KPI_Weights!$B$5,V20*KPI_Weights!$B$6,W20*KPI_Weights!$B$7,X20*KPI_Weights!$B$8,Y20*KPI_Weights!$B$9,Z20*KPI_Weights!$B$10,AA20*KPI_Weights!$B$11,AB20*KPI_Weights!$B$12,AC20*KPI_Weights!$B$13,AD20*KPI_Weights!$B$14,AE20*KPI_Weights!$B$15,AF20*KPI_Weights!$B$16,AG20*KPI_Weights!$B$17,AH20*KPI_Weights!$B$18))/5) | AL20: =IF(COUNTA(T20:AH20)=0,"",IF(OR(T20<=1,W20<=1,X20<=1,Y20<=1,AB20<=1),"YES","NO")) | AM20: =IF(AJ20="","",IF(AND(AL20="NO",AJ20>=0.75),"YES","NO")) | AN20: =IF(AJ20="","",IF(AJ20<0.4,"Critical",IF(AJ20<0.6,"Poor",IF(AJ20<0.75,"Needs Improvement",IF(AJ20<0.9,"Good","Excellent")))))
A21: =IF($B21="","",TEXT($B21,"yyyymmdd")&"-"&SUBSTITUTE($F21," ","")&"-"&TEXT(COUNTIF($F$4:F21,$F21),"00")) | C21: =IF($B21="","",WEEKNUM($B21,2)) | D21: =IF($B21="","",TEXT($B21,"yyyy-mm")) | G21: =IF(OR($E21="",$F21=""),"",IFERROR(IF($E21=INDEX(Cluster_Master!$A$4:$A$18,MATCH($F21,Cluster_Master!$B$4:$B$18,0)),"OK","CHECK"),"CHECK")) | H21: =IFERROR(INDEX(Cluster_Master!$C$4:$C$18,MATCH($F21,Cluster_Master!$B$4:$B$18,0)),"") | I21: =IFERROR(INDEX(Cluster_Master!$D$4:$D$18,MATCH($F21,Cluster_Master!$B$4:$B$18,0)),"") | J21: =IFERROR(INDEX(Cluster_Master!$E$4:$E$18,MATCH($F21,Cluster_Master!$B$4:$B$18,0)),"") | K21: =IFERROR(INDEX(Cluster_Master!$F$4:$F$18,MATCH($F21,Cluster_Master!$B$4:$B$18,0)),"") | L21: =IFERROR(INDEX(Cluster_Master!$G$4:$G$18,MATCH($F21,Cluster_Master!$B$4:$B$18,0)),"") | M21: =IFERROR(INDEX(Cluster_Master!$H$4:$H$18,MATCH($F21,Cluster_Master!$B$4:$B$18,0)),"") | AI21: =IF(COUNTA(T21:AH21)=0,"",SUM(T21:AH21)) | AJ21: =IF(COUNTA(T21:AH21)=0,"",AI21/75) | AK21: =IF(COUNTA(T21:AH21)=0,"",(SUM(T21*KPI_Weights!$B$4,U21*KPI_Weights!$B$5,V21*KPI_Weights!$B$6,W21*KPI_Weights!$B$7,X21*KPI_Weights!$B$8,Y21*KPI_Weights!$B$9,Z21*KPI_Weights!$B$10,AA21*KPI_Weights!$B$11,AB21*KPI_Weights!$B$12,AC21*KPI_Weights!$B$13,AD21*KPI_Weights!$B$14,AE21*KPI_Weights!$B$15,AF21*KPI_Weights!$B$16,AG21*KPI_Weights!$B$17,AH21*KPI_Weights!$B$18))/5) | AL21: =IF(COUNTA(T21:AH21)=0,"",IF(OR(T21<=1,W21<=1,X21<=1,Y21<=1,AB21<=1),"YES","NO")) | AM21: =IF(AJ21="","",IF(AND(AL21="NO",AJ21>=0.75),"YES","NO")) | AN21: =IF(AJ21="","",IF(AJ21<0.4,"Critical",IF(AJ21<0.6,"Poor",IF(AJ21<0.75,"Needs Improvement",IF(AJ21<0.9,"Good","Excellent")))))
... A996: =IF($B996="","",TEXT($B996,"yyyymmdd")&"-"&SUBSTITUTE($F996," ","")&"-"&TEXT(COUNTIF($F$4:F996,$F996),"00")) | C996: =IF($B996="","",WEEKNUM($B996,2)) | D996: =IF($B996="","",TEXT($B996,"yyyy-mm")) | G996: =IF(OR($E996="",$F996=""),"",IFERROR(IF($E996=INDEX(Cluster_Master!$A$4:$A$18,MATCH($F996,Cluster_Master!$B$4:$B$18,0)),"OK","CHECK"),"CHECK")) | H996: =IFERROR(INDEX(Cluster_Master!$C$4:$C$18,MATCH($F996,Cluster_Master!$B$4:$B$18,0)),"") | I996: =IFERROR(INDEX(Cluster_Master!$D$4:$D$18,MATCH($F996,Cluster_Master!$B$4:$B$18,0)),"") | J996: =IFERROR(INDEX(Cluster_Master!$E$4:$E$18,MATCH($F996,Cluster_Master!$B$4:$B$18,0)),"") | K996: =IFERROR(INDEX(Cluster_Master!$F$4:$F$18,MATCH($F996,Cluster_Master!$B$4:$B$18,0)),"") | L996: =IFERROR(INDEX(Cluster_Master!$G$4:$G$18,MATCH($F996,Cluster_Master!$B$4:$B$18,0)),"") | M996: =IFERROR(INDEX(Cluster_Master!$H$4:$H$18,MATCH($F996,Cluster_Master!$B$4:$B$18,0)),"") | AI996: =IF(COUNTA(T996:AH996)=0,"",SUM(T996:AH996)) | AJ996: =IF(COUNTA(T996:AH996)=0,"",AI996/75) | AK996: =IF(COUNTA(T996:AH996)=0,"",(SUM(T996*KPI_Weights!$B$4,U996*KPI_Weights!$B$5,V996*KPI_Weights!$B$6,W996*KPI_Weights!$B$7,X996*KPI_Weights!$B$8,Y996*KPI_Weights!$B$9,Z996*KPI_Weights!$B$10,AA996*KPI_Weights!$B$11,AB996*KPI_Weights!$B$12,AC996*KPI_Weights!$B$13,AD996*KPI_Weights!$B$14,AE996*KPI_Weights!$B$15,AF996*KPI_Weights!$B$16,AG996*KPI_Weights!$B$17,AH996*KPI_Weights!$B$18))/5) | AL996: =IF(COUNTA(T996:AH996)=0,"",IF(OR(T996<=1,W996<=1,X996<=1,Y996<=1,AB996<=1),"YES","NO")) | AM996: =IF(AJ996="","",IF(AND(AL996="NO",AJ996>=0.75),"YES","NO")) | AN996: =IF(AJ996="","",IF(AJ996<0.4,"Critical",IF(AJ996<0.6,"Poor",IF(AJ996<0.75,"Needs Improvement",IF(AJ996<0.9,"Good","Excellent")))))

Sheet Weekly_Dashboard
A1: Weekly Dashboard
A2: Set the control week and month in blue-font cells. This sheet summarizes weekly and current month performance by cluster and highlights weak KPIs / root causes.
A4: Control inputs
A5: Selected Week No | B5: =IFERROR(MAX(Weekly_Inspections!$C$4:$C$996),"") -> 14
A6: Selected Month (yyyy-mm) | B6: =IFERROR(LOOKUP(2,1/(Weekly_Inspections!$D$4:$D$996<>""),Weekly_Inspections!$D$4:$D$996),"") -> 2026-03
A7: Previous Month (yyyy-mm) | B7: =IF($B$6="","",TEXT(EDATE(DATE(VALUE(LEFT($B$6,4)),VALUE(RIGHT($B$6,2)),1),-1),"yyyy-mm")) -> 2026-02
A9: Cluster | B9: Package | C9: Contractor | D9: Week Avg Raw % | E9: Week Avg Weighted % | F9: Week Red Flags | G9: Month Avg Raw % | H9: Month Avg Weighted % | I9: Month Red Flags | J9: Month Improvement | K9: Award Eligible | L9: Rank
A10: Cluster 7A | B10: =IFERROR(INDEX(Cluster_Master!$A$4:$A$18,MATCH($A10,Cluster_Master!$B$4:$B$18,0)),"") -> 2 | C10: =IFERROR(INDEX(Cluster_Master!$C$4:$C$18,MATCH($A10,Cluster_Master!$B$4:$B$18,0)),"") -> TAJV | D10: =IF($B$5="","",IFERROR(AVERAGEIFS(Weekly_Inspections!$AJ$4:$AJ$996,Weekly_Inspections!$F$4:$F$996,$A10,Weekly_Inspections!$C$4:$C$996,$B$5),"")) | E10: =IF($B$5="","",IFERROR(AVERAGEIFS(Weekly_Inspections!$AK$4:$AK$996,Weekly_Inspections!$F$4:$F$996,$A10,Weekly_Inspections!$C$4:$C$996,$B$5),"")) | F10: =IF($B$5="","",COUNTIFS(Weekly_Inspections!$F$4:$F$996,$A10,Weekly_Inspections!$C$4:$C$996,$B$5,Weekly_Inspections!$AL$4:$AL$996,"YES")) -> 0 | G10: =IF($B$6="","",IFERROR(AVERAGEIFS(Weekly_Inspections!$AJ$4:$AJ$996,Weekly_Inspections!$F$4:$F$996,$A10,Weekly_Inspections!$D$4:$D$996,$B$6),"")) | H10: =IF($B$6="","",IFERROR(AVERAGEIFS(Weekly_Inspections!$AK$4:$AK$996,Weekly_Inspections!$F$4:$F$996,$A10,Weekly_Inspections!$D$4:$D$996,$B$6),"")) | I10: =IF($B$6="","",COUNTIFS(Weekly_Inspections!$F$4:$F$996,$A10,Weekly_Inspections!$D$4:$D$996,$B$6,Weekly_Inspections!$AL$4:$AL$996,"YES")) -> 0 | J10: =IF(OR($B$6="",$B$7=""),"",IFERROR((G10-AVERAGEIFS(Weekly_Inspections!$AJ$4:$AJ$996,Weekly_Inspections!$F$4:$F$996,$A10,Weekly_Inspections!$D$4:$D$996,$B$7))/AVERAGEIFS(Weekly_Inspections!$AJ$4:$AJ$996,Weekly_Inspections!$F$4:$F$996,$A10,Weekly_Inspections!$D$4:$D$996,$B$7),"")) | K10: =IF(G10="","",IF(AND(I10=0,G10>=0.75),"YES","NO")) | L10: =IF(G10="","",RANK(G10,$G$10:$G$24,0))
A11: Cluster 7B | B11: =IFERROR(INDEX(Cluster_Master!$A$4:$A$18,MATCH($A11,Cluster_Master!$B$4:$B$18,0)),"") -> 2 | C11: =IFERROR(INDEX(Cluster_Master!$C$4:$C$18,MATCH($A11,Cluster_Master!$B$4:$B$18,0)),"") -> TAJV | D11: =IF($B$5="","",IFERROR(AVERAGEIFS(Weekly_Inspections!$AJ$4:$AJ$996,Weekly_Inspections!$F$4:$F$996,$A11,Weekly_Inspections!$C$4:$C$996,$B$5),"")) | E11: =IF($B$5="","",IFERROR(AVERAGEIFS(Weekly_Inspections!$AK$4:$AK$996,Weekly_Inspections!$F$4:$F$996,$A11,Weekly_Inspections!$C$4:$C$996,$B$5),"")) | F11: =IF($B$5="","",COUNTIFS(Weekly_Inspections!$F$4:$F$996,$A11,Weekly_Inspections!$C$4:$C$996,$B$5,Weekly_Inspections!$AL$4:$AL$996,"YES")) -> 0 | G11: =IF($B$6="","",IFERROR(AVERAGEIFS(Weekly_Inspections!$AJ$4:$AJ$996,Weekly_Inspections!$F$4:$F$996,$A11,Weekly_Inspections!$D$4:$D$996,$B$6),"")) | H11: =IF($B$6="","",IFERROR(AVERAGEIFS(Weekly_Inspections!$AK$4:$AK$996,Weekly_Inspections!$F$4:$F$996,$A11,Weekly_Inspections!$D$4:$D$996,$B$6),"")) | I11: =IF($B$6="","",COUNTIFS(Weekly_Inspections!$F$4:$F$996,$A11,Weekly_Inspections!$D$4:$D$996,$B$6,Weekly_Inspections!$AL$4:$AL$996,"YES")) -> 0 | J11: =IF(OR($B$6="",$B$7=""),"",IFERROR((G11-AVERAGEIFS(Weekly_Inspections!$AJ$4:$AJ$996,Weekly_Inspections!$F$4:$F$996,$A11,Weekly_Inspections!$D$4:$D$996,$B$7))/AVERAGEIFS(Weekly_Inspections!$AJ$4:$AJ$996,Weekly_Inspections!$F$4:$F$996,$A11,Weekly_Inspections!$D$4:$D$996,$B$7),"")) | K11: =IF(G11="","",IF(AND(I11=0,G11>=0.75),"YES","NO")) | L11: =IF(G11="","",RANK(G11,$G$10:$G$24,0))
A12: Cluster 8A | B12: =IFERROR(INDEX(Cluster_Master!$A$4:$A$18,MATCH($A12,Cluster_Master!$B$4:$B$18,0)),"") -> 2 | C12: =IFERROR(INDEX(Cluster_Master!$C$4:$C$18,MATCH($A12,Cluster_Master!$B$4:$B$18,0)),"") -> TAJV | D12: =IF($B$5="","",IFERROR(AVERAGEIFS(Weekly_Inspections!$AJ$4:$AJ$996,Weekly_Inspections!$F$4:$F$996,$A12,Weekly_Inspections!$C$4:$C$996,$B$5),"")) | E12: =IF($B$5="","",IFERROR(AVERAGEIFS(Weekly_Inspections!$AK$4:$AK$996,Weekly_Inspections!$F$4:$F$996,$A12,Weekly_Inspections!$C$4:$C$996,$B$5),"")) | F12: =IF($B$5="","",COUNTIFS(Weekly_Inspections!$F$4:$F$996,$A12,Weekly_Inspections!$C$4:$C$996,$B$5,Weekly_Inspections!$AL$4:$AL$996,"YES")) -> 0 | G12: =IF($B$6="","",IFERROR(AVERAGEIFS(Weekly_Inspections!$AJ$4:$AJ$996,Weekly_Inspections!$F$4:$F$996,$A12,Weekly_Inspections!$D$4:$D$996,$B$6),"")) -> 0.78666667 | H12: =IF($B$6="","",IFERROR(AVERAGEIFS(Weekly_Inspections!$AK$4:$AK$996,Weekly_Inspections!$F$4:$F$996,$A12,Weekly_Inspections!$D$4:$D$996,$B$6),"")) -> 0.794 | I12: =IF($B$6="","",COUNTIFS(Weekly_Inspections!$F$4:$F$996,$A12,Weekly_Inspections!$D$4:$D$996,$B$6,Weekly_Inspections!$AL$4:$AL$996,"YES")) -> 0 | J12: =IF(OR($B$6="",$B$7=""),"",IFERROR((G12-AVERAGEIFS(Weekly_Inspections!$AJ$4:$AJ$996,Weekly_Inspections!$F$4:$F$996,$A12,Weekly_Inspections!$D$4:$D$996,$B$7))/AVERAGEIFS(Weekly_Inspections!$AJ$4:$AJ$996,Weekly_Inspections!$F$4:$F$996,$A12,Weekly_Inspections!$D$4:$D$996,$B$7),"")) | K12: =IF(G12="","",IF(AND(I12=0,G12>=0.75),"YES","NO")) -> YES | L12: =IF(G12="","",RANK(G12,$G$10:$G$24,0)) -> 1
A13: Cluster 8B | B13: =IFERROR(INDEX(Cluster_Master!$A$4:$A$18,MATCH($A13,Cluster_Master!$B$4:$B$18,0)),"") -> 2 | C13: =IFERROR(INDEX(Cluster_Master!$C$4:$C$18,MATCH($A13,Cluster_Master!$B$4:$B$18,0)),"") -> TAJV | D13: =IF($B$5="","",IFERROR(AVERAGEIFS(Weekly_Inspections!$AJ$4:$AJ$996,Weekly_Inspections!$F$4:$F$996,$A13,Weekly_Inspections!$C$4:$C$996,$B$5),"")) | E13: =IF($B$5="","",IFERROR(AVERAGEIFS(Weekly_Inspections!$AK$4:$AK$996,Weekly_Inspections!$F$4:$F$996,$A13,Weekly_Inspections!$C$4:$C$996,$B$5),"")) | F13: =IF($B$5="","",COUNTIFS(Weekly_Inspections!$F$4:$F$996,$A13,Weekly_Inspections!$C$4:$C$996,$B$5,Weekly_Inspections!$AL$4:$AL$996,"YES")) -> 0 | G13: =IF($B$6="","",IFERROR(AVERAGEIFS(Weekly_Inspections!$AJ$4:$AJ$996,Weekly_Inspections!$F$4:$F$996,$A13,Weekly_Inspections!$D$4:$D$996,$B$6),"")) | H13: =IF($B$6="","",IFERROR(AVERAGEIFS(Weekly_Inspections!$AK$4:$AK$996,Weekly_Inspections!$F$4:$F$996,$A13,Weekly_Inspections!$D$4:$D$996,$B$6),"")) | I13: =IF($B$6="","",COUNTIFS(Weekly_Inspections!$F$4:$F$996,$A13,Weekly_Inspections!$D$4:$D$996,$B$6,Weekly_Inspections!$AL$4:$AL$996,"YES")) -> 0 | J13: =IF(OR($B$6="",$B$7=""),"",IFERROR((G13-AVERAGEIFS(Weekly_Inspections!$AJ$4:$AJ$996,Weekly_Inspections!$F$4:$F$996,$A13,Weekly_Inspections!$D$4:$D$996,$B$7))/AVERAGEIFS(Weekly_Inspections!$AJ$4:$AJ$996,Weekly_Inspections!$F$4:$F$996,$A13,Weekly_Inspections!$D$4:$D$996,$B$7),"")) | K13: =IF(G13="","",IF(AND(I13=0,G13>=0.75),"YES","NO")) | L13: =IF(G13="","",RANK(G13,$G$10:$G$24,0))
A14: Cluster 8C | B14: =IFERROR(INDEX(Cluster_Master!$A$4:$A$18,MATCH($A14,Cluster_Master!$B$4:$B$18,0)),"") -> 2 | C14: =IFERROR(INDEX(Cluster_Master!$C$4:$C$18,MATCH($A14,Cluster_Master!$B$4:$B$18,0)),"") -> TAJV | D14: =IF($B$5="","",IFERROR(AVERAGEIFS(Weekly_Inspections!$AJ$4:$AJ$996,Weekly_Inspections!$F$4:$F$996,$A14,Weekly_Inspections!$C$4:$C$996,$B$5),"")) | E14: =IF($B$5="","",IFERROR(AVERAGEIFS(Weekly_Inspections!$AK$4:$AK$996,Weekly_Inspections!$F$4:$F$996,$A14,Weekly_Inspections!$C$4:$C$996,$B$5),"")) | F14: =IF($B$5="","",COUNTIFS(Weekly_Inspections!$F$4:$F$996,$A14,Weekly_Inspections!$C$4:$C$996,$B$5,Weekly_Inspections!$AL$4:$AL$996,"YES")) -> 0 | G14: =IF($B$6="","",IFERROR(AVERAGEIFS(Weekly_Inspections!$AJ$4:$AJ$996,Weekly_Inspections!$F$4:$F$996,$A14,Weekly_Inspections!$D$4:$D$996,$B$6),"")) | H14: =IF($B$6="","",IFERROR(AVERAGEIFS(Weekly_Inspections!$AK$4:$AK$996,Weekly_Inspections!$F$4:$F$996,$A14,Weekly_Inspections!$D$4:$D$996,$B$6),"")) | I14: =IF($B$6="","",COUNTIFS(Weekly_Inspections!$F$4:$F$996,$A14,Weekly_Inspections!$D$4:$D$996,$B$6,Weekly_Inspections!$AL$4:$AL$996,"YES")) -> 0 | J14: =IF(OR($B$6="",$B$7=""),"",IFERROR((G14-AVERAGEIFS(Weekly_Inspections!$AJ$4:$AJ$996,Weekly_Inspections!$F$4:$F$996,$A14,Weekly_Inspections!$D$4:$D$996,$B$7))/AVERAGEIFS(Weekly_Inspections!$AJ$4:$AJ$996,Weekly_Inspections!$F$4:$F$996,$A14,Weekly_Inspections!$D$4:$D$996,$B$7),"")) | K14: =IF(G14="","",IF(AND(I14=0,G14>=0.75),"YES","NO")) | L14: =IF(G14="","",RANK(G14,$G$10:$G$24,0))
A15: Cluster 8D | B15: =IFERROR(INDEX(Cluster_Master!$A$4:$A$18,MATCH($A15,Cluster_Master!$B$4:$B$18,0)),"") -> 2 | C15: =IFERROR(INDEX(Cluster_Master!$C$4:$C$18,MATCH($A15,Cluster_Master!$B$4:$B$18,0)),"") -> TAJV | D15: =IF($B$5="","",IFERROR(AVERAGEIFS(Weekly_Inspections!$AJ$4:$AJ$996,Weekly_Inspections!$F$4:$F$996,$A15,Weekly_Inspections!$C$4:$C$996,$B$5),"")) | E15: =IF($B$5="","",IFERROR(AVERAGEIFS(Weekly_Inspections!$AK$4:$AK$996,Weekly_Inspections!$F$4:$F$996,$A15,Weekly_Inspections!$C$4:$C$996,$B$5),"")) | F15: =IF($B$5="","",COUNTIFS(Weekly_Inspections!$F$4:$F$996,$A15,Weekly_Inspections!$C$4:$C$996,$B$5,Weekly_Inspections!$AL$4:$AL$996,"YES")) -> 0 | G15: =IF($B$6="","",IFERROR(AVERAGEIFS(Weekly_Inspections!$AJ$4:$AJ$996,Weekly_Inspections!$F$4:$F$996,$A15,Weekly_Inspections!$D$4:$D$996,$B$6),"")) | H15: =IF($B$6="","",IFERROR(AVERAGEIFS(Weekly_Inspections!$AK$4:$AK$996,Weekly_Inspections!$F$4:$F$996,$A15,Weekly_Inspections!$D$4:$D$996,$B$6),"")) | I15: =IF($B$6="","",COUNTIFS(Weekly_Inspections!$F$4:$F$996,$A15,Weekly_Inspections!$D$4:$D$996,$B$6,Weekly_Inspections!$AL$4:$AL$996,"YES")) -> 0 | J15: =IF(OR($B$6="",$B$7=""),"",IFERROR((G15-AVERAGEIFS(Weekly_Inspections!$AJ$4:$AJ$996,Weekly_Inspections!$F$4:$F$996,$A15,Weekly_Inspections!$D$4:$D$996,$B$7))/AVERAGEIFS(Weekly_Inspections!$AJ$4:$AJ$996,Weekly_Inspections!$F$4:$F$996,$A15,Weekly_Inspections!$D$4:$D$996,$B$7),"")) | K15: =IF(G15="","",IF(AND(I15=0,G15>=0.75),"YES","NO")) | L15: =IF(G15="","",RANK(G15,$G$10:$G$24,0))
A16: Cluster 3 | B16: =IFERROR(INDEX(Cluster_Master!$A$4:$A$18,MATCH($A16,Cluster_Master!$B$4:$B$18,0)),"") -> 3 | C16: =IFERROR(INDEX(Cluster_Master!$C$4:$C$18,MATCH($A16,Cluster_Master!$B$4:$B$18,0)),"") -> INNOVO | D16: =IF($B$5="","",IFERROR(AVERAGEIFS(Weekly_Inspections!$AJ$4:$AJ$996,Weekly_Inspections!$F$4:$F$996,$A16,Weekly_Inspections!$C$4:$C$996,$B$5),"")) | E16: =IF($B$5="","",IFERROR(AVERAGEIFS(Weekly_Inspections!$AK$4:$AK$996,Weekly_Inspections!$F$4:$F$996,$A16,Weekly_Inspections!$C$4:$C$996,$B$5),"")) | F16: =IF($B$5="","",COUNTIFS(Weekly_Inspections!$F$4:$F$996,$A16,Weekly_Inspections!$C$4:$C$996,$B$5,Weekly_Inspections!$AL$4:$AL$996,"YES")) -> 0 | G16: =IF($B$6="","",IFERROR(AVERAGEIFS(Weekly_Inspections!$AJ$4:$AJ$996,Weekly_Inspections!$F$4:$F$996,$A16,Weekly_Inspections!$D$4:$D$996,$B$6),"")) | H16: =IF($B$6="","",IFERROR(AVERAGEIFS(Weekly_Inspections!$AK$4:$AK$996,Weekly_Inspections!$F$4:$F$996,$A16,Weekly_Inspections!$D$4:$D$996,$B$6),"")) | I16: =IF($B$6="","",COUNTIFS(Weekly_Inspections!$F$4:$F$996,$A16,Weekly_Inspections!$D$4:$D$996,$B$6,Weekly_Inspections!$AL$4:$AL$996,"YES")) -> 0 | J16: =IF(OR($B$6="",$B$7=""),"",IFERROR((G16-AVERAGEIFS(Weekly_Inspections!$AJ$4:$AJ$996,Weekly_Inspections!$F$4:$F$996,$A16,Weekly_Inspections!$D$4:$D$996,$B$7))/AVERAGEIFS(Weekly_Inspections!$AJ$4:$AJ$996,Weekly_Inspections!$F$4:$F$996,$A16,Weekly_Inspections!$D$4:$D$996,$B$7),"")) | K16: =IF(G16="","",IF(AND(I16=0,G16>=0.75),"YES","NO")) | L16: =IF(G16="","",RANK(G16,$G$10:$G$24,0))
A17: Cluster 4 | B17: =IFERROR(INDEX(Cluster_Master!$A$4:$A$18,MATCH($A17,Cluster_Master!$B$4:$B$18,0)),"") -> 3 | C17: =IFERROR(INDEX(Cluster_Master!$C$4:$C$18,MATCH($A17,Cluster_Master!$B$4:$B$18,0)),"") -> INNOVO | D17: =IF($B$5="","",IFERROR(AVERAGEIFS(Weekly_Inspections!$AJ$4:$AJ$996,Weekly_Inspections!$F$4:$F$996,$A17,Weekly_Inspections!$C$4:$C$996,$B$5),"")) -> 0.54666667 | E17: =IF($B$5="","",IFERROR(AVERAGEIFS(Weekly_Inspections!$AK$4:$AK$996,Weekly_Inspections!$F$4:$F$996,$A17,Weekly_Inspections!$C$4:$C$996,$B$5),"")) -> 0.52 | F17: =IF($B$5="","",COUNTIFS(Weekly_Inspections!$F$4:$F$996,$A17,Weekly_Inspections!$C$4:$C$996,$B$5,Weekly_Inspections!$AL$4:$AL$996,"YES")) -> 1 | G17: =IF($B$6="","",IFERROR(AVERAGEIFS(Weekly_Inspections!$AJ$4:$AJ$996,Weekly_Inspections!$F$4:$F$996,$A17,Weekly_Inspections!$D$4:$D$996,$B$6),"")) -> 0.54666667 | H17: =IF($B$6="","",IFERROR(AVERAGEIFS(Weekly_Inspections!$AK$4:$AK$996,Weekly_Inspections!$F$4:$F$996,$A17,Weekly_Inspections!$D$4:$D$996,$B$6),"")) -> 0.52 | I17: =IF($B$6="","",COUNTIFS(Weekly_Inspections!$F$4:$F$996,$A17,Weekly_Inspections!$D$4:$D$996,$B$6,Weekly_Inspections!$AL$4:$AL$996,"YES")) -> 1 | J17: =IF(OR($B$6="",$B$7=""),"",IFERROR((G17-AVERAGEIFS(Weekly_Inspections!$AJ$4:$AJ$996,Weekly_Inspections!$F$4:$F$996,$A17,Weekly_Inspections!$D$4:$D$996,$B$7))/AVERAGEIFS(Weekly_Inspections!$AJ$4:$AJ$996,Weekly_Inspections!$F$4:$F$996,$A17,Weekly_Inspections!$D$4:$D$996,$B$7),"")) | K17: =IF(G17="","",IF(AND(I17=0,G17>=0.75),"YES","NO")) -> NO | L17: =IF(G17="","",RANK(G17,$G$10:$G$24,0)) -> 2
A18: Cluster 5 | B18: =IFERROR(INDEX(Cluster_Master!$A$4:$A$18,MATCH($A18,Cluster_Master!$B$4:$B$18,0)),"") -> 3 | C18: =IFERROR(INDEX(Cluster_Master!$C$4:$C$18,MATCH($A18,Cluster_Master!$B$4:$B$18,0)),"") -> INNOVO | D18: =IF($B$5="","",IFERROR(AVERAGEIFS(Weekly_Inspections!$AJ$4:$AJ$996,Weekly_Inspections!$F$4:$F$996,$A18,Weekly_Inspections!$C$4:$C$996,$B$5),"")) | E18: =IF($B$5="","",IFERROR(AVERAGEIFS(Weekly_Inspections!$AK$4:$AK$996,Weekly_Inspections!$F$4:$F$996,$A18,Weekly_Inspections!$C$4:$C$996,$B$5),"")) | F18: =IF($B$5="","",COUNTIFS(Weekly_Inspections!$F$4:$F$996,$A18,Weekly_Inspections!$C$4:$C$996,$B$5,Weekly_Inspections!$AL$4:$AL$996,"YES")) -> 0 | G18: =IF($B$6="","",IFERROR(AVERAGEIFS(Weekly_Inspections!$AJ$4:$AJ$996,Weekly_Inspections!$F$4:$F$996,$A18,Weekly_Inspections!$D$4:$D$996,$B$6),"")) | H18: =IF($B$6="","",IFERROR(AVERAGEIFS(Weekly_Inspections!$AK$4:$AK$996,Weekly_Inspections!$F$4:$F$996,$A18,Weekly_Inspections!$D$4:$D$996,$B$6),"")) | I18: =IF($B$6="","",COUNTIFS(Weekly_Inspections!$F$4:$F$996,$A18,Weekly_Inspections!$D$4:$D$996,$B$6,Weekly_Inspections!$AL$4:$AL$996,"YES")) -> 0 | J18: =IF(OR($B$6="",$B$7=""),"",IFERROR((G18-AVERAGEIFS(Weekly_Inspections!$AJ$4:$AJ$996,Weekly_Inspections!$F$4:$F$996,$A18,Weekly_Inspections!$D$4:$D$996,$B$7))/AVERAGEIFS(Weekly_Inspections!$AJ$4:$AJ$996,Weekly_Inspections!$F$4:$F$996,$A18,Weekly_Inspections!$D$4:$D$996,$B$7),"")) | K18: =IF(G18="","",IF(AND(I18=0,G18>=0.75),"YES","NO")) | L18: =IF(G18="","",RANK(G18,$G$10:$G$24,0))
