Workbook
Name Package_List: 'Lookups'!$A$3:$A$5
Name Cluster_List: 'Lookups'!$B$3:$B$17
Name Evaluator_Role_List: 'Lookups'!$C$3:$C$11
Name High_Risk_Activity_List: 'Lookups'!$D$3:$D$18
Name Yes_No_List: 'Lookups'!$E$3:$E$4
Name Root_Cause_List: 'Lookups'!$F$3:$F$13
Name Status_List: 'Lookups'!$G$3:$G$6
Name KPI_List: 'Lookups'!$H$3:$H$17
Name Score_List: 'Lookups'!$I$3:$I$8

Sheet Instructions
A1: Saadiyat Lagoons HSE Scoring Template - Full System Updated
A2: This workbook is structured as a live HSE weekly KPI, dashboard, gap analysis, and CAPA control file. Complete only blue-font input cells or unlocked input fields.
A3: Complete the visible input columns only. Hidden columns calculate automatically.
A4: Score each KPI from 0 to 5. 0 = collapse of control, 5 = excellent sustained control.
A5: Package and Cluster are mandatory. Contractor and responsible team auto-populate.
A6: Weekly_Dashboard is for top management review. Monthly_Dashboard tracks recognition trend.
A7: Gap_Analysis and CAPA_Tracker are for close-out management.
A9: Weekly operating method
A10: 1. Enter one line per completed site walk in Weekly_Inspections.
A11: 2. Select Package, Cluster, role, high risk activity, and KPI-for-attention fields from dropdown lists only.
A12: 3. Score every KPI from 0 to 5. Critical red flag logic reads the gate KPI list directly from KPI_Weights.
A13: 4. Use Weekly_Dashboard for current week review, Monthly_Dashboard for recognition/improvement review, Gap_Analysis for weak KPI focus, and CAPA_Tracker for closeout status.
... A21: 5. Cluster master, lookup lists, and KPI weights can be revised centrally when formally approved.

Sheet Cluster_Master
A1: Cluster Master Register
A2: Package | B2: Cluster | C2: Contractor | D2: Project Director (PD) | E2: Project Manager (PM) | F2: Construction Manager (CM) | G2: HSE Manager (HSEM) | H2: Section Engineer (SE) | I2: Key
A3: 2 | B3: Cluster 7A | C3: TAJV | D3: Hicham Adel Narch | E3: Ghaidh Alfaour | F3: George Deeb | G3: Timur Terakopov | H3: Liqat | I3: 2|Cluster 7A
A4: 2 | B4: Cluster 7B | C4: TAJV | D4: Hicham Adel Narch | E4: Ghaidh Alfaour | F4: George Deeb | G4: Timur Terakopov | H4: Eyad | I4: 2|Cluster 7B
A5: 2 | B5: Cluster 8A | C5: TAJV | D5: Hicham Adel Narch | E5: Ghaidh Alfaour | F5: Mohamed Salama | G5: Timur Terakopov | H5: Ahmad Adel | I5: 2|Cluster 8A
A6: 2 | B6: Cluster 8B | C6: TAJV | D6: Hicham Adel Narch | E6: Ghaidh Alfaour | F6: Mohamed Salama | G6: Timur Terakopov | H6: Ahmad Adel | I6: 2|Cluster 8B
A7: 2 | B7: Cluster 8C | C7: TAJV | D7: Hicham Adel Narch | E7: Ghaidh Alfaour | F7: George Deeb | G7: Timur Terakopov | H7: Ahmad Adel | I7: 2|Cluster 8C
A8: 2 | B8: Cluster 8D | C8: TAJV | D8: Hicham Adel Narch | E8: Ghaidh Alfaour | F8: George Deeb | G8: Timur Terakopov | H8: Ahmad Adel | I8: 2|Cluster 8D
A9: 3 | B9: Cluster 3 | C9: INNOVO | D9: Kahtan Tikriti | E9: Aiman Abdullah | F9: Salama Al Samdy | G9: Mazen Al Atwani | H9: TBD - Update Section Engineer | I9: 3|Cluster 3
A10: 3 | B10: Cluster 4 | C10: INNOVO | D10: Kahtan Tikriti | E10: Aiman Abdullah | F10: Baha Basheer | G10: Mazen Al Atwani | H10: TBD - Update Section Engineer | I10: 3|Cluster 4
A11: 3 | B11: Cluster 5 | C11: INNOVO | D11: Kahtan Tikriti | E11: Michael Ghali | F11: Robair Louies | G11: Mazen Al Atwani | H11: TBD - Update Section Engineer | I11: 3|Cluster 5
A12: 3 | B12: Cluster 6 | C12: INNOVO | D12: Kahtan Tikriti | E12: Michael Ghali | F12: Remon Karas | G12: Mazen Al Atwani | H12: TBD - Update Section Engineer | I12: 3|Cluster 6
A13: 4 | B13: Cluster 1A | C13: TAJV | D13: Hicham Adel Narch | E13: Ghaidh Alfaour | F13: Alaa Hegab | G13: Timur Terakopov | H13: Amr Taha | I13: 4|Cluster 1A
A14: 4 | B14: Cluster 1B | C14: TAJV | D14: Hicham Adel Narch | E14: Ghaidh Alfaour | F14: Hossam Ali Maher | G14: Timur Terakopov | H14: Md Ramadan / Osama Said | I14: 4|Cluster 1B
... A17: 4 | B17: Cluster 2C | C17: TAJV | D17: Hicham Adel Narch | E17: Ghaidh Alfaour | F17: Ahmed Salah Hassan Dewidar | G17: Timur Terakopov | H17: Salah Nayef | I17: 4|Cluster 2C

Sheet Lookups
A1: Lookup Lists
A2: Package_List | B2: Cluster_List | C2: Evaluator_Role_List | D2: High_Risk_Activity_List | E2: Yes_No_List | F2: Root_Cause_List | G2: Status_List | H2: KPI_List | I2: Score_List
A3: 2 | B3: Cluster 7A | C3: Project Director | D3: Work at Height | E3: YES | F3: Leadership failure | G3: Open | H3: Work at Height Control | I3: 0
A4: 3 | B4: Cluster 7B | C4: Project Manager | D4: Edge Protection | E4: NO | F4: Poor supervision | G4: In Progress | H4: Edge Protection | I4: 1
A5: 4 | B5: Cluster 8A | C5: Construction Manager | D5: Falling Objects | F5: Poor planning | G5: Closed | H5: Falling Object Prevention | I5: 2
B6: Cluster 8B | C6: HSE Manager | D6: Excavation | F6: PTW failure | G6: On Hold | H6: Excavation Safety | I6: 3
B7: Cluster 8C | C7: Section Engineer | D7: Scaffolding | F7: Weak MSRA | H7: Scaffolding Compliance | I7: 4
B8: Cluster 8D | C8: QA/QC | D8: Permit to Work | F8: Poor subcontractor control | H8: PTW Implementation | I8: 5
B9: Cluster 3 | C9: KEO | D9: MSRA / Risk Assessment | F9: Resource constraint | H9: PTW Field Verification
B10: Cluster 4 | C10: Client | D10: Lifting Operations | F10: Inadequate competence | H10: MSRA Quality
B11: Cluster 5 | C11: Other | D11: Traffic Management | F11: Poor housekeeping culture | H11: Lifting/Precast Installation
B12: Cluster 6 | D12: Housekeeping | F12: Interface / simultaneous activity conflict | H12: Traffic & Man-Machine Interface
B13: Cluster 1A | D13: Waste Management | F13: Other | H13: Housekeeping/Waste Management
B14: Cluster 1B | D14: Fire Readiness | H14: Welfare Arrangement
B15: Cluster 2A | D15: Electrical Safety | H15: Fire Readiness
B16: Cluster 2B | D16: Portable Power Tools | H16: Supervision & Subcontractor Control
B17: Cluster 2C | D17: Heat Stress | H17: Temporary Electrical & Tool Safety
D18: Other

Sheet KPI_Weights
A1: KPI Weights and Gate Rules
A2: KPI | B2: Weight | C2: Critical Gate KPI? | D2: Notes
A3: Work at Height Control | B3: 0.12 | C3: YES | D3: Primary fall prevention and work at height control
A4: Edge Protection | B4: 0.12 | C4: NO | D4: Continuity and quality of edge protection
A5: Falling Object Prevention | B5: 0.05 | C5: NO | D5: Exclusion zones, toe boards, debris/tool control
A6: Excavation Safety | B6: 0.08 | C6: YES | D6: Barricading, access, services, support, spoil setback
A7: Scaffolding Compliance | B7: 0.1 | C7: YES | D7: Tagging, inspection, full planking, access, stability
A8: PTW Implementation | B8: 0.08 | C8: YES | D8: Valid PTW, correct scope, signatories, controls
A9: PTW Field Verification | B9: 0.06 | C9: NO | D9: Physical field verification before permit approval
A10: MSRA Quality | B10: 0.03 | C10: NO | D10: Task-specific risk assessment and understanding
A11: Lifting/Precast Installation | B11: 0.1 | C11: YES | D11: Lift plan, appointed person, exclusion, rigging
A12: Traffic & Man-Machine Interface | B12: 0.06 | C12: NO | D12: Pedestrian segregation, routes, signage, reversing
A13: Housekeeping/Waste Management | B13: 0.03 | C13: NO | D13: Cleanliness, stacking, access routes, slip/trip control
A14: Welfare Arrangement | B14: 0.03 | C14: NO | D14: Segregation, storage, transfer/disposal control
... A17: Temporary Electrical & Tool Safety | B17: 0.06 | C17: NO | D17: Temporary power, RCD, condition of tools/cables

Sheet Weekly_Inspections
A1: Weekly Inspection Entry Sheet - Full System
A2: Complete only blue-font input cells. Package and Cluster auto-fill leadership, scoring, dashboard, and CAPA logic.
A3: Inspection_ID | B3: Inspection_Date | C3: Week_No | D3: Month | E3: Package | F3: Cluster | G3: Package_Cluster_Check | H3: Contractor | I3: Project Director (PD) | J3: Project Manager (PM) | K3: Construction Manager (CM) | L3: HSE Manager (HSEM) | M3: Section Engineer (SE) | N3: Your_Name | O3: Your_Role | P3: Area_or_Villa | Q3: Workers_Observed | R3: Main_High_Risk_Activity | S3: Stop_Work | T3: Work_at_Height | U3: Edge_Protection | V3: Falling_Object_Prevention | W3: Excavation_Safety | X3: Scaffolding_Compliance | Y3: PTW_Implementation | Z3: PTW_Field_Verification | AA3: MSRA_Quality | AB3: Lifting/Precast Installation | AC3: Traffic_Interface | AD3: Housekeeping/Waste Management | AE3: Welfare Arrangement | AF3: Fire_Readiness | AG3: Supervision_Subcontractor | AH3: Electrical_Tool_Safety | AI3: Total_Score | AJ3: Raw_Score_% | AK3: Weighted_Score_% | AL3: Critical_Red_Flag | AM3: Award_Eligible | AN3: Rating_Band | AO3: Repeat_Issue_Seen | AP3: Likely_Root_Cause | AQ3: Top_3_Gaps_Observed | AR3: Immediate_Action_Taken | AS3: Preventive_Action_Required | AT3: Positive_Observations | AU3: Action_Owner | AV3: Target_Closeout_Date | AW3: Evidence_Link_or_Photo | AX3: KPI_for_PD_Attention | AY3: KPI_for_PM_Attention | AZ3: KPI_for_CM_Attention | BA3: KPI_for_HSEM_Followup | BB3: KPI_for_SE_Supervision | BC3: Leadership_Visible_Effective | BD3: Unsafe_Work_Corrected_Immediately | BE3: Best_Improved_Cluster_this_Week | BF3: Cluster_Needing_Immediate_Intervention
A4: =IF(B4="","","INS-"&TEXT(ROW()-3,"000")) | B4: 46107 | C4: =IF(B4="","",ISOWEEKNUM(B4)) | D4: =IF(B4="","",TEXT(B4,"yyyy-mm")) | E4: 4 | F4: Cluster 2A | G4: =IF(OR(E4="",F4=""),"",IF(COUNTIF(Cluster_Master!$I$3:$I$17,E4&"|"&F4)=1,"Valid","Review")) | H4: =IF($G4<>"Valid","",VLOOKUP($E4&"|"&$F4,Cluster_Master!$I$3:$H$17,3,FALSE)) | I4: =IF($G4<>"Valid","",VLOOKUP($E4&"|"&$F4,Cluster_Master!$I$3:$H$17,4,FALSE)) | J4: =IF($G4<>"Valid","",VLOOKUP($E4&"|"&$F4,Cluster_Master!$I$3:$H$17,5,FALSE)) | K4: =IF($G4<>"Valid","",VLOOKUP($E4&"|"&$F4,Cluster_Master!$I$3:$H$17,6,FALSE)) | L4: =IF($G4<>"Valid","",VLOOKUP($E4&"|"&$F4,Cluster_Master!$I$3:$H$17,7,FALSE)) | M4: =IF($G4<>"Valid","",VLOOKUP($E4&"|"&$F4,Cluster_Master!$I$3:$H$17,8,FALSE)) | N4: Godwin | O4: KEO | P4: Villa 8 to 16 | R4: Work at Height | S4: YES | T4: 2 | U4: 2 | V4: 3 | W4: 3 | X4: 2 | Y4: 3 | Z4: 1 | AA4: 3 | AC4: 3 | AD4: 1 | AE4: 1 | AF4: 2 | AG4: 1 | AH4: 2 | AI4: =IF(COUNT(T4:AH4)=0,"",SUM(T4:AH4)) | AJ4: =IF(AI4="","",AI4/75) | AK4: =IF(AI4="","",SUMPRODUCT(T4:AH4,KPI_Weights!$B$3:$B$17)/5) | AL4: =IF(COUNT(T4:AH4)=0,"",IF(OR(T4<=1,W4<=1,X4<=1,Y4<=1,AB4<=1),"YES","NO")) | AM4: =IF(AK4="","",IF(AND(AK4="NO",AJ4>=0.85),"YES","NO")) | AN4: =IF(AJ4="","",IF(AJ4>=0.90,"Excellent",IF(AJ4>=0.80,"Good",IF(AJ4>=0.70,"Fair","Poor")))) | AO4: YES | AP4: Leadership failure | AQ4: 1. Leadership failure 2. Poor supervision 3. Poor sub-contractor control 4. PTW failure | AR4: Unsafe work practices were suspended immediately. The CM of the cluster was called but he refused to visit the location. | AS4: 1. PTW must be controlled by the main contractor. 2. Close supervision of sub-contractors by main contractor shall be ensured. 3. Non-performing subcontractors shall not be paid and shall be removed from project. 4. Non-performing construction team shall be replaced without delays | AU4: 1-3rd recommendation by the cluster CM 4th recommendation by the PD. | AV4: 46114
A5: =IF(B5="","","INS-"&TEXT(ROW()-3,"000")) | B5: 46107 | C5: =IF(B5="","",ISOWEEKNUM(B5)) | D5: =IF(B5="","",TEXT(B5,"yyyy-mm")) | E5: 2 | F5: Cluster 8A | G5: =IF(OR(E5="",F5=""),"",IF(COUNTIF(Cluster_Master!$I$3:$I$17,E5&"|"&F5)=1,"Valid","Review")) | H5: =IF($G5<>"Valid","",VLOOKUP($E5&"|"&$F5,Cluster_Master!$I$3:$H$17,3,FALSE)) | I5: =IF($G5<>"Valid","",VLOOKUP($E5&"|"&$F5,Cluster_Master!$I$3:$H$17,4,FALSE)) | J5: =IF($G5<>"Valid","",VLOOKUP($E5&"|"&$F5,Cluster_Master!$I$3:$H$17,5,FALSE)) | K5: =IF($G5<>"Valid","",VLOOKUP($E5&"|"&$F5,Cluster_Master!$I$3:$H$17,6,FALSE)) | L5: =IF($G5<>"Valid","",VLOOKUP($E5&"|"&$F5,Cluster_Master!$I$3:$H$17,7,FALSE)) | M5: =IF($G5<>"Valid","",VLOOKUP($E5&"|"&$F5,Cluster_Master!$I$3:$H$17,8,FALSE)) | N5: Godwin | O5: KEO | P5: General | R5: Scaffolding | S5: NO | T5: 4 | U5: 4 | V5: 4 | W5: 4 | X5: 4 | Y5: 4 | Z5: 4 | AA5: 4 | AB5: 4 | AC5: 4 | AD5: 4 | AE5: 3 | AF5: 4 | AG5: 4 | AH5: 4 | AI5: =IF(COUNT(T5:AH5)=0,"",SUM(T5:AH5)) | AJ5: =IF(AI5="","",AI5/75) | AK5: =IF(AI5="","",SUMPRODUCT(T5:AH5,KPI_Weights!$B$3:$B$17)/5) | AL5: =IF(COUNT(T5:AH5)=0,"",IF(OR(T5<=1,W5<=1,X5<=1,Y5<=1,AB5<=1),"YES","NO")) | AM5: =IF(AK5="","",IF(AND(AK5="NO",AJ5>=0.85),"YES","NO")) | AN5: =IF(AJ5="","",IF(AJ5>=0.90,"Excellent",IF(AJ5>=0.80,"Good",IF(AJ5>=0.70,"Fair","Poor")))) | AO5: NO | AP5: Other | AQ5: No significant gap observed | AR5: The team was commended for their visible leadership in driving transformation at Cluster 8A. | AS5: The Construction Manager and his team were advised to ensure that sub-contractors do not mess up with their site. 1. No payment for work if site condition is below the acceptable standard. 2. Close supervision of sub-contractors by the construction team of the main contractor. 3. Housekeeping shall be maintained for all shift. 4. Provide a temporary storage area for waste for each villa. 5. PTW shall remain under the control of the main contractor. | AU5: Construction Manager of Cluster 8A HSE Manager of TAJV | AV5: Always
A6: =IF(B6="","","INS-"&TEXT(ROW()-3,"000")) | B6: 46111 | C6: =IF(B6="","",ISOWEEKNUM(B6)) | D6: =IF(B6="","",TEXT(B6,"yyyy-mm")) | E6: 3 | F6: Cluster 4 | G6: =IF(OR(E6="",F6=""),"",IF(COUNTIF(Cluster_Master!$I$3:$I$17,E6&"|"&F6)=1,"Valid","Review")) | H6: =IF($G6<>"Valid","",VLOOKUP($E6&"|"&$F6,Cluster_Master!$I$3:$H$17,3,FALSE)) | I6: =IF($G6<>"Valid","",VLOOKUP($E6&"|"&$F6,Cluster_Master!$I$3:$H$17,4,FALSE)) | J6: =IF($G6<>"Valid","",VLOOKUP($E6&"|"&$F6,Cluster_Master!$I$3:$H$17,5,FALSE)) | K6: =IF($G6<>"Valid","",VLOOKUP($E6&"|"&$F6,Cluster_Master!$I$3:$H$17,6,FALSE)) | L6: =IF($G6<>"Valid","",VLOOKUP($E6&"|"&$F6,Cluster_Master!$I$3:$H$17,7,FALSE)) | M6: =IF($G6<>"Valid","",VLOOKUP($E6&"|"&$F6,Cluster_Master!$I$3:$H$17,8,FALSE)) | N6: Shinoj | O6: KEO | P6: Villa 8 to 16 | Q6: Block work | R6: Edge Protection | S6: NO | T6: 3 | U6: 2 | V6: 3 | W6: 3 | X6: 2 | Y6: 4 | Z6: 3 | AA6: 5 | AB6: 1 | AC6: 2 | AD6: 4 | AE6: 2 | AF6: 3 | AG6: 1 | AH6: 3 | AI6: =IF(COUNT(T6:AH6)=0,"",SUM(T6:AH6)) | AJ6: =IF(AI6="","",AI6/75) | AK6: =IF(AI6="","",SUMPRODUCT(T6:AH6,KPI_Weights!$B$3:$B$17)/5) | AL6: =IF(COUNT(T6:AH6)=0,"",IF(OR(T6<=1,W6<=1,X6<=1,Y6<=1,AB6<=1),"YES","NO")) | AM6: =IF(AK6="","",IF(AND(AK6="NO",AJ6>=0.85),"YES","NO")) | AN6: =IF(AJ6="","",IF(AJ6>=0.90,"Excellent",IF(AJ6>=0.80,"Good",IF(AJ6>=0.70,"Fair","Poor")))) | AO6: NO | AP6: Poor supervision | AR6: Safety concern identified during site walk. | AS6: Improve supervision and close the edge protection gaps before continuation. | AV6: 46112
A7: =IF(B7="","","INS-"&TEXT(ROW()-3,"000")) | C7: =IF(B7="","",ISOWEEKNUM(B7)) | D7: =IF(B7="","",TEXT(B7,"yyyy-mm")) | G7: =IF(OR(E7="",F7=""),"",IF(COUNTIF(Cluster_Master!$I$3:$I$17,E7&"|"&F7)=1,"Valid","Review")) | H7: =IF($G7<>"Valid","",VLOOKUP($E7&"|"&$F7,Cluster_Master!$I$3:$H$17,3,FALSE)) | I7: =IF($G7<>"Valid","",VLOOKUP($E7&"|"&$F7,Cluster_Master!$I$3:$H$17,4,FALSE)) | J7: =IF($G7<>"Valid","",VLOOKUP($E7&"|"&$F7,Cluster_Master!$I$3:$H$17,5,FALSE)) | K7: =IF($G7<>"Valid","",VLOOKUP($E7&"|"&$F7,Cluster_Master!$I$3:$H$17,6,FALSE)) | L7: =IF($G7<>"Valid","",VLOOKUP($E7&"|"&$F7,Cluster_Master!$I$3:$H$17,7,FALSE)) | M7: =IF($G7<>"Valid","",VLOOKUP($E7&"|"&$F7,Cluster_Master!$I$3:$H$17,8,FALSE)) | AI7: =IF(COUNT(T7:AH7)=0,"",SUM(T7:AH7)) | AJ7: =IF(AI7="","",AI7/75) | AK7: =IF(AI7="","",SUMPRODUCT(T7:AH7,KPI_Weights!$B$3:$B$17)/5) | AL7: =IF(COUNT(T7:AH7)=0,"",IF(OR(T7<=1,W7<=1,X7<=1,Y7<=1,AB7<=1),"YES","NO")) | AM7: =IF(AK7="","",IF(AND(AK7="NO",AJ7>=0.85),"YES","NO")) | AN7: =IF(AJ7="","",IF(AJ7>=0.90,"Excellent",IF(AJ7>=0.80,"Good",IF(AJ7>=0.70,"Fair","Poor"))))
A8: =IF(B8="","","INS-"&TEXT(ROW()-3,"000")) | C8: =IF(B8="","",ISOWEEKNUM(B8)) | D8: =IF(B8="","",TEXT(B8,"yyyy-mm")) | G8: =IF(OR(E8="",F8=""),"",IF(COUNTIF(Cluster_Master!$I$3:$I$17,E8&"|"&F8)=1,"Valid","Review")) | H8: =IF($G8<>"Valid","",VLOOKUP($E8&"|"&$F8,Cluster_Master!$I$3:$H$17,3,FALSE)) | I8: =IF($G8<>"Valid","",VLOOKUP($E8&"|"&$F8,Cluster_Master!$I$3:$H$17,4,FALSE)) | J8: =IF($G8<>"Valid","",VLOOKUP($E8&"|"&$F8,Cluster_Master!$I$3:$H$17,5,FALSE)) | K8: =IF($G8<>"Valid","",VLOOKUP($E8&"|"&$F8,Cluster_Master!$I$3:$H$17,6,FALSE)) | L8: =IF($G8<>"Valid","",VLOOKUP($E8&"|"&$F8,Cluster_Master!$I$3:$H$17,7,FALSE)) | M8: =IF($G8<>"Valid","",VLOOKUP($E8&"|"&$F8,Cluster_Master!$I$3:$H$17,8,FALSE)) | AI8: =IF(COUNT(T8:AH8)=0,"",SUM(T8:AH8)) | AJ8: =IF(AI8="","",AI8/75) | AK8: =IF(AI8="","",SUMPRODUCT(T8:AH8,KPI_Weights!$B$3:$B$17)/5) | AL8: =IF(COUNT(T8:AH8)=0,"",IF(OR(T8<=1,W8<=1,X8<=1,Y8<=1,AB8<=1),"YES","NO")) | AM8: =IF(AK8="","",IF(AND(AK8="NO",AJ8>=0.85),"YES","NO")) | AN8: =IF(AJ8="","",IF(AJ8>=0.90,"Excellent",IF(AJ8>=0.80,"Good",IF(AJ8>=0.70,"Fair","Poor"))))
A9: =IF(B9="","","INS-"&TEXT(ROW()-3,"000")) | C9: =IF(B9="","",ISOWEEKNUM(B9)) | D9: =IF(B9="","",TEXT(B9,"yyyy-mm")) | G9: =IF(OR(E9="",F9=""),"",IF(COUNTIF(Cluster_Master!$I$3:$I$17,E9&"|"&F9)=1,"Valid","Review")) | H9: =IF($G9<>"Valid","",VLOOKUP($E9&"|"&$F9,Cluster_Master!$I$3:$H$17,3,FALSE)) | I9: =IF($G9<>"Valid","",VLOOKUP($E9&"|"&$F9,Cluster_Master!$I$3:$H$17,4,FALSE)) | J9: =IF($G9<>"Valid","",VLOOKUP($E9&"|"&$F9,Cluster_Master!$I$3:$H$17,5,FALSE)) | K9: =IF($G9<>"Valid","",VLOOKUP($E9&"|"&$F9,Cluster_Master!$I$3:$H$17,6,FALSE)) | L9: =IF($G9<>"Valid","",VLOOKUP($E9&"|"&$F9,Cluster_Master!$I$3:$H$17,7,FALSE)) | M9: =IF($G9<>"Valid","",VLOOKUP($E9&"|"&$F9,Cluster_Master!$I$3:$H$17,8,FALSE)) | AI9: =IF(COUNT(T9:AH9)=0,"",SUM(T9:AH9)) | AJ9: =IF(AI9="","",AI9/75) | AK9: =IF(AI9="","",SUMPRODUCT(T9:AH9,KPI_Weights!$B$3:$B$17)/5) | AL9: =IF(COUNT(T9:AH9)=0,"",IF(OR(T9<=1,W9<=1,X9<=1,Y9<=1,AB9<=1),"YES","NO")) | AM9: =IF(AK9="","",IF(AND(AK9="NO",AJ9>=0.85),"YES","NO")) | AN9: =IF(AJ9="","",IF(AJ9>=0.90,"Excellent",IF(AJ9>=0.80,"Good",IF(AJ9>=0.70,"Fair","Poor"))))
A10: =IF(B10="","","INS-"&TEXT(ROW()-3,"000")) | C10: =IF(B10="","",ISOWEEKNUM(B10)) | D10: =IF(B10="","",TEXT(B10,"yyyy-mm")) | G10: =IF(OR(E10="",F10=""),"",IF(COUNTIF(Cluster_Master!$I$3:$I$17,E10&"|"&F10)=1,"Valid","Review")) | H10: =IF($G10<>"Valid","",VLOOKUP($E10&"|"&$F10,Cluster_Master!$I$3:$H$17,3,FALSE)) | I10: =IF($G10<>"Valid","",VLOOKUP($E10&"|"&$F10,Cluster_Master!$I$3:$H$17,4,FALSE)) | J10: =IF($G10<>"Valid","",VLOOKUP($E10&"|"&$F10,Cluster_Master!$I$3:$H$17,5,FALSE)) | K10: =IF($G10<>"Valid","",VLOOKUP($E10&"|"&$F10,Cluster_Master!$I$3:$H$17,6,FALSE)) | L10: =IF($G10<>"Valid","",VLOOKUP($E10&"|"&$F10,Cluster_Master!$I$3:$H$17,7,FALSE)) | M10: =IF($G10<>"Valid","",VLOOKUP($E10&"|"&$F10,Cluster_Master!$I$3:$H$17,8,FALSE)) | AI10: =IF(COUNT(T10:AH10)=0,"",SUM(T10:AH10)) | AJ10: =IF(AI10="","",AI10/75) | AK10: =IF(AI10="","",SUMPRODUCT(T10:AH10,KPI_Weights!$B$3:$B$17)/5) | AL10: =IF(COUNT(T10:AH10)=0,"",IF(OR(T10<=1,W10<=1,X10<=1,Y10<=1,AB10<=1),"YES","NO")) | AM10: =IF(AK10="","",IF(AND(AK10="NO",AJ10>=0.85),"YES","NO")) | AN10: =IF(AJ10="","",IF(AJ10>=0.90,"Excellent",IF(AJ10>=0.80,"Good",IF(AJ10>=0.70,"Fair","Poor"))))
A11: =IF(B11="","","INS-"&TEXT(ROW()-3,"000")) | C11: =IF(B11="","",ISOWEEKNUM(B11)) | D11: =IF(B11="","",TEXT(B11,"yyyy-mm")) | G11: =IF(OR(E11="",F11=""),"",IF(COUNTIF(Cluster_Master!$I$3:$I$17,E11&"|"&F11)=1,"Valid","Review")) | H11: =IF($G11<>"Valid","",VLOOKUP($E11&"|"&$F11,Cluster_Master!$I$3:$H$17,3,FALSE)) | I11: =IF($G11<>"Valid","",VLOOKUP($E11&"|"&$F11,Cluster_Master!$I$3:$H$17,4,FALSE)) | J11: =IF($G11<>"Valid","",VLOOKUP($E11&"|"&$F11,Cluster_Master!$I$3:$H$17,5,FALSE)) | K11: =IF($G11<>"Valid","",VLOOKUP($E11&"|"&$F11,Cluster_Master!$I$3:$H$17,6,FALSE)) | L11: =IF($G11<>"Valid","",VLOOKUP($E11&"|"&$F11,Cluster_Master!$I$3:$H$17,7,FALSE)) | M11: =IF($G11<>"Valid","",VLOOKUP($E11&"|"&$F11,Cluster_Master!$I$3:$H$17,8,FALSE)) | AI11: =IF(COUNT(T11:AH11)=0,"",SUM(T11:AH11)) | AJ11: =IF(AI11="","",AI11/75) | AK11: =IF(AI11="","",SUMPRODUCT(T11:AH11,KPI_Weights!$B$3:$B$17)/5) | AL11: =IF(COUNT(T11:AH11)=0,"",IF(OR(T11<=1,W11<=1,X11<=1,Y11<=1,AB11<=1),"YES","NO")) | AM11: =IF(AK11="","",IF(AND(AK11="NO",AJ11>=0.85),"YES","NO")) | AN11: =IF(AJ11="","",IF(AJ11>=0.90,"Excellent",IF(AJ11>=0.80,"Good",IF(AJ11>=0.70,"Fair","Poor"))))
A12: =IF(B12="","","INS-"&TEXT(ROW()-3,"000")) | C12: =IF(B12="","",ISOWEEKNUM(B12)) | D12: =IF(B12="","",TEXT(B12,"yyyy-mm")) | G12: =IF(OR(E12="",F12=""),"",IF(COUNTIF(Cluster_Master!$I$3:$I$17,E12&"|"&F12)=1,"Valid","Review")) | H12: =IF($G12<>"Valid","",VLOOKUP($E12&"|"&$F12,Cluster_Master!$I$3:$H$17,3,FALSE)) | I12: =IF($G12<>"Valid","",VLOOKUP($E12&"|"&$F12,Cluster_Master!$I$3:$H$17,4,FALSE)) | J12: =IF($G12<>"Valid","",VLOOKUP($E12&"|"&$F12,Cluster_Master!$I$3:$H$17,5,FALSE)) | K12: =IF($G12<>"Valid","",VLOOKUP($E12&"|"&$F12,Cluster_Master!$I$3:$H$17,6,FALSE)) | L12: =IF($G12<>"Valid","",VLOOKUP($E12&"|"&$F12,Cluster_Master!$I$3:$H$17,7,FALSE)) | M12: =IF($G12<>"Valid","",VLOOKUP($E12&"|"&$F12,Cluster_Master!$I$3:$H$17,8,FALSE)) | AI12: =IF(COUNT(T12:AH12)=0,"",SUM(T12:AH12)) | AJ12: =IF(AI12="","",AI12/75) | AK12: =IF(AI12="","",SUMPRODUCT(T12:AH12,KPI_Weights!$B$3:$B$17)/5) | AL12: =IF(COUNT(T12:AH12)=0,"",IF(OR(T12<=1,W12<=1,X12<=1,Y12<=1,AB12<=1),"YES","NO")) | AM12: =IF(AK12="","",IF(AND(AK12="NO",AJ12>=0.85),"YES","NO")) | AN12: =IF(AJ12="","",IF(AJ12>=0.90,"Excellent",IF(AJ12>=0.80,"Good",IF(AJ12>=0.70,"Fair","Poor"))))
A13: =IF(B13="","","INS-"&TEXT(ROW()-3,"000")) | C13: =IF(B13="","",ISOWEEKNUM(B13)) | D13: =IF(B13="","",TEXT(B13,"yyyy-mm")) | G13: =IF(OR(E13="",F13=""),"",IF(COUNTIF(Cluster_Master!$I$3:$I$17,E13&"|"&F13)=1,"Valid","Review")) | H13: =IF($G13<>"Valid","",VLOOKUP($E13&"|"&$F13,Cluster_Master!$I$3:$H$17,3,FALSE)) | I13: =IF($G13<>"Valid","",VLOOKUP($E13&"|"&$F13,Cluster_Master!$I$3:$H$17,4,FALSE)) | J13: =IF($G13<>"Valid","",VLOOKUP($E13&"|"&$F13,Cluster_Master!$I$3:$H$17,5,FALSE)) | K13: =IF($G13<>"Valid","",VLOOKUP($E13&"|"&$F13,Cluster_Master!$I$3:$H$17,6,FALSE)) | L13: =IF($G13<>"Valid","",VLOOKUP($E13&"|"&$F13,Cluster_Master!$I$3:$H$17,7,FALSE)) | M13: =IF($G13<>"Valid","",VLOOKUP($E13&"|"&$F13,Cluster_Master!$I$3:$H$17,8,FALSE)) | AI13: =IF(COUNT(T13:AH13)=0,"",SUM(T13:AH13)) | AJ13: =IF(AI13="","",AI13/75) | AK13: =IF(AI13="","",SUMPRODUCT(T13:AH13,KPI_Weights!$B$3:$B$17)/5) | AL13: =IF(COUNT(T13:AH13)=0,"",IF(OR(T13<=1,W13<=1,X13<=1,Y13<=1,AB13<=1),"YES","NO")) | AM13: =IF(AK13="","",IF(AND(AK13="NO",AJ13>=0.85),"YES","NO")) | AN13: =IF(AJ13="","",IF(AJ13>=0.90,"Excellent",IF(AJ13>=0.80,"Good",IF(AJ13>=0.70,"Fair","Poor"))))
A14: =IF(B14="","","INS-"&TEXT(ROW()-3,"000")) | C14: =IF(B14="","",ISOWEEKNUM(B14)) | D14: =IF(B14="","",TEXT(B14,"yyyy-mm")) | G14: =IF(OR(E14="",F14=""),"",IF(COUNTIF(Cluster_Master!$I$3:$I$17,E14&"|"&F14)=1,"Valid","Review")) | H14: =IF($G14<>"Valid","",VLOOKUP($E14&"|"&$F14,Cluster_Master!$I$3:$H$17,3,FALSE)) | I14: =IF($G14<>"Valid","",VLOOKUP($E14&"|"&$F14,Cluster_Master!$I$3:$H$17,4,FALSE)) | J14: =IF($G14<>"Valid","",VLOOKUP($E14&"|"&$F14,Cluster_Master!$I$3:$H$17,5,FALSE)) | K14: =IF($G14<>"Valid","",VLOOKUP($E14&"|"&$F14,Cluster_Master!$I$3:$H$17,6,FALSE)) | L14: =IF($G14<>"Valid","",VLOOKUP($E14&"|"&$F14,Cluster_Master!$I$3:$H$17,7,FALSE)) | M14: =IF($G14<>"Valid","",VLOOKUP($E14&"|"&$F14,Cluster_Master!$I$3:$H$17,8,FALSE)) | AI14: =IF(COUNT(T14:AH14)=0,"",SUM(T14:AH14)) | AJ14: =IF(AI14="","",AI14/75) | AK14: =IF(AI14="","",SUMPRODUCT(T14:AH14,KPI_Weights!$B$3:$B$17)/5) | AL14: =IF(COUNT(T14:AH14)=0,"",IF(OR(T14<=1,W14<=1,X14<=1,Y14<=1,AB14<=1),"YES","NO")) | AM14: =IF(AK14="","",IF(AND(AK14="NO",AJ14>=0.85),"YES","NO")) | AN14: =IF(AJ14="","",IF(AJ14>=0.90,"Excellent",IF(AJ14>=0.80,"Good",IF(AJ14>=0.70,"Fair","Poor"))))
A15: =IF(B15="","","INS-"&TEXT(ROW()-3,"000")) | C15: =IF(B15="","",ISOWEEKNUM(B15)) | D15: =IF(B15="","",TEXT(B15,"yyyy-mm")) | G15: =IF(OR(E15="",F15=""),"",IF(COUNTIF(Cluster_Master!$I$3:$I$17,E15&"|"&F15)=1,"Valid","Review")) | H15: =IF($G15<>"Valid","",VLOOKUP($E15&"|"&$F15,Cluster_Master!$I$3:$H$17,3,FALSE)) | I15: =IF($G15<>"Valid","",VLOOKUP($E15&"|"&$F15,Cluster_Master!$I$3:$H$17,4,FALSE)) | J15: =IF($G15<>"Valid","",VLOOKUP($E15&"|"&$F15,Cluster_Master!$I$3:$H$17,5,FALSE)) | K15: =IF($G15<>"Valid","",VLOOKUP($E15&"|"&$F15,Cluster_Master!$I$3:$H$17,6,FALSE)) | L15: =IF($G15<>"Valid","",VLOOKUP($E15&"|"&$F15,Cluster_Master!$I$3:$H$17,7,FALSE)) | M15: =IF($G15<>"Valid","",VLOOKUP($E15&"|"&$F15,Cluster_Master!$I$3:$H$17,8,FALSE)) | AI15: =IF(COUNT(T15:AH15)=0,"",SUM(T15:AH15)) | AJ15: =IF(AI15="","",AI15/75) | AK15: =IF(AI15="","",SUMPRODUCT(T15:AH15,KPI_Weights!$B$3:$B$17)/5) | AL15: =IF(COUNT(T15:AH15)=0,"",IF(OR(T15<=1,W15<=1,X15<=1,Y15<=1,AB15<=1),"YES","NO")) | AM15: =IF(AK15="","",IF(AND(AK15="NO",AJ15>=0.85),"YES","NO")) | AN15: =IF(AJ15="","",IF(AJ15>=0.90,"Excellent",IF(AJ15>=0.80,"Good",IF(AJ15>=0.70,"Fair","Poor"))))
A16: =IF(B16="","","INS-"&TEXT(ROW()-3,"000")) | C16: =IF(B16="","",ISOWEEKNUM(B16)) | D16: =IF(B16="","",TEXT(B16,"yyyy-mm")) | G16: =IF(OR(E16="",F16=""),"",IF(COUNTIF(Cluster_Master!$I$3:$I$17,E16&"|"&F16)=1,"Valid","Review")) | H16: =IF($G16<>"Valid","",VLOOKUP($E16&"|"&$F16,Cluster_Master!$I$3:$H$17,3,FALSE)) | I16: =IF($G16<>"Valid","",VLOOKUP($E16&"|"&$F16,Cluster_Master!$I$3:$H$17,4,FALSE)) | J16: =IF($G16<>"Valid","",VLOOKUP($E16&"|"&$F16,Cluster_Master!$I$3:$H$17,5,FALSE)) | K16: =IF($G16<>"Valid","",VLOOKUP($E16&"|"&$F16,Cluster_Master!$I$3:$H$17,6,FALSE)) | L16: =IF($G16<>"Valid","",VLOOKUP($E16&"|"&$F16,Cluster_Master!$I$3:$H$17,7,FALSE)) | M16: =IF($G16<>"Valid","",VLOOKUP($E16&"|"&$F16,Cluster_Master!$I$3:$H$17,8,FALSE)) | AI16: =IF(COUNT(T16:AH16)=0,"",SUM(T16:AH16)) | AJ16: =IF(AI16="","",AI16/75) | AK16: =IF(AI16="","",SUMPRODUCT(T16:AH16,KPI_Weights!$B$3:$B$17)/5) | AL16: =IF(COUNT(T16:AH16)=0,"",IF(OR(T16<=1,W16<=1,X16<=1,Y16<=1,AB16<=1),"YES","NO")) | AM16: =IF(AK16="","",IF(AND(AK16="NO",AJ16>=0.85),"YES","NO")) | AN16: =IF(AJ16="","",IF(AJ16>=0.90,"Excellent",IF(AJ16>=0.80,"Good",IF(AJ16>=0.70,"Fair","Poor"))))
A17: =IF(B17="","","INS-"&TEXT(ROW()-3,"000")) | C17: =IF(B17="","",ISOWEEKNUM(B17)) | D17: =IF(B17="","",TEXT(B17,"yyyy-mm")) | G17: =IF(OR(E17="",F17=""),"",IF(COUNTIF(Cluster_Master!$I$3:$I$17,E17&"|"&F17)=1,"Valid","Review")) | H17: =IF($G17<>"Valid","",VLOOKUP($E17&"|"&$F17,Cluster_Master!$I$3:$H$17,3,FALSE)) | I17: =IF($G17<>"Valid","",VLOOKUP($E17&"|"&$F17,Cluster_Master!$I$3:$H$17,4,FALSE)) | J17: =IF($G17<>"Valid","",VLOOKUP($E17&"|"&$F17,Cluster_Master!$I$3:$H$17,5,FALSE)) | K17: =IF($G17<>"Valid","",VLOOKUP($E17&"|"&$F17,Cluster_Master!$I$3:$H$17,6,FALSE)) | L17: =IF($G17<>"Valid","",VLOOKUP($E17&"|"&$F17,Cluster_Master!$I$3:$H$17,7,FALSE)) | M17: =IF($G17<>"Valid","",VLOOKUP($E17&"|"&$F17,Cluster_Master!$I$3:$H$17,8,FALSE)) | AI17: =IF(COUNT(T17:AH17)=0,"",SUM(T17:AH17)) | AJ17: =IF(AI17="","",AI17/75) | AK17: =IF(AI17="","",SUMPRODUCT(T17:AH17,KPI_Weights!$B$3:$B$17)/5) | AL17: =IF(COUNT(T17:AH17)=0,"",IF(OR(T17<=1,W17<=1,X17<=1,Y17<=1,AB17<=1),"YES","NO")) | AM17: =IF(AK17="","",IF(AND(AK17="NO",AJ17>=0.85),"YES","NO")) | AN17: =IF(AJ17="","",IF(AJ17>=0.90,"Excellent",IF(AJ17>=0.80,"Good",IF(AJ17>=0.70,"Fair","Poor"))))
A18: =IF(B18="","","INS-"&TEXT(ROW()-3,"000")) | C18: =IF(B18="","",ISOWEEKNUM(B18)) | D18: =IF(B18="","",TEXT(B18,"yyyy-mm")) | G18: =IF(OR(E18="",F18=""),"",IF(COUNTIF(Cluster_Master!$I$3:$I$17,E18&"|"&F18)=1,"Valid","Review")) | H18: =IF($G18<>"Valid","",VLOOKUP($E18&"|"&$F18,Cluster_Master!$I$3:$H$17,3,FALSE)) | I18: =IF($G18<>"Valid","",VLOOKUP($E18&"|"&$F18,Cluster_Master!$I$3:$H$17,4,FALSE)) | J18: =IF($G18<>"Valid","",VLOOKUP($E18&"|"&$F18,Cluster_Master!$I$3:$H$17,5,FALSE)) | K18: =IF($G18<>"Valid","",VLOOKUP($E18&"|"&$F18,Cluster_Master!$I$3:$H$17,6,FALSE)) | L18: =IF($G18<>"Valid","",VLOOKUP($E18&"|"&$F18,Cluster_Master!$I$3:$H$17,7,FALSE)) | M18: =IF($G18<>"Valid","",VLOOKUP($E18&"|"&$F18,Cluster_Master!$I$3:$H$17,8,FALSE)) | AI18: =IF(COUNT(T18:AH18)=0,"",SUM(T18:AH18)) | AJ18: =IF(AI18="","",AI18/75) | AK18: =IF(AI18="","",SUMPRODUCT(T18:AH18,KPI_Weights!$B$3:$B$17)/5) | AL18: =IF(COUNT(T18:AH18)=0,"",IF(OR(T18<=1,W18<=1,X18<=1,Y18<=1,AB18<=1),"YES","NO")) | AM18: =IF(AK18="","",IF(AND(AK18="NO",AJ18>=0.85),"YES","NO")) | AN18: =IF(AJ18="","",IF(AJ18>=0.90,"Excellent",IF(AJ18>=0.80,"Good",IF(AJ18>=0.70,"Fair","Poor"))))
... A996: =IF(B996="","","INS-"&TEXT(ROW()-3,"000")) | C996: =IF(B996="","",ISOWEEKNUM(B996)) | D996: =IF(B996="","",TEXT(B996,"yyyy-mm")) | G996: =IF(OR(E996="",F996=""),"",IF(COUNTIF(Cluster_Master!$I$3:$I$17,E996&"|"&F996)=1,"Valid","Review")) | H996: =IF($G996<>"Valid","",VLOOKUP($E996&"|"&$F996,Cluster_Master!$I$3:$H$17,3,FALSE)) | I996: =IF($G996<>"Valid","",VLOOKUP($E996&"|"&$F996,Cluster_Master!$I$3:$H$17,4,FALSE)) | J996: =IF($G996<>"Valid","",VLOOKUP($E996&"|"&$F996,Cluster_Master!$I$3:$H$17,5,FALSE)) | K996: =IF($G996<>"Valid","",VLOOKUP($E996&"|"&$F996,Cluster_Master!$I$3:$H$17,6,FALSE)) | L996: =IF($G996<>"Valid","",VLOOKUP($E996&"|"&$F996,Cluster_Master!$I$3:$H$17,7,FALSE)) | M996: =IF($G996<>"Valid","",VLOOKUP($E996&"|"&$F996,Cluster_Master!$I$3:$H$17,8,FALSE)) | AI996: =IF(COUNT(T996:AH996)=0,"",SUM(T996:AH996)) | AJ996: =IF(AI996="","",AI996/75) | AK996: =IF(AI996="","",SUMPRODUCT(T996:AH996,KPI_Weights!$B$3:$B$17)/5) | AL996: =IF(COUNT(T996:AH996)=0,"",IF(OR(T996<=1,W996<=1,X996<=1,Y996<=1,AB996<=1),"YES","NO")) | AM996: =IF(AK996="","",IF(AND(AK996="NO",AJ996>=0.85),"YES","NO")) | AN996: =IF(AJ996="","",IF(AJ996>=0.90,"Excellent",IF(AJ996>=0.80,"Good",IF(AJ996>=0.70,"Fair","Poor"))))

Sheet Weekly_Dashboard
A1: Weekly Dashboard
A3: Selected Week No | B3: 13
A4: Selected Month (yyyy-mm) | B4: 2026-03
A5: Previous Month (yyyy-mm) | B5: 2026-02
A8: Cluster | B8: Package | C8: Contractor | D8: Week Avg Raw % | E8: Week Avg Weighted % | F8: Week Red Flags | G8: Month Avg Raw % | H8: Month Avg Weighted % | I8: Month Red Flags | J8: Month Improvement | K8: Award Eligible | L8: Rank
A9: Cluster 7A | B9: =IFERROR(VLOOKUP($A9,Cluster_Master!$B$3:$C$17,1,FALSE),"") | C9: =IFERROR(VLOOKUP($A9,Cluster_Master!$B$3:$C$17,2,FALSE),"") | D9: =IFERROR(AVERAGEIFS(Weekly_Inspections!$AJ$4:$AJ$996,Weekly_Inspections!$F$4:$F$996,$A9,Weekly_Inspections!$C$4:$C$996,$B$3),"") | E9: =IFERROR(AVERAGEIFS(Weekly_Inspections!$AK$4:$AK$996,Weekly_Inspections!$F$4:$F$996,$A9,Weekly_Inspections!$C$4:$C$996,$B$3),"") | F9: =COUNTIFS(Weekly_Inspections!$F$4:$F$996,$A9,Weekly_Inspections!$C$4:$C$996,$B$3,Weekly_Inspections!$AL$4:$AL$996,"YES") | G9: =IFERROR(AVERAGEIFS(Weekly_Inspections!$AJ$4:$AJ$996,Weekly_Inspections!$F$4:$F$996,$A9,Weekly_Inspections!$D$4:$D$996,$B$4),"") | H9: =IFERROR(AVERAGEIFS(Weekly_Inspections!$AK$4:$AK$996,Weekly_Inspections!$F$4:$F$996,$A9,Weekly_Inspections!$D$4:$D$996,$B$4),"") | I9: =COUNTIFS(Weekly_Inspections!$F$4:$F$996,$A9,Weekly_Inspections!$D$4:$D$996,$B$4,Weekly_Inspections!$AL$4:$AL$996,"YES") | J9: =IFERROR(H9-AVERAGEIFS(Weekly_Inspections!$AK$4:$AK$996,Weekly_Inspections!$F$4:$F$996,$A9,Weekly_Inspections!$D$4:$D$996,$B$5),"") | K9: =IF(AND(H9>=0.85,I9=0),"YES","NO") | L9: =IFERROR(RANK(H9,$H$9:$H$23,0),"")
A10: Cluster 7B | B10: =IFERROR(VLOOKUP($A10,Cluster_Master!$B$3:$C$17,1,FALSE),"") | C10: =IFERROR(VLOOKUP($A10,Cluster_Master!$B$3:$C$17,2,FALSE),"") | D10: =IFERROR(AVERAGEIFS(Weekly_Inspections!$AJ$4:$AJ$996,Weekly_Inspections!$F$4:$F$996,$A10,Weekly_Inspections!$C$4:$C$996,$B$3),"") | E10: =IFERROR(AVERAGEIFS(Weekly_Inspections!$AK$4:$AK$996,Weekly_Inspections!$F$4:$F$996,$A10,Weekly_Inspections!$C$4:$C$996,$B$3),"") | F10: =COUNTIFS(Weekly_Inspections!$F$4:$F$996,$A10,Weekly_Inspections!$C$4:$C$996,$B$3,Weekly_Inspections!$AL$4:$AL$996,"YES") | G10: =IFERROR(AVERAGEIFS(Weekly_Inspections!$AJ$4:$AJ$996,Weekly_Inspections!$F$4:$F$996,$A10,Weekly_Inspections!$D$4:$D$996,$B$4),"") | H10: =IFERROR(AVERAGEIFS(Weekly_Inspections!$AK$4:$AK$996,Weekly_Inspections!$F$4:$F$996,$A10,Weekly_Inspections!$D$4:$D$996,$B$4),"") | I10: =COUNTIFS(Weekly_Inspections!$F$4:$F$996,$A10,Weekly_Inspections!$D$4:$D$996,$B$4,Weekly_Inspections!$AL$4:$AL$996,"YES") | J10: =IFERROR(H10-AVERAGEIFS(Weekly_Inspections!$AK$4:$AK$996,Weekly_Inspections!$F$4:$F$996,$A10,Weekly_Inspections!$D$4:$D$996,$B$5),"") | K10: =IF(AND(H10>=0.85,I10=0),"YES","NO") | L10: =IFERROR(RANK(H10,$H$9:$H$23,0),"")
A11: Cluster 8A | B11: =IFERROR(VLOOKUP($A11,Cluster_Master!$B$3:$C$17,1,FALSE),"") | C11: =IFERROR(VLOOKUP($A11,Cluster_Master!$B$3:$C$17,2,FALSE),"") | D11: =IFERROR(AVERAGEIFS(Weekly_Inspections!$AJ$4:$AJ$996,Weekly_Inspections!$F$4:$F$996,$A11,Weekly_Inspections!$C$4:$C$996,$B$3),"") | E11: =IFERROR(AVERAGEIFS(Weekly_Inspections!$AK$4:$AK$996,Weekly_Inspections!$F$4:$F$996,$A11,Weekly_Inspections!$C$4:$C$996,$B$3),"") | F11: =COUNTIFS(Weekly_Inspections!$F$4:$F$996,$A11,Weekly_Inspections!$C$4:$C$996,$B$3,Weekly_Inspections!$AL$4:$AL$996,"YES") | G11: =IFERROR(AVERAGEIFS(Weekly_Inspections!$AJ$4:$AJ$996,Weekly_Inspections!$F$4:$F$996,$A11,Weekly_Inspections!$D$4:$D$996,$B$4),"") | H11: =IFERROR(AVERAGEIFS(Weekly_Inspections!$AK$4:$AK$996,Weekly_Inspections!$F$4:$F$996,$A11,Weekly_Inspections!$D$4:$D$996,$B$4),"") | I11: =COUNTIFS(Weekly_Inspections!$F$4:$F$996,$A11,Weekly_Inspections!$D$4:$D$996,$B$4,Weekly_Inspections!$AL$4:$AL$996,"YES") | J11: =IFERROR(H11-AVERAGEIFS(Weekly_Inspections!$AK$4:$AK$996,Weekly_Inspections!$F$4:$F$996,$A11,Weekly_Inspections!$D$4:$D$996,$B$5),"") | K11: =IF(AND(H11>=0.85,I11=0),"YES","NO") | L11: =IFERROR(RANK(H11,$H$9:$H$23,0),"")
A12: Cluster 8B | B12: =IFERROR(VLOOKUP($A12,Cluster_Master!$B$3:$C$17,1,FALSE),"") | C12: =IFERROR(VLOOKUP($A12,Cluster_Master!$B$3:$C$17,2,FALSE),"") | D12: =IFERROR(AVERAGEIFS(Weekly_Inspections!$AJ$4:$AJ$996,Weekly_Inspections!$F$4:$F$996,$A12,Weekly_Inspections!$C$4:$C$996,$B$3),"") | E12: =IFERROR(AVERAGEIFS(Weekly_Inspections!$AK$4:$AK$996,Weekly_Inspections!$F$4:$F$996,$A12,Weekly_Inspections!$C$4:$C$996,$B$3),"") | F12: =COUNTIFS(Weekly_Inspections!$F$4:$F$996,$A12,Weekly_Inspections!$C$4:$C$996,$B$3,Weekly_Inspections!$AL$4:$AL$996,"YES") | G12: =IFERROR(AVERAGEIFS(Weekly_Inspections!$AJ$4:$AJ$996,Weekly_Inspections!$F$4:$F$996,$A12,Weekly_Inspections!$D$4:$D$996,$B$4),"") | H12: =IFERROR(AVERAGEIFS(Weekly_Inspections!$AK$4:$AK$996,Weekly_Inspections!$F$4:$F$996,$A12,Weekly_Inspections!$D$4:$D$996,$B$4),"") | I12: =COUNTIFS(Weekly_Inspections!$F$4:$F$996,$A12,Weekly_Inspections!$D$4:$D$996,$B$4,Weekly_Inspections!$AL$4:$AL$996,"YES") | J12: =IFERROR(H12-AVERAGEIFS(Weekly_Inspections!$AK$4:$AK$996,Weekly_Inspections!$F$4:$F$996,$A12,Weekly_Inspections!$D$4:$D$996,$B$5),"") | K12: =IF(AND(H12>=0.85,I12=0),"YES","NO") | L12: =IFERROR(RANK(H12,$H$9:$H$23,0),"")
A13: Cluster 8C | B13: =IFERROR(VLOOKUP($A13,Cluster_Master!$B$3:$C$17,1,FALSE),"") | C13: =IFERROR(VLOOKUP($A13,Cluster_Master!$B$3:$C$17,2,FALSE),"") | D13: =IFERROR(AVERAGEIFS(Weekly_Inspections!$AJ$4:$AJ$996,Weekly_Inspections!$F$4:$F$996,$A13,Weekly_Inspections!$C$4:$C$996,$B$3),"") | E13: =IFERROR(AVERAGEIFS(Weekly_Inspections!$AK$4:$AK$996,Weekly_Inspections!$F$4:$F$996,$A13,Weekly_Inspections!$C$4:$C$996,$B$3),"") | F13: =COUNTIFS(Weekly_Inspections!$F$4:$F$996,$A13,Weekly_Inspections!$C$4:$C$996,$B$3,Weekly_Inspections!$AL$4:$AL$996,"YES") | G13: =IFERROR(AVERAGEIFS(Weekly_Inspections!$AJ$4:$AJ$996,Weekly_Inspections!$F$4:$F$996,$A13,Weekly_Inspections!$D$4:$D$996,$B$4),"") | H13: =IFERROR(AVERAGEIFS(Weekly_Inspections!$AK$4:$AK$996,Weekly_Inspections!$F$4:$F$996,$A13,Weekly_Inspections!$D$4:$D$996,$B$4),"") | I13: =COUNTIFS(Weekly_Inspections!$F$4:$F$996,$A13,Weekly_Inspections!$D$4:$D$996,$B$4,Weekly_Inspections!$AL$4:$AL$996,"YES") | J13: =IFERROR(H13-AVERAGEIFS(Weekly_Inspections!$AK$4:$AK$996,Weekly_Inspections!$F$4:$F$996,$A13,Weekly_Inspections!$D$4:$D$996,$B$5),"") | K13: =IF(AND(H13>=0.85,I13=0),"YES","NO") | L13: =IFERROR(RANK(H13,$H$9:$H$23,0),"")
A14: Cluster 8D | B14: =IFERROR(VLOOKUP($A14,Cluster_Master!$B$3:$C$17,1,FALSE),"") | C14: =IFERROR(VLOOKUP($A14,Cluster_Master!$B$3:$C$17,2,FALSE),"") | D14: =IFERROR(AVERAGEIFS(Weekly_Inspections!$AJ$4:$AJ$996,Weekly_Inspections!$F$4:$F$996,$A14,Weekly_Inspections!$C$4:$C$996,$B$3),"") | E14: =IFERROR(AVERAGEIFS(Weekly_Inspections!$AK$4:$AK$996,Weekly_Inspections!$F$4:$F$996,$A14,Weekly_Inspections!$C$4:$C$996,$B$3),"") | F14: =COUNTIFS(Weekly_Inspections!$F$4:$F$996,$A14,Weekly_Inspections!$C$4:$C$996,$B$3,Weekly_Inspections!$AL$4:$AL$996,"YES") | G14: =IFERROR(AVERAGEIFS(Weekly_Inspections!$AJ$4:$AJ$996,Weekly_Inspections!$F$4:$F$996,$A14,Weekly_Inspections!$D$4:$D$996,$B$4),"") | H14: =IFERROR(AVERAGEIFS(Weekly_Inspections!$AK$4:$AK$996,Weekly_Inspections!$F$4:$F$996,$A14,Weekly_Inspections!$D$4:$D$996,$B$4),"") | I14: =COUNTIFS(Weekly_Inspections!$F$4:$F$996,$A14,Weekly_Inspections!$D$4:$D$996,$B$4,Weekly_Inspections!$AL$4:$AL$996,"YES") | J14: =IFERROR(H14-AVERAGEIFS(Weekly_Inspections!$AK$4:$AK$996,Weekly_Inspections!$F$4:$F$996,$A14,Weekly_Inspections!$D$4:$D$996,$B$5),"") | K14: =IF(AND(H14>=0.85,I14=0),"YES","NO") | L14: =IFERROR(RANK(H14,$H$9:$H$23,0),"")
A15: Cluster 3 | B15: =IFERROR(VLOOKUP($A15,Cluster_Master!$B$3:$C$17,1,FALSE),"") | C15: =IFERROR(VLOOKUP($A15,Cluster_Master!$B$3:$C$17,2,FALSE),"") | D15: =IFERROR(AVERAGEIFS(Weekly_Inspections!$AJ$4:$AJ$996,Weekly_Inspections!$F$4:$F$996,$A15,Weekly_Inspections!$C$4:$C$996,$B$3),"") | E15: =IFERROR(AVERAGEIFS(Weekly_Inspections!$AK$4:$AK$996,Weekly_Inspections!$F$4:$F$996,$A15,Weekly_Inspections!$C$4:$C$996,$B$3),"") | F15: =COUNTIFS(Weekly_Inspections!$F$4:$F$996,$A15,Weekly_Inspections!$C$4:$C$996,$B$3,Weekly_Inspections!$AL$4:$AL$996,"YES") | G15: =IFERROR(AVERAGEIFS(Weekly_Inspections!$AJ$4:$AJ$996,Weekly_Inspections!$F$4:$F$996,$A15,Weekly_Inspections!$D$4:$D$996,$B$4),"") | H15: =IFERROR(AVERAGEIFS(Weekly_Inspections!$AK$4:$AK$996,Weekly_Inspections!$F$4:$F$996,$A15,Weekly_Inspections!$D$4:$D$996,$B$4),"") | I15: =COUNTIFS(Weekly_Inspections!$F$4:$F$996,$A15,Weekly_Inspections!$D$4:$D$996,$B$4,Weekly_Inspections!$AL$4:$AL$996,"YES") | J15: =IFERROR(H15-AVERAGEIFS(Weekly_Inspections!$AK$4:$AK$996,Weekly_Inspections!$F$4:$F$996,$A15,Weekly_Inspections!$D$4:$D$996,$B$5),"") | K15: =IF(AND(H15>=0.85,I15=0),"YES","NO") | L15: =IFERROR(RANK(H15,$H$9:$H$23,0),"")
A16: Cluster 4 | B16: =IFERROR(VLOOKUP($A16,Cluster_Master!$B$3:$C$17,1,FALSE),"") | C16: =IFERROR(VLOOKUP($A16,Cluster_Master!$B$3:$C$17,2,FALSE),"") | D16: =IFERROR(AVERAGEIFS(Weekly_Inspections!$AJ$4:$AJ$996,Weekly_Inspections!$F$4:$F$996,$A16,Weekly_Inspections!$C$4:$C$996,$B$3),"") | E16: =IFERROR(AVERAGEIFS(Weekly_Inspections!$AK$4:$AK$996,Weekly_Inspections!$F$4:$F$996,$A16,Weekly_Inspections!$C$4:$C$996,$B$3),"") | F16: =COUNTIFS(Weekly_Inspections!$F$4:$F$996,$A16,Weekly_Inspections!$C$4:$C$996,$B$3,Weekly_Inspections!$AL$4:$AL$996,"YES") | G16: =IFERROR(AVERAGEIFS(Weekly_Inspections!$AJ$4:$AJ$996,Weekly_Inspections!$F$4:$F$996,$A16,Weekly_Inspections!$D$4:$D$996,$B$4),"") | H16: =IFERROR(AVERAGEIFS(Weekly_Inspections!$AK$4:$AK$996,Weekly_Inspections!$F$4:$F$996,$A16,Weekly_Inspections!$D$4:$D$996,$B$4),"") | I16: =COUNTIFS(Weekly_Inspections!$F$4:$F$996,$A16,Weekly_Inspections!$D$4:$D$996,$B$4,Weekly_Inspections!$AL$4:$AL$996,"YES") | J16: =IFERROR(H16-AVERAGEIFS(Weekly_Inspections!$AK$4:$AK$996,Weekly_Inspections!$F$4:$F$996,$A16,Weekly_Inspections!$D$4:$D$996,$B$5),"") | K16: =IF(AND(H16>=0.85,I16=0),"YES","NO") | L16: =IFERROR(RANK(H16,$H$9:$H$23,0),"")
A17: Cluster 5 | B17: =IFERROR(VLOOKUP($A17,Cluster_Master!$B$3:$C$17,1,FALSE),"") | C17: =IFERROR(VLOOKUP($A17,Cluster_Master!$B$3:$C$17,2,FALSE),"") | D17: =IFERROR(AVERAGEIFS(Weekly_Inspections!$AJ$4:$AJ$996,Weekly_Inspections!$F$4:$F$996,$A17,Weekly_Inspections!$C$4:$C$996,$B$3),"") | E17: =IFERROR(AVERAGEIFS(Weekly_Inspections!$AK$4:$AK$996,Weekly_Inspections!$F$4:$F$996,$A17,Weekly_Inspections!$C$4:$C$996,$B$3),"") | F17: =COUNTIFS(Weekly_Inspections!$F$4:$F$996,$A17,Weekly_Inspections!$C$4:$C$996,$B$3,Weekly_Inspections!$AL$4:$AL$996,"YES") | G17: =IFERROR(AVERAGEIFS(Weekly_Inspections!$AJ$4:$AJ$996,Weekly_Inspections!$F$4:$F$996,$A17,Weekly_Inspections!$D$4:$D$996,$B$4),"") | H17: =IFERROR(AVERAGEIFS(Weekly_Inspections!$AK$4:$AK$996,Weekly_Inspections!$F$4:$F$996,$A17,Weekly_Inspections!$D$4:$D$996,$B$4),"") | I17: =COUNTIFS(Weekly_Inspections!$F$4:$F$996,$A17,Weekly_Inspections!$D$4:$D$996,$B$4,Weekly_Inspections!$AL$4:$AL$996,"YES") | J17: =IFERROR(H17-AVERAGEIFS(Weekly_Inspections!$AK$4:$AK$996,Weekly_Inspections!$F$4:$F$996,$A17,Weekly_Inspections!$D$4:$D$996,$B$5),"") | K17: =IF(AND(H17>=0.85,I17=0),"YES","NO") | L17: =IFERROR(RANK(H17,$H$9:$H$23,0),"")
A18: Cluster 6 | B18: =IFERROR(VLOOKUP($A18,Cluster_Master!$B$3:$C$17,1,FALSE),"") | C18: =IFERROR(VLOOKUP($A18,Cluster_Master!$B$3:$C$17,2,FALSE),"") | D18: =IFERROR(AVERAGEIFS(Weekly_Inspections!$AJ$4:$AJ$996,Weekly_Inspections!$F$4:$F$996,$A18,Weekly_Inspections!$C$4:$C$996,$B$3),"") | E18: =IFERROR(AVERAGEIFS(Weekly_Inspections!$AK$4:$AK$996,Weekly_Inspections!$F$4:$F$996,$A18,Weekly_Inspections!$C$4:$C$996,$B$3),"") | F18: =COUNTIFS(Weekly_Inspections!$F$4:$F$996,$A18,Weekly_Inspections!$C$4:$C$996,$B$3,Weekly_Inspections!$AL$4:$AL$996,"YES") | G18: =IFERROR(AVERAGEIFS(Weekly_Inspections!$AJ$4:$AJ$996,Weekly_Inspections!$F$4:$F$996,$A18,Weekly_Inspections!$D$4:$D$996,$B$4),"") | H18: =IFERROR(AVERAGEIFS(Weekly_Inspections!$AK$4:$AK$996,Weekly_Inspections!$F$4:$F$996,$A18,Weekly_Inspections!$D$4:$D$996,$B$4),"") | I18: =COUNTIFS(Weekly_Inspections!$F$4:$F$996,$A18,Weekly_Inspections!$D$4:$D$996,$B$4,Weekly_Inspections!$AL$4:$AL$996,"YES") | J18: =IFERROR(H18-AVERAGEIFS(Weekly_Inspections!$AK$4:$AK$996,Weekly_Inspections!$F$4:$F$996,$A18,Weekly_Inspections!$D$4:$D$996,$B$5),"") | K18: =IF(AND(H18>=0.85,I18=0),"YES","NO") | L18: =IFERROR(RANK(H18,$H$9:$H$23,0),"")
A19: Cluster 1A | B19: =IFERROR(VLOOKUP($A19,Cluster_Master!$B$3:$C$17,1,FALSE),"") | C19: =IFERROR(VLOOKUP($A19,Cluster_Master!$B$3:$C$17,2,FALSE),"") | D19: =IFERROR(AVERAGEIFS(Weekly_Inspections!$AJ$4:$AJ$996,Weekly_Inspections!$F$4:$F$996,$A19,Weekly_Inspections!$C$4:$C$996,$B$3),"") | E19: =IFERROR(AVERAGEIFS(Weekly_Inspections!$AK$4:$AK$996,Weekly_Inspections!$F$4:$F$996,$A19,Weekly_Inspections!$C$4:$C$996,$B$3),"") | F19: =COUNTIFS(Weekly_Inspections!$F$4:$F$996,$A19,Weekly_Inspections!$C$4:$C$996,$B$3,Weekly_Inspections!$AL$4:$AL$996,"YES") | G19: =IFERROR(AVERAGEIFS(Weekly_Inspections!$AJ$4:$AJ$996,Weekly_Inspections!$F$4:$F$996,$A19,Weekly_Inspections!$D$4:$D$996,$B$4),"") | H19: =IFERROR(AVERAGEIFS(Weekly_Inspections!$AK$4:$AK$996,Weekly_Inspections!$F$4:$F$996,$A19,Weekly_Inspections!$D$4:$D$996,$B$4),"") | I19: =COUNTIFS(Weekly_Inspections!$F$4:$F$996,$A19,Weekly_Inspections!$D$4:$D$996,$B$4,Weekly_Inspections!$AL$4:$AL$996,"YES") | J19: =IFERROR(H19-AVERAGEIFS(Weekly_Inspections!$AK$4:$AK$996,Weekly_Inspections!$F$4:$F$996,$A19,Weekly_Inspections!$D$4:$D$996,$B$5),"") | K19: =IF(AND(H19>=0.85,I19=0),"YES","NO") | L19: =IFERROR(RANK(H19,$H$9:$H$23,0),"")
A20: Cluster 1B | B20: =IFERROR(VLOOKUP($A20,Cluster_Master!$B$3:$C$17,1,FALSE),"") | C20: =IFERROR(VLOOKUP($A20,Cluster_Master!$B$3:$C$17,2,FALSE),"") | D20: =IFERROR(AVERAGEIFS(Weekly_Inspections!$AJ$4:$AJ$996,Weekly_Inspections!$F$4:$F$996,$A20,Weekly_Inspections!$C$4:$C$996,$B$3),"") | E20: =IFERROR(AVERAGEIFS(Weekly_Inspections!$AK$4:$AK$996,Weekly_Inspections!$F$4:$F$996,$A20,Weekly_Inspections!$C$4:$C$996,$B$3),"") | F20: =COUNTIFS(Weekly_Inspections!$F$4:$F$996,$A20,Weekly_Inspections!$C$4:$C$996,$B$3,Weekly_Inspections!$AL$4:$AL$996,"YES") | G20: =IFERROR(AVERAGEIFS(Weekly_Inspections!$AJ$4:$AJ$996,Weekly_Inspections!$F$4:$F$996,$A20,Weekly_Inspections!$D$4:$D$996,$B$4),"") | H20: =IFERROR(AVERAGEIFS(Weekly_Inspections!$AK$4:$AK$996,Weekly_Inspections!$F$4:$F$996,$A20,Weekly_Inspections!$D$4:$D$996,$B$4),"") | I20: =COUNTIFS(Weekly_Inspections!$F$4:$F$996,$A20,Weekly_Inspections!$D$4:$D$996,$B$4,Weekly_Inspections!$AL$4:$AL$996,"YES") | J20: =IFERROR(H20-AVERAGEIFS(Weekly_Inspections!$AK$4:$AK$996,Weekly_Inspections!$F$4:$F$996,$A20,Weekly_Inspections!$D$4:$D$996,$B$5),"") | K20: =IF(AND(H20>=0.85,I20=0),"YES","NO") | L20: =IFERROR(RANK(H20,$H$9:$H$23,0),"")
... A23: Cluster 2C | B23: =IFERROR(VLOOKUP($A23,Cluster_Master!$B$3:$C$17,1,FALSE),"") | C23: =IFERROR(VLOOKUP($A23,Cluster_Master!$B$3:$C$17,2,FALSE),"") | D23: =IFERROR(AVERAGEIFS(Weekly_Inspections!$AJ$4:$AJ$996,Weekly_Inspections!$F$4:$F$996,$A23,Weekly_Inspections!$C$4:$C$996,$B$3),"") | E23: =IFERROR(AVERAGEIFS(Weekly_Inspections!$AK$4:$AK$996,Weekly_Inspections!$F$4:$F$996,$A23,Weekly_Inspections!$C$4:$C$996,$B$3),"") | F23: =COUNTIFS(Weekly_Inspections!$F$4:$F$996,$A23,Weekly_Inspections!$C$4:$C$996,$B$3,Weekly_Inspections!$AL$4:$AL$996,"YES") | G23: =IFERROR(AVERAGEIFS(Weekly_Inspections!$AJ$4:$AJ$996,Weekly_Inspections!$F$4:$F$996,$A23,Weekly_Inspections!$D$4:$D$996,$B$4),"") | H23: =IFERROR(AVERAGEIFS(Weekly_Inspections!$AK$4:$AK$996,Weekly_Inspections!$F$4:$F$996,$A23,Weekly_Inspections!$D$4:$D$996,$B$4),"") | I23: =COUNTIFS(Weekly_Inspections!$F$4:$F$996,$A23,Weekly_Inspections!$D$4:$D$996,$B$4,Weekly_Inspections!$AL$4:$AL$996,"YES") | J23: =IFERROR(H23-AVERAGEIFS(Weekly_Inspections!$AK$4:$AK$996,Weekly_Inspections!$F$4:$F$996,$A23,Weekly_Inspections!$D$4:$D$996,$B$5),"") | K23: =IF(AND(H23>=0.85,I23=0),"YES","NO") | L23: =IFERROR(RANK(H23,$H$9:$H$23,0),"")
A27: KPI | B27: Selected Week Avg Score | C27: Selected Month Avg Score | D27: Gap to 5 (Week) | E27: Gap to 5 (Month) | F27: Root Cause | G27: Selected Week Count | H27: Selected Month Count
A28: Work at Height Control | B28: =IFERROR(AVERAGEIFS(Weekly_Inspections!$T$4:$T$996,Weekly_Inspections!$C$4:$C$996,$B$3),"") | C28: =IFERROR(AVERAGEIFS(Weekly_Inspections!$T$4:$T$996,Weekly_Inspections!$D$4:$D$996,$B$4),"") | D28: =IF(B28="","",5-B28) | E28: =IF(C28="","",5-C28) | F28: Leadership failure | G28: =COUNTIFS(Weekly_Inspections!$AP$4:$AP$996,$F28,Weekly_Inspections!$C$4:$C$996,$B$3) | H28: =COUNTIFS(Weekly_Inspections!$AP$4:$AP$996,$F28,Weekly_Inspections!$D$4:$D$996,$B$4)
A29: Edge Protection | B29: =IFERROR(AVERAGEIFS(Weekly_Inspections!$U$4:$U$996,Weekly_Inspections!$C$4:$C$996,$B$3),"") | C29: =IFERROR(AVERAGEIFS(Weekly_Inspections!$U$4:$U$996,Weekly_Inspections!$D$4:$D$996,$B$4),"") | D29: =IF(B29="","",5-B29) | E29: =IF(C29="","",5-C29) | F29: Poor supervision | G29: =COUNTIFS(Weekly_Inspections!$AP$4:$AP$996,$F29,Weekly_Inspections!$C$4:$C$996,$B$3) | H29: =COUNTIFS(Weekly_Inspections!$AP$4:$AP$996,$F29,Weekly_Inspections!$D$4:$D$996,$B$4)
A30: Falling Object Prevention | B30: =IFERROR(AVERAGEIFS(Weekly_Inspections!$V$4:$V$996,Weekly_Inspections!$C$4:$C$996,$B$3),"") | C30: =IFERROR(AVERAGEIFS(Weekly_Inspections!$V$4:$V$996,Weekly_Inspections!$D$4:$D$996,$B$4),"") | D30: =IF(B30="","",5-B30) | E30: =IF(C30="","",5-C30) | F30: Poor planning | G30: =COUNTIFS(Weekly_Inspections!$AP$4:$AP$996,$F30,Weekly_Inspections!$C$4:$C$996,$B$3) | H30: =COUNTIFS(Weekly_Inspections!$AP$4:$AP$996,$F30,Weekly_Inspections!$D$4:$D$996,$B$4)
A31: Excavation Safety | B31: =IFERROR(AVERAGEIFS(Weekly_Inspections!$W$4:$W$996,Weekly_Inspections!$C$4:$C$996,$B$3),"") | C31: =IFERROR(AVERAGEIFS(Weekly_Inspections!$W$4:$W$996,Weekly_Inspections!$D$4:$D$996,$B$4),"") | D31: =IF(B31="","",5-B31) | E31: =IF(C31="","",5-C31) | F31: PTW failure | G31: =COUNTIFS(Weekly_Inspections!$AP$4:$AP$996,$F31,Weekly_Inspections!$C$4:$C$996,$B$3) | H31: =COUNTIFS(Weekly_Inspections!$AP$4:$AP$996,$F31,Weekly_Inspections!$D$4:$D$996,$B$4)
A32: Scaffolding Compliance | B32: =IFERROR(AVERAGEIFS(Weekly_Inspections!$X$4:$X$996,Weekly_Inspections!$C$4:$C$996,$B$3),"") | C32: =IFERROR(AVERAGEIFS(Weekly_Inspections!$X$4:$X$996,Weekly_Inspections!$D$4:$D$996,$B$4),"") | D32: =IF(B32="","",5-B32) | E32: =IF(C32="","",5-C32) | F32: Weak MSRA | G32: =COUNTIFS(Weekly_Inspections!$AP$4:$AP$996,$F32,Weekly_Inspections!$C$4:$C$996,$B$3) | H32: =COUNTIFS(Weekly_Inspections!$AP$4:$AP$996,$F32,Weekly_Inspections!$D$4:$D$996,$B$4)
A33: PTW Implementation | B33: =IFERROR(AVERAGEIFS(Weekly_Inspections!$Y$4:$Y$996,Weekly_Inspections!$C$4:$C$996,$B$3),"") | C33: =IFERROR(AVERAGEIFS(Weekly_Inspections!$Y$4:$Y$996,Weekly_Inspections!$D$4:$D$996,$B$4),"") | D33: =IF(B33="","",5-B33) | E33: =IF(C33="","",5-C33) | F33: Poor subcontractor control | G33: =COUNTIFS(Weekly_Inspections!$AP$4:$AP$996,$F33,Weekly_Inspections!$C$4:$C$996,$B$3) | H33: =COUNTIFS(Weekly_Inspections!$AP$4:$AP$996,$F33,Weekly_Inspections!$D$4:$D$996,$B$4)
A34: PTW Field Verification | B34: =IFERROR(AVERAGEIFS(Weekly_Inspections!$Z$4:$Z$996,Weekly_Inspections!$C$4:$C$996,$B$3),"") | C34: =IFERROR(AVERAGEIFS(Weekly_Inspections!$Z$4:$Z$996,Weekly_Inspections!$D$4:$D$996,$B$4),"") | D34: =IF(B34="","",5-B34) | E34: =IF(C34="","",5-C34) | F34: Resource constraint | G34: =COUNTIFS(Weekly_Inspections!$AP$4:$AP$996,$F34,Weekly_Inspections!$C$4:$C$996,$B$3) | H34: =COUNTIFS(Weekly_Inspections!$AP$4:$AP$996,$F34,Weekly_Inspections!$D$4:$D$996,$B$4)
A35: MSRA Quality | B35: =IFERROR(AVERAGEIFS(Weekly_Inspections!$AA$4:$AA$996,Weekly_Inspections!$C$4:$C$996,$B$3),"") | C35: =IFERROR(AVERAGEIFS(Weekly_Inspections!$AA$4:$AA$996,Weekly_Inspections!$D$4:$D$996,$B$4),"") | D35: =IF(B35="","",5-B35) | E35: =IF(C35="","",5-C35) | F35: Inadequate competence | G35: =COUNTIFS(Weekly_Inspections!$AP$4:$AP$996,$F35,Weekly_Inspections!$C$4:$C$996,$B$3) | H35: =COUNTIFS(Weekly_Inspections!$AP$4:$AP$996,$F35,Weekly_Inspections!$D$4:$D$996,$B$4)
A36: Lifting/Precast Installation | B36: =IFERROR(AVERAGEIFS(Weekly_Inspections!$AB$4:$AB$996,Weekly_Inspections!$C$4:$C$996,$B$3),"") | C36: =IFERROR(AVERAGEIFS(Weekly_Inspections!$AB$4:$AB$996,Weekly_Inspections!$D$4:$D$996,$B$4),"") | D36: =IF(B36="","",5-B36) | E36: =IF(C36="","",5-C36) | F36: Poor housekeeping culture | G36: =COUNTIFS(Weekly_Inspections!$AP$4:$AP$996,$F36,Weekly_Inspections!$C$4:$C$996,$B$3) | H36: =COUNTIFS(Weekly_Inspections!$AP$4:$AP$996,$F36,Weekly_Inspections!$D$4:$D$996,$B$4)
A37: Traffic & Man-Machine Interface | B37: =IFERROR(AVERAGEIFS(Weekly_Inspections!$AC$4:$AC$996,Weekly_Inspections!$C$4:$C$996,$B$3),"") | C37: =IFERROR(AVERAGEIFS(Weekly_Inspections!$AC$4:$AC$996,Weekly_Inspections!$D$4:$D$996,$B$4),"") | D37: =IF(B37="","",5-B37) | E37: =IF(C37="","",5-C37) | F37: Interface / simultaneous activity conflict | G37: =COUNTIFS(Weekly_Inspections!$AP$4:$AP$996,$F37,Weekly_Inspections!$C$4:$C$996,$B$3) | H37: =COUNTIFS(Weekly_Inspections!$AP$4:$AP$996,$F37,Weekly_Inspections!$D$4:$D$996,$B$4)
A38: Housekeeping/Waste Management | B38: =IFERROR(AVERAGEIFS(Weekly_Inspections!$AD$4:$AD$996,Weekly_Inspections!$C$4:$C$996,$B$3),"") | C38: =IFERROR(AVERAGEIFS(Weekly_Inspections!$AD$4:$AD$996,Weekly_Inspections!$D$4:$D$996,$B$4),"") | D38: =IF(B38="","",5-B38) | E38: =IF(C38="","",5-C38) | F38: Other | G38: =COUNTIFS(Weekly_Inspections!$AP$4:$AP$996,$F38,Weekly_Inspections!$C$4:$C$996,$B$3) | H38: =COUNTIFS(Weekly_Inspections!$AP$4:$AP$996,$F38,Weekly_Inspections!$D$4:$D$996,$B$4)
A39: Welfare Arrangement | B39: =IFERROR(AVERAGEIFS(Weekly_Inspections!$AE$4:$AE$996,Weekly_Inspections!$C$4:$C$996,$B$3),"") | C39: =IFERROR(AVERAGEIFS(Weekly_Inspections!$AE$4:$AE$996,Weekly_Inspections!$D$4:$D$996,$B$4),"") | D39: =IF(B39="","",5-B39) | E39: =IF(C39="","",5-C39) | G39: =COUNTIFS(Weekly_Inspections!$AP$4:$AP$996,$F39,Weekly_Inspections!$C$4:$C$996,$B$3) | H39: =COUNTIFS(Weekly_Inspections!$AP$4:$AP$996,$F39,Weekly_Inspections!$D$4:$D$996,$B$4)
A40: Fire Readiness | B40: =IFERROR(AVERAGEIFS(Weekly_Inspections!$AF$4:$AF$996,Weekly_Inspections!$C$4:$C$996,$B$3),"") | C40: =IFERROR(AVERAGEIFS(Weekly_Inspections!$AF$4:$AF$996,Weekly_Inspections!$D$4:$D$996,$B$4),"") | D40: =IF(B40="","",5-B40) | E40: =IF(C40="","",5-C40) | G40: =COUNTIFS(Weekly_Inspections!$AP$4:$AP$996,$F40,Weekly_Inspections!$C$4:$C$996,$B$3) | H40: =COUNTIFS(Weekly_Inspections!$AP$4:$AP$996,$F40,Weekly_Inspections!$D$4:$D$996,$B$4)
A41: Supervision & Subcontractor Control | B41: =IFERROR(AVERAGEIFS(Weekly_Inspections!$AG$4:$AG$996,Weekly_Inspections!$C$4:$C$996,$B$3),"") | C41: =IFERROR(AVERAGEIFS(Weekly_Inspections!$AG$4:$AG$996,Weekly_Inspections!$D$4:$D$996,$B$4),"") | D41: =IF(B41="","",5-B41) | E41: =IF(C41="","",5-C41) | G41: =COUNTIFS(Weekly_Inspections!$AP$4:$AP$996,$F41,Weekly_Inspections!$C$4:$C$996,$B$3) | H41: =COUNTIFS(Weekly_Inspections!$AP$4:$AP$996,$F41,Weekly_Inspections!$D$4:$D$996,$B$4)
A42: Temporary Electrical & Tool Safety | B42: =IFERROR(AVERAGEIFS(Weekly_Inspections!$AH$4:$AH$996,Weekly_Inspections!$C$4:$C$996,$B$3),"") | C42: =IFERROR(AVERAGEIFS(Weekly_Inspections!$AH$4:$AH$996,Weekly_Inspections!$D$4:$D$996,$B$4),"") | D42: =IF(B42="","",5-B42) | E42: =IF(C42="","",5-C42) | G42: =COUNTIFS(Weekly_Inspections!$AP$4:$AP$996,$F42,Weekly_Inspections!$C$4:$C$996,$B$3) | H42: =COUNTIFS(Weekly_Inspections!$AP$4:$AP$996,$F42,Weekly_Inspections!$D$4:$D$996,$B$4)

Sheet Monthly_Dashboard
A1: Monthly Dashboard
A3: Selected Month (yyyy-mm) | B3: 2026-03
A4: Previous Month (yyyy-mm) | B4: 2026-02
A6: Cluster | B6: Package | C6: Contractor | D6: Month Avg Raw % | E6: Month Avg Weighted % | F6: Red Flags | G6: Improvement vs Prev Month | H6: Award Eligible | I6: Rank | J6: Open Actions | K6: Overdue Actions
A7: Cluster 7A | B7: =IFERROR(VLOOKUP($A7,Cluster_Master!$B$3:$C$17,1,FALSE),"") | C7: =IFERROR(VLOOKUP($A7,Cluster_Master!$B$3:$C$17,2,FALSE),"") | D7: =IFERROR(AVERAGEIFS(Weekly_Inspections!$AJ$4:$AJ$996,Weekly_Inspections!$F$4:$F$996,$A7,Weekly_Inspections!$D$4:$D$996,$B$3),"") | E7: =IFERROR(AVERAGEIFS(Weekly_Inspections!$AK$4:$AK$996,Weekly_Inspections!$F$4:$F$996,$A7,Weekly_Inspections!$D$4:$D$996,$B$3),"") | F7: =COUNTIFS(Weekly_Inspections!$F$4:$F$996,$A7,Weekly_Inspections!$D$4:$D$996,$B$3,Weekly_Inspections!$AL$4:$AL$996,"YES") | G7: =IFERROR(E7-AVERAGEIFS(Weekly_Inspections!$AK$4:$AK$996,Weekly_Inspections!$F$4:$F$996,$A7,Weekly_Inspections!$D$4:$D$996,$B$4),"") | H7: =IF(AND(E7>=0.85,F7=0),"YES","NO") | I7: =IFERROR(RANK(E7,$E$7:$E$21,0),"") | J7: =COUNTIFS(CAPA_Tracker!$D$3:$D$200,$A7,CAPA_Tracker!$M$3:$M$200,"<>Closed",CAPA_Tracker!$A$3:$A$200,"<>") | K7: =COUNTIFS(CAPA_Tracker!$D$3:$D$200,$A7,CAPA_Tracker!$P$3:$P$200,"YES",CAPA_Tracker!$A$3:$A$200,"<>")
A8: Cluster 7B | B8: =IFERROR(VLOOKUP($A8,Cluster_Master!$B$3:$C$17,1,FALSE),"") | C8: =IFERROR(VLOOKUP($A8,Cluster_Master!$B$3:$C$17,2,FALSE),"") | D8: =IFERROR(AVERAGEIFS(Weekly_Inspections!$AJ$4:$AJ$996,Weekly_Inspections!$F$4:$F$996,$A8,Weekly_Inspections!$D$4:$D$996,$B$3),"") | E8: =IFERROR(AVERAGEIFS(Weekly_Inspections!$AK$4:$AK$996,Weekly_Inspections!$F$4:$F$996,$A8,Weekly_Inspections!$D$4:$D$996,$B$3),"") | F8: =COUNTIFS(Weekly_Inspections!$F$4:$F$996,$A8,Weekly_Inspections!$D$4:$D$996,$B$3,Weekly_Inspections!$AL$4:$AL$996,"YES") | G8: =IFERROR(E8-AVERAGEIFS(Weekly_Inspections!$AK$4:$AK$996,Weekly_Inspections!$F$4:$F$996,$A8,Weekly_Inspections!$D$4:$D$996,$B$4),"") | H8: =IF(AND(E8>=0.85,F8=0),"YES","NO") | I8: =IFERROR(RANK(E8,$E$7:$E$21,0),"") | J8: =COUNTIFS(CAPA_Tracker!$D$3:$D$200,$A8,CAPA_Tracker!$M$3:$M$200,"<>Closed",CAPA_Tracker!$A$3:$A$200,"<>") | K8: =COUNTIFS(CAPA_Tracker!$D$3:$D$200,$A8,CAPA_Tracker!$P$3:$P$200,"YES",CAPA_Tracker!$A$3:$A$200,"<>")
A9: Cluster 8A | B9: =IFERROR(VLOOKUP($A9,Cluster_Master!$B$3:$C$17,1,FALSE),"") | C9: =IFERROR(VLOOKUP($A9,Cluster_Master!$B$3:$C$17,2,FALSE),"") | D9: =IFERROR(AVERAGEIFS(Weekly_Inspections!$AJ$4:$AJ$996,Weekly_Inspections!$F$4:$F$996,$A9,Weekly_Inspections!$D$4:$D$996,$B$3),"") | E9: =IFERROR(AVERAGEIFS(Weekly_Inspections!$AK$4:$AK$996,Weekly_Inspections!$F$4:$F$996,$A9,Weekly_Inspections!$D$4:$D$996,$B$3),"") | F9: =COUNTIFS(Weekly_Inspections!$F$4:$F$996,$A9,Weekly_Inspections!$D$4:$D$996,$B$3,Weekly_Inspections!$AL$4:$AL$996,"YES") | G9: =IFERROR(E9-AVERAGEIFS(Weekly_Inspections!$AK$4:$AK$996,Weekly_Inspections!$F$4:$F$996,$A9,Weekly_Inspections!$D$4:$D$996,$B$4),"") | H9: =IF(AND(E9>=0.85,F9=0),"YES","NO") | I9: =IFERROR(RANK(E9,$E$7:$E$21,0),"") | J9: =COUNTIFS(CAPA_Tracker!$D$3:$D$200,$A9,CAPA_Tracker!$M$3:$M$200,"<>Closed",CAPA_Tracker!$A$3:$A$200,"<>") | K9: =COUNTIFS(CAPA_Tracker!$D$3:$D$200,$A9,CAPA_Tracker!$P$3:$P$200,"YES",CAPA_Tracker!$A$3:$A$200,"<>")
A10: Cluster 8B | B10: =IFERROR(VLOOKUP($A10,Cluster_Master!$B$3:$C$17,1,FALSE),"") | C10: =IFERROR(VLOOKUP($A10,Cluster_Master!$B$3:$C$17,2,FALSE),"") | D10: =IFERROR(AVERAGEIFS(Weekly_Inspections!$AJ$4:$AJ$996,Weekly_Inspections!$F$4:$F$996,$A10,Weekly_Inspections!$D$4:$D$996,$B$3),"") | E10: =IFERROR(AVERAGEIFS(Weekly_Inspections!$AK$4:$AK$996,Weekly_Inspections!$F$4:$F$996,$A10,Weekly_Inspections!$D$4:$D$996,$B$3),"") | F10: =COUNTIFS(Weekly_Inspections!$F$4:$F$996,$A10,Weekly_Inspections!$D$4:$D$996,$B$3,Weekly_Inspections!$AL$4:$AL$996,"YES") | G10: =IFERROR(E10-AVERAGEIFS(Weekly_Inspections!$AK$4:$AK$996,Weekly_Inspections!$F$4:$F$996,$A10,Weekly_Inspections!$D$4:$D$996,$B$4),"") | H10: =IF(AND(E10>=0.85,F10=0),"YES","NO") | I10: =IFERROR(RANK(E10,$E$7:$E$21,0),"") | J10: =COUNTIFS(CAPA_Tracker!$D$3:$D$200,$A10,CAPA_Tracker!$M$3:$M$200,"<>Closed",CAPA_Tracker!$A$3:$A$200,"<>") | K10: =COUNTIFS(CAPA_Tracker!$D$3:$D$200,$A10,CAPA_Tracker!$P$3:$P$200,"YES",CAPA_Tracker!$A$3:$A$200,"<>")
A11: Cluster 8C | B11: =IFERROR(VLOOKUP($A11,Cluster_Master!$B$3:$C$17,1,FALSE),"") | C11: =IFERROR(VLOOKUP($A11,Cluster_Master!$B$3:$C$17,2,FALSE),"") | D11: =IFERROR(AVERAGEIFS(Weekly_Inspections!$AJ$4:$AJ$996,Weekly_Inspections!$F$4:$F$996,$A11,Weekly_Inspections!$D$4:$D$996,$B$3),"") | E11: =IFERROR(AVERAGEIFS(Weekly_Inspections!$AK$4:$AK$996,Weekly_Inspections!$F$4:$F$996,$A11,Weekly_Inspections!$D$4:$D$996,$B$3),"") | F11: =COUNTIFS(Weekly_Inspections!$F$4:$F$996,$A11,Weekly_Inspections!$D$4:$D$996,$B$3,Weekly_Inspections!$AL$4:$AL$996,"YES") | G11: =IFERROR(E11-AVERAGEIFS(Weekly_Inspections!$AK$4:$AK$996,Weekly_Inspections!$F$4:$F$996,$A11,Weekly_Inspections!$D$4:$D$996,$B$4),"") | H11: =IF(AND(E11>=0.85,F11=0),"YES","NO") | I11: =IFERROR(RANK(E11,$E$7:$E$21,0),"") | J11: =COUNTIFS(CAPA_Tracker!$D$3:$D$200,$A11,CAPA_Tracker!$M$3:$M$200,"<>Closed",CAPA_Tracker!$A$3:$A$200,"<>") | K11: =COUNTIFS(CAPA_Tracker!$D$3:$D$200,$A11,CAPA_Tracker!$P$3:$P$200,"YES",CAPA_Tracker!$A$3:$A$200,"<>")
A12: Cluster 8D | B12: =IFERROR(VLOOKUP($A12,Cluster_Master!$B$3:$C$17,1,FALSE),"") | C12: =IFERROR(VLOOKUP($A12,Cluster_Master!$B$3:$C$17,2,FALSE),"") | D12: =IFERROR(AVERAGEIFS(Weekly_Inspections!$AJ$4:$AJ$996,Weekly_Inspections!$F$4:$F$996,$A12,Weekly_Inspections!$D$4:$D$996,$B$3),"") | E12: =IFERROR(AVERAGEIFS(Weekly_Inspections!$AK$4:$AK$996,Weekly_Inspections!$F$4:$F$996,$A12,Weekly_Inspections!$D$4:$D$996,$B$3),"") | F12: =COUNTIFS(Weekly_Inspections!$F$4:$F$996,$A12,Weekly_Inspections!$D$4:$D$996,$B$3,Weekly_Inspections!$AL$4:$AL$996,"YES") | G12: =IFERROR(E12-AVERAGEIFS(Weekly_Inspections!$AK$4:$AK$996,Weekly_Inspections!$F$4:$F$996,$A12,Weekly_Inspections!$D$4:$D$996,$B$4),"") | H12: =IF(AND(E12>=0.85,F12=0),"YES","NO") | I12: =IFERROR(RANK(E12,$E$7:$E$21,0),"") | J12: =COUNTIFS(CAPA_Tracker!$D$3:$D$200,$A12,CAPA_Tracker!$M$3:$M$200,"<>Closed",CAPA_Tracker!$A$3:$A$200,"<>") | K12: =COUNTIFS(CAPA_Tracker!$D$3:$D$200,$A12,CAPA_Tracker!$P$3:$P$200,"YES",CAPA_Tracker!$A$3:$A$200,"<>")
